[2025-09-21T23:22:07.183+0000] {local_task_job_runner.py:123} INFO - ::group::Pre task execution logs
[2025-09-21T23:22:07.201+0000] {taskinstance.py:2614} INFO - Dependencies all met for dep_context=non-requeueable deps ti=<TaskInstance: nawy_real_estate_pipeline.installing_required_dependencies manual__2025-09-20T07:52:23.498254+00:00 [queued]>
[2025-09-21T23:22:07.208+0000] {taskinstance.py:2614} INFO - Dependencies all met for dep_context=requeueable deps ti=<TaskInstance: nawy_real_estate_pipeline.installing_required_dependencies manual__2025-09-20T07:52:23.498254+00:00 [queued]>
[2025-09-21T23:22:07.208+0000] {taskinstance.py:2867} INFO - Starting attempt 2 of 2
[2025-09-21T23:22:07.300+0000] {taskinstance.py:2890} INFO - Executing <Task(BashOperator): installing_required_dependencies> on 2025-09-20 07:52:23.498254+00:00
[2025-09-21T23:22:07.308+0000] {warnings.py:112} WARNING - /home/***/.local/lib/python3.12/site-packages/***/task/task_runner/standard_task_runner.py:70: DeprecationWarning: This process (pid=400) is multi-threaded, use of fork() may lead to deadlocks in the child.
  pid = os.fork()

[2025-09-21T23:22:07.310+0000] {standard_task_runner.py:72} INFO - Started process 437 to run task
[2025-09-21T23:22:07.311+0000] {standard_task_runner.py:104} INFO - Running: ['***', 'tasks', 'run', 'nawy_real_estate_pipeline', 'installing_required_dependencies', 'manual__2025-09-20T07:52:23.498254+00:00', '--job-id', '376', '--raw', '--subdir', 'DAGS_FOLDER/nawy_dag.py', '--cfg-path', '/tmp/tmpabw3z1d8']
[2025-09-21T23:22:07.313+0000] {standard_task_runner.py:105} INFO - Job 376: Subtask installing_required_dependencies
[2025-09-21T23:22:07.506+0000] {task_command.py:467} INFO - Running <TaskInstance: nawy_real_estate_pipeline.installing_required_dependencies manual__2025-09-20T07:52:23.498254+00:00 [running]> on host b65782a7021d
[2025-09-21T23:22:07.913+0000] {taskinstance.py:3134} INFO - Exporting env vars: AIRFLOW_CTX_DAG_OWNER='***' AIRFLOW_CTX_DAG_ID='nawy_real_estate_pipeline' AIRFLOW_CTX_TASK_ID='installing_required_dependencies' AIRFLOW_CTX_EXECUTION_DATE='2025-09-20T07:52:23.498254+00:00' AIRFLOW_CTX_TRY_NUMBER='2' AIRFLOW_CTX_DAG_RUN_ID='manual__2025-09-20T07:52:23.498254+00:00'
[2025-09-21T23:22:07.914+0000] {logging_mixin.py:190} INFO - Task instance is in running state
[2025-09-21T23:22:07.915+0000] {logging_mixin.py:190} INFO -  Previous state of the Task instance: queued
[2025-09-21T23:22:07.916+0000] {logging_mixin.py:190} INFO - Current task name:installing_required_dependencies state:running start_date:2025-09-21 23:22:07.202423+00:00
[2025-09-21T23:22:07.916+0000] {logging_mixin.py:190} INFO - Dag name:nawy_real_estate_pipeline and current dag run status:running
[2025-09-21T23:22:07.917+0000] {taskinstance.py:732} INFO - ::endgroup::
[2025-09-21T23:22:07.918+0000] {subprocess.py:78} INFO - Tmp dir root location: /tmp
[2025-09-21T23:22:07.958+0000] {subprocess.py:88} INFO - Running command: ['/usr/bin/bash', '-c', ' cd /opt/***/dags/../include/nawy_dbt_project && dbt clean &&  dbt deps --no-version-check ']
[2025-09-21T23:22:07.976+0000] {subprocess.py:99} INFO - Output:
[2025-09-21T23:22:11.208+0000] {subprocess.py:106} INFO - [0m23:22:11  Running with dbt=1.10.11
[2025-09-21T23:22:11.451+0000] {subprocess.py:106} INFO - [0m23:22:11  Checking /opt/***/include/nawy_dbt_project/target/*
[2025-09-21T23:22:11.452+0000] {subprocess.py:106} INFO - [0m23:22:11  Cleaned /opt/***/include/nawy_dbt_project/target/*
[2025-09-21T23:22:11.452+0000] {subprocess.py:106} INFO - [0m23:22:11  Checking /opt/***/include/nawy_dbt_project/dbt_packages/*
[2025-09-21T23:22:11.477+0000] {subprocess.py:106} INFO - [0m23:22:11  Cleaned /opt/***/include/nawy_dbt_project/dbt_packages/*
[2025-09-21T23:22:11.478+0000] {subprocess.py:106} INFO - [0m23:22:11  Finished cleaning all paths.
[2025-09-21T23:22:19.303+0000] {subprocess.py:106} INFO - [0m23:22:19  Running with dbt=1.10.11
[2025-09-21T23:22:23.444+0000] {subprocess.py:106} INFO - [0m23:22:23  Installing dbt-labs/dbt_utils
[2025-09-21T23:22:24.838+0000] {subprocess.py:106} INFO - [0m23:22:24  Encountered an error:
[2025-09-21T23:22:24.839+0000] {subprocess.py:106} INFO - [Errno 2] No such file or directory: 'dbt_packages/dbt-utils-1.3.0/integration_tests/.env/redshift.env'
[2025-09-21T23:22:24.847+0000] {subprocess.py:106} INFO - [0m23:22:24  Traceback (most recent call last):
[2025-09-21T23:22:24.848+0000] {subprocess.py:106} INFO -   File "/home/***/.local/lib/python3.12/site-packages/dbt/cli/requires.py", line 178, in wrapper
[2025-09-21T23:22:24.849+0000] {subprocess.py:106} INFO -     result, success = func(*args, **kwargs)
[2025-09-21T23:22:24.850+0000] {subprocess.py:106} INFO -                       ^^^^^^^^^^^^^^^^^^^^^
[2025-09-21T23:22:24.851+0000] {subprocess.py:106} INFO -   File "/home/***/.local/lib/python3.12/site-packages/dbt/cli/requires.py", line 128, in wrapper
[2025-09-21T23:22:24.852+0000] {subprocess.py:106} INFO -     return func(*args, **kwargs)
[2025-09-21T23:22:24.852+0000] {subprocess.py:106} INFO -            ^^^^^^^^^^^^^^^^^^^^^
[2025-09-21T23:22:24.853+0000] {subprocess.py:106} INFO -   File "/home/***/.local/lib/python3.12/site-packages/dbt/cli/requires.py", line 254, in wrapper
[2025-09-21T23:22:24.854+0000] {subprocess.py:106} INFO -     return func(*args, **kwargs)
[2025-09-21T23:22:24.855+0000] {subprocess.py:106} INFO -            ^^^^^^^^^^^^^^^^^^^^^
[2025-09-21T23:22:24.856+0000] {subprocess.py:106} INFO -   File "/home/***/.local/lib/python3.12/site-packages/dbt/cli/requires.py", line 303, in wrapper
[2025-09-21T23:22:24.857+0000] {subprocess.py:106} INFO -     return func(*args, **kwargs)
[2025-09-21T23:22:24.858+0000] {subprocess.py:106} INFO -            ^^^^^^^^^^^^^^^^^^^^^
[2025-09-21T23:22:24.859+0000] {subprocess.py:106} INFO -   File "/home/***/.local/lib/python3.12/site-packages/dbt/cli/main.py", line 461, in deps
[2025-09-21T23:22:24.860+0000] {subprocess.py:106} INFO -     results = task.run()
[2025-09-21T23:22:24.861+0000] {subprocess.py:106} INFO -               ^^^^^^^^^^
[2025-09-21T23:22:24.862+0000] {subprocess.py:106} INFO -   File "/home/***/.local/lib/python3.12/site-packages/dbt/task/deps.py", line 258, in run
[2025-09-21T23:22:24.863+0000] {subprocess.py:106} INFO -     package.install(self.project, renderer)
[2025-09-21T23:22:24.864+0000] {subprocess.py:106} INFO -   File "/home/***/.local/lib/python3.12/site-packages/dbt/deps/registry.py", line 63, in install
[2025-09-21T23:22:24.866+0000] {subprocess.py:106} INFO -     self._install(project, renderer)
[2025-09-21T23:22:24.867+0000] {subprocess.py:106} INFO -   File "/home/***/.local/lib/python3.12/site-packages/dbt/deps/base.py", line 121, in _install
[2025-09-21T23:22:24.868+0000] {subprocess.py:106} INFO -     connection_exception_retry(download_untar_fn, 5)
[2025-09-21T23:22:24.869+0000] {subprocess.py:106} INFO -   File "/home/***/.local/lib/python3.12/site-packages/dbt_common/utils/connection.py", line 22, in connection_exception_retry
[2025-09-21T23:22:24.870+0000] {subprocess.py:106} INFO -     return fn()
[2025-09-21T23:22:24.871+0000] {subprocess.py:106} INFO -            ^^^^
[2025-09-21T23:22:24.871+0000] {subprocess.py:106} INFO -   File "/home/***/.local/lib/python3.12/site-packages/dbt/deps/base.py", line 133, in download_and_untar
[2025-09-21T23:22:24.872+0000] {subprocess.py:106} INFO -     system.untar_package(tar_path, deps_path, package_name)
[2025-09-21T23:22:24.873+0000] {subprocess.py:106} INFO -   File "/home/***/.local/lib/python3.12/site-packages/dbt_common/clients/system.py", line 644, in untar_package
[2025-09-21T23:22:24.874+0000] {subprocess.py:106} INFO -     safe_extract(tarball, dest_dir)
[2025-09-21T23:22:24.875+0000] {subprocess.py:106} INFO -   File "/home/***/.local/lib/python3.12/site-packages/dbt_common/clients/system.py", line 637, in safe_extract
[2025-09-21T23:22:24.876+0000] {subprocess.py:106} INFO -     tarball.extractall(path, members=members)
[2025-09-21T23:22:24.877+0000] {subprocess.py:106} INFO -   File "/usr/local/lib/python3.12/tarfile.py", line 2302, in extractall
[2025-09-21T23:22:24.877+0000] {subprocess.py:106} INFO -     self._extract_one(tarinfo, path, set_attrs=not tarinfo.isdir(),
[2025-09-21T23:22:24.878+0000] {subprocess.py:106} INFO -   File "/usr/local/lib/python3.12/tarfile.py", line 2369, in _extract_one
[2025-09-21T23:22:24.879+0000] {subprocess.py:106} INFO -     self._handle_fatal_error(e)
[2025-09-21T23:22:24.880+0000] {subprocess.py:106} INFO -   File "/usr/local/lib/python3.12/tarfile.py", line 2365, in _extract_one
[2025-09-21T23:22:24.881+0000] {subprocess.py:106} INFO -     self._extract_member(tarinfo, os.path.join(path, tarinfo.name),
[2025-09-21T23:22:24.883+0000] {subprocess.py:106} INFO -   File "/usr/local/lib/python3.12/tarfile.py", line 2448, in _extract_member
[2025-09-21T23:22:24.884+0000] {subprocess.py:106} INFO -     self.makefile(tarinfo, targetpath)
[2025-09-21T23:22:24.885+0000] {subprocess.py:106} INFO -   File "/usr/local/lib/python3.12/tarfile.py", line 2494, in makefile
[2025-09-21T23:22:24.886+0000] {subprocess.py:106} INFO -     with bltn_open(targetpath, "wb") as target:
[2025-09-21T23:22:24.887+0000] {subprocess.py:106} INFO -          ^^^^^^^^^^^^^^^^^^^^^^^^^^^
[2025-09-21T23:22:24.888+0000] {subprocess.py:106} INFO - FileNotFoundError: [Errno 2] No such file or directory: 'dbt_packages/dbt-utils-1.3.0/integration_tests/.env/redshift.env'
[2025-09-21T23:22:24.888+0000] {subprocess.py:106} INFO - 
[2025-09-21T23:22:25.965+0000] {subprocess.py:110} INFO - Command exited with return code 2
[2025-09-21T23:22:26.301+0000] {taskinstance.py:3313} ERROR - Task failed with exception
Traceback (most recent call last):
  File "/home/airflow/.local/lib/python3.12/site-packages/airflow/models/taskinstance.py", line 768, in _execute_task
    result = _execute_callable(context=context, **execute_callable_kwargs)
             ^^^^^^^^^^^^^^^^^^^^^^^^^^^^^^^^^^^^^^^^^^^^^^^^^^^^^^^^^^^^^
  File "/home/airflow/.local/lib/python3.12/site-packages/airflow/models/taskinstance.py", line 734, in _execute_callable
    return ExecutionCallableRunner(
           ^^^^^^^^^^^^^^^^^^^^^^^^
  File "/home/airflow/.local/lib/python3.12/site-packages/airflow/utils/operator_helpers.py", line 252, in run
    return self.func(*args, **kwargs)
           ^^^^^^^^^^^^^^^^^^^^^^^^^^
  File "/home/airflow/.local/lib/python3.12/site-packages/airflow/models/baseoperator.py", line 424, in wrapper
    return func(self, *args, **kwargs)
           ^^^^^^^^^^^^^^^^^^^^^^^^^^^
  File "/home/airflow/.local/lib/python3.12/site-packages/airflow/operators/bash.py", line 276, in execute
    raise AirflowException(
airflow.exceptions.AirflowException: Bash command failed. The command returned a non-zero exit code 2.
[2025-09-21T23:22:26.310+0000] {logging_mixin.py:190} INFO - Task instance in failure state
[2025-09-21T23:22:26.311+0000] {logging_mixin.py:190} INFO - Task start:2025-09-21 23:22:07.202423+00:00 end:2025-09-21 23:22:26.309607+00:00 duration:19.107184
[2025-09-21T23:22:26.312+0000] {logging_mixin.py:190} INFO - Task:<Task(BashOperator): installing_required_dependencies> dag:<DAG: nawy_real_estate_pipeline> dagrun:<DagRun nawy_real_estate_pipeline @ 2025-09-20 07:52:23.498254+00:00: manual__2025-09-20T07:52:23.498254+00:00, state:running, queued_at: 2025-09-21 23:03:47.690764+00:00. externally triggered: True>
[2025-09-21T23:22:26.313+0000] {logging_mixin.py:190} INFO - Failure caused by Bash command failed. The command returned a non-zero exit code 2.
[2025-09-21T23:22:26.314+0000] {taskinstance.py:1226} INFO - Marking task as FAILED. dag_id=nawy_real_estate_pipeline, task_id=installing_required_dependencies, run_id=manual__2025-09-20T07:52:23.498254+00:00, execution_date=20250920T075223, start_date=20250921T232207, end_date=20250921T232226
[2025-09-21T23:22:26.576+0000] {taskinstance.py:341} INFO - ::group::Post task execution logs
[2025-09-21T23:22:26.577+0000] {standard_task_runner.py:124} ERROR - Failed to execute job 376 for task installing_required_dependencies (Bash command failed. The command returned a non-zero exit code 2.; 437)
Traceback (most recent call last):
  File "/home/airflow/.local/lib/python3.12/site-packages/airflow/task/task_runner/standard_task_runner.py", line 117, in _start_by_fork
    ret = args.func(args, dag=self.dag)
          ^^^^^^^^^^^^^^^^^^^^^^^^^^^^^
  File "/home/airflow/.local/lib/python3.12/site-packages/airflow/cli/cli_config.py", line 49, in command
    return func(*args, **kwargs)
           ^^^^^^^^^^^^^^^^^^^^^
  File "/home/airflow/.local/lib/python3.12/site-packages/airflow/utils/cli.py", line 116, in wrapper
    return f(*args, **kwargs)
           ^^^^^^^^^^^^^^^^^^
  File "/home/airflow/.local/lib/python3.12/site-packages/airflow/cli/commands/task_command.py", line 483, in task_run
    task_return_code = _run_task_by_selected_method(args, _dag, ti)
                       ^^^^^^^^^^^^^^^^^^^^^^^^^^^^^^^^^^^^^^^^^^^^
  File "/home/airflow/.local/lib/python3.12/site-packages/airflow/cli/commands/task_command.py", line 256, in _run_task_by_selected_method
    return _run_raw_task(args, ti)
           ^^^^^^^^^^^^^^^^^^^^^^^
  File "/home/airflow/.local/lib/python3.12/site-packages/airflow/cli/commands/task_command.py", line 341, in _run_raw_task
    return ti._run_raw_task(
           ^^^^^^^^^^^^^^^^^
  File "/home/airflow/.local/lib/python3.12/site-packages/airflow/utils/session.py", line 97, in wrapper
    return func(*args, session=session, **kwargs)
           ^^^^^^^^^^^^^^^^^^^^^^^^^^^^^^^^^^^^^^
  File "/home/airflow/.local/lib/python3.12/site-packages/airflow/models/taskinstance.py", line 3006, in _run_raw_task
    return _run_raw_task(
           ^^^^^^^^^^^^^^
  File "/home/airflow/.local/lib/python3.12/site-packages/airflow/models/taskinstance.py", line 274, in _run_raw_task
    TaskInstance._execute_task_with_callbacks(
  File "/home/airflow/.local/lib/python3.12/site-packages/airflow/models/taskinstance.py", line 3161, in _execute_task_with_callbacks
    result = self._execute_task(context, task_orig)
             ^^^^^^^^^^^^^^^^^^^^^^^^^^^^^^^^^^^^^^
  File "/home/airflow/.local/lib/python3.12/site-packages/airflow/models/taskinstance.py", line 3185, in _execute_task
    return _execute_task(self, context, task_orig)
           ^^^^^^^^^^^^^^^^^^^^^^^^^^^^^^^^^^^^^^^
  File "/home/airflow/.local/lib/python3.12/site-packages/airflow/models/taskinstance.py", line 768, in _execute_task
    result = _execute_callable(context=context, **execute_callable_kwargs)
             ^^^^^^^^^^^^^^^^^^^^^^^^^^^^^^^^^^^^^^^^^^^^^^^^^^^^^^^^^^^^^
  File "/home/airflow/.local/lib/python3.12/site-packages/airflow/models/taskinstance.py", line 734, in _execute_callable
    return ExecutionCallableRunner(
           ^^^^^^^^^^^^^^^^^^^^^^^^
  File "/home/airflow/.local/lib/python3.12/site-packages/airflow/utils/operator_helpers.py", line 252, in run
    return self.func(*args, **kwargs)
           ^^^^^^^^^^^^^^^^^^^^^^^^^^
  File "/home/airflow/.local/lib/python3.12/site-packages/airflow/models/baseoperator.py", line 424, in wrapper
    return func(self, *args, **kwargs)
           ^^^^^^^^^^^^^^^^^^^^^^^^^^^
  File "/home/airflow/.local/lib/python3.12/site-packages/airflow/operators/bash.py", line 276, in execute
    raise AirflowException(
airflow.exceptions.AirflowException: Bash command failed. The command returned a non-zero exit code 2.
[2025-09-21T23:22:26.683+0000] {local_task_job_runner.py:266} INFO - Task exited with return code 1
[2025-09-21T23:22:26.811+0000] {taskinstance.py:3901} INFO - 0 downstream tasks scheduled from follow-on schedule check
[2025-09-21T23:22:26.858+0000] {local_task_job_runner.py:245} INFO - ::endgroup::
