[2025-09-21T23:22:17.181+0000] {local_task_job_runner.py:123} INFO - ::group::Pre task execution logs
[2025-09-21T23:22:17.228+0000] {taskinstance.py:2614} INFO - Dependencies all met for dep_context=non-requeueable deps ti=<TaskInstance: nawy_real_estate_pipeline.installing_required_dependencies manual__2025-09-21T13:56:02.427086+00:00 [queued]>
[2025-09-21T23:22:17.249+0000] {taskinstance.py:2614} INFO - Dependencies all met for dep_context=requeueable deps ti=<TaskInstance: nawy_real_estate_pipeline.installing_required_dependencies manual__2025-09-21T13:56:02.427086+00:00 [queued]>
[2025-09-21T23:22:17.255+0000] {taskinstance.py:2867} INFO - Starting attempt 2 of 2
[2025-09-21T23:22:17.338+0000] {taskinstance.py:2890} INFO - Executing <Task(BashOperator): installing_required_dependencies> on 2025-09-21 13:56:02.427086+00:00
[2025-09-21T23:22:17.348+0000] {warnings.py:112} WARNING - /home/***/.local/lib/python3.12/site-packages/***/task/task_runner/standard_task_runner.py:70: DeprecationWarning: This process (pid=457) is multi-threaded, use of fork() may lead to deadlocks in the child.
  pid = os.fork()

[2025-09-21T23:22:17.350+0000] {standard_task_runner.py:72} INFO - Started process 471 to run task
[2025-09-21T23:22:17.352+0000] {standard_task_runner.py:104} INFO - Running: ['***', 'tasks', 'run', 'nawy_real_estate_pipeline', 'installing_required_dependencies', 'manual__2025-09-21T13:56:02.427086+00:00', '--job-id', '381', '--raw', '--subdir', 'DAGS_FOLDER/nawy_dag.py', '--cfg-path', '/tmp/tmpj73eyifc']
[2025-09-21T23:22:17.354+0000] {standard_task_runner.py:105} INFO - Job 381: Subtask installing_required_dependencies
[2025-09-21T23:22:17.546+0000] {task_command.py:467} INFO - Running <TaskInstance: nawy_real_estate_pipeline.installing_required_dependencies manual__2025-09-21T13:56:02.427086+00:00 [running]> on host b65782a7021d
[2025-09-21T23:22:17.852+0000] {taskinstance.py:3134} INFO - Exporting env vars: AIRFLOW_CTX_DAG_OWNER='***' AIRFLOW_CTX_DAG_ID='nawy_real_estate_pipeline' AIRFLOW_CTX_TASK_ID='installing_required_dependencies' AIRFLOW_CTX_EXECUTION_DATE='2025-09-21T13:56:02.427086+00:00' AIRFLOW_CTX_TRY_NUMBER='2' AIRFLOW_CTX_DAG_RUN_ID='manual__2025-09-21T13:56:02.427086+00:00'
[2025-09-21T23:22:17.855+0000] {logging_mixin.py:190} INFO - Task instance is in running state
[2025-09-21T23:22:17.856+0000] {logging_mixin.py:190} INFO -  Previous state of the Task instance: queued
[2025-09-21T23:22:17.856+0000] {logging_mixin.py:190} INFO - Current task name:installing_required_dependencies state:running start_date:2025-09-21 23:22:17.230681+00:00
[2025-09-21T23:22:17.857+0000] {logging_mixin.py:190} INFO - Dag name:nawy_real_estate_pipeline and current dag run status:running
[2025-09-21T23:22:17.858+0000] {taskinstance.py:732} INFO - ::endgroup::
[2025-09-21T23:22:17.860+0000] {subprocess.py:78} INFO - Tmp dir root location: /tmp
[2025-09-21T23:22:17.888+0000] {subprocess.py:88} INFO - Running command: ['/usr/bin/bash', '-c', ' cd /opt/***/dags/../include/nawy_dbt_project && dbt clean &&  dbt deps --no-version-check ']
[2025-09-21T23:22:17.910+0000] {subprocess.py:99} INFO - Output:
[2025-09-21T23:22:24.268+0000] {subprocess.py:106} INFO - [0m23:22:24  Running with dbt=1.10.11
[2025-09-21T23:22:24.812+0000] {subprocess.py:106} INFO - [0m23:22:24  Checking /opt/***/include/nawy_dbt_project/target/*
[2025-09-21T23:22:24.814+0000] {subprocess.py:106} INFO - [0m23:22:24  Cleaned /opt/***/include/nawy_dbt_project/target/*
[2025-09-21T23:22:24.815+0000] {subprocess.py:106} INFO - [0m23:22:24  Checking /opt/***/include/nawy_dbt_project/dbt_packages/*
[2025-09-21T23:22:24.864+0000] {subprocess.py:106} INFO - [0m23:22:24  Cleaned /opt/***/include/nawy_dbt_project/dbt_packages/*
[2025-09-21T23:22:24.865+0000] {subprocess.py:106} INFO - [0m23:22:24  Finished cleaning all paths.
[2025-09-21T23:22:32.249+0000] {subprocess.py:106} INFO - [0m23:22:32  Running with dbt=1.10.11
[2025-09-21T23:22:35.773+0000] {subprocess.py:106} INFO - [0m23:22:35  Installing dbt-labs/dbt_utils
[2025-09-21T23:22:40.199+0000] {subprocess.py:106} INFO - [0m23:22:40  Encountered an error:
[2025-09-21T23:22:40.200+0000] {subprocess.py:106} INFO - [Errno 17] File exists: 'dbt_packages/dbt_utils'
[2025-09-21T23:22:40.206+0000] {subprocess.py:106} INFO - [0m23:22:40  Traceback (most recent call last):
[2025-09-21T23:22:40.207+0000] {subprocess.py:106} INFO -   File "/usr/local/lib/python3.12/shutil.py", line 847, in move
[2025-09-21T23:22:40.208+0000] {subprocess.py:106} INFO -     os.rename(src, real_dst)
[2025-09-21T23:22:40.208+0000] {subprocess.py:106} INFO - PermissionError: [Errno 13] Permission denied: 'dbt_packages/dbt-utils-1.3.0' -> 'dbt_packages/dbt_utils'
[2025-09-21T23:22:40.209+0000] {subprocess.py:106} INFO - 
[2025-09-21T23:22:40.211+0000] {subprocess.py:106} INFO - During handling of the above exception, another exception occurred:
[2025-09-21T23:22:40.212+0000] {subprocess.py:106} INFO - 
[2025-09-21T23:22:40.212+0000] {subprocess.py:106} INFO - Traceback (most recent call last):
[2025-09-21T23:22:40.213+0000] {subprocess.py:106} INFO -   File "/home/***/.local/lib/python3.12/site-packages/dbt/cli/requires.py", line 178, in wrapper
[2025-09-21T23:22:40.215+0000] {subprocess.py:106} INFO -     result, success = func(*args, **kwargs)
[2025-09-21T23:22:40.216+0000] {subprocess.py:106} INFO -                       ^^^^^^^^^^^^^^^^^^^^^
[2025-09-21T23:22:40.216+0000] {subprocess.py:106} INFO -   File "/home/***/.local/lib/python3.12/site-packages/dbt/cli/requires.py", line 128, in wrapper
[2025-09-21T23:22:40.218+0000] {subprocess.py:106} INFO -     return func(*args, **kwargs)
[2025-09-21T23:22:40.219+0000] {subprocess.py:106} INFO -            ^^^^^^^^^^^^^^^^^^^^^
[2025-09-21T23:22:40.221+0000] {subprocess.py:106} INFO -   File "/home/***/.local/lib/python3.12/site-packages/dbt/cli/requires.py", line 254, in wrapper
[2025-09-21T23:22:40.222+0000] {subprocess.py:106} INFO -     return func(*args, **kwargs)
[2025-09-21T23:22:40.223+0000] {subprocess.py:106} INFO -            ^^^^^^^^^^^^^^^^^^^^^
[2025-09-21T23:22:40.225+0000] {subprocess.py:106} INFO -   File "/home/***/.local/lib/python3.12/site-packages/dbt/cli/requires.py", line 303, in wrapper
[2025-09-21T23:22:40.226+0000] {subprocess.py:106} INFO -     return func(*args, **kwargs)
[2025-09-21T23:22:40.227+0000] {subprocess.py:106} INFO -            ^^^^^^^^^^^^^^^^^^^^^
[2025-09-21T23:22:40.228+0000] {subprocess.py:106} INFO -   File "/home/***/.local/lib/python3.12/site-packages/dbt/cli/main.py", line 461, in deps
[2025-09-21T23:22:40.230+0000] {subprocess.py:106} INFO -     results = task.run()
[2025-09-21T23:22:40.231+0000] {subprocess.py:106} INFO -               ^^^^^^^^^^
[2025-09-21T23:22:40.232+0000] {subprocess.py:106} INFO -   File "/home/***/.local/lib/python3.12/site-packages/dbt/task/deps.py", line 258, in run
[2025-09-21T23:22:40.233+0000] {subprocess.py:106} INFO -     package.install(self.project, renderer)
[2025-09-21T23:22:40.235+0000] {subprocess.py:106} INFO -   File "/home/***/.local/lib/python3.12/site-packages/dbt/deps/registry.py", line 63, in install
[2025-09-21T23:22:40.236+0000] {subprocess.py:106} INFO -     self._install(project, renderer)
[2025-09-21T23:22:40.237+0000] {subprocess.py:106} INFO -   File "/home/***/.local/lib/python3.12/site-packages/dbt/deps/base.py", line 121, in _install
[2025-09-21T23:22:40.238+0000] {subprocess.py:106} INFO -     connection_exception_retry(download_untar_fn, 5)
[2025-09-21T23:22:40.239+0000] {subprocess.py:106} INFO -   File "/home/***/.local/lib/python3.12/site-packages/dbt_common/utils/connection.py", line 22, in connection_exception_retry
[2025-09-21T23:22:40.240+0000] {subprocess.py:106} INFO -     return fn()
[2025-09-21T23:22:40.241+0000] {subprocess.py:106} INFO -            ^^^^
[2025-09-21T23:22:40.242+0000] {subprocess.py:106} INFO -   File "/home/***/.local/lib/python3.12/site-packages/dbt/deps/base.py", line 133, in download_and_untar
[2025-09-21T23:22:40.244+0000] {subprocess.py:106} INFO -     system.untar_package(tar_path, deps_path, package_name)
[2025-09-21T23:22:40.245+0000] {subprocess.py:106} INFO -   File "/home/***/.local/lib/python3.12/site-packages/dbt_common/clients/system.py", line 649, in untar_package
[2025-09-21T23:22:40.247+0000] {subprocess.py:106} INFO -     dbt_common.clients.system.rename(downloaded_path, desired_path, force=True)
[2025-09-21T23:22:40.249+0000] {subprocess.py:106} INFO -   File "/home/***/.local/lib/python3.12/site-packages/dbt_common/clients/system.py", line 612, in rename
[2025-09-21T23:22:40.250+0000] {subprocess.py:106} INFO -     shutil.move(from_path, to_path)
[2025-09-21T23:22:40.251+0000] {subprocess.py:106} INFO -   File "/usr/local/lib/python3.12/shutil.py", line 863, in move
[2025-09-21T23:22:40.252+0000] {subprocess.py:106} INFO -     copytree(src, real_dst, copy_function=copy_function,
[2025-09-21T23:22:40.253+0000] {subprocess.py:106} INFO -   File "/usr/local/lib/python3.12/shutil.py", line 600, in copytree
[2025-09-21T23:22:40.254+0000] {subprocess.py:106} INFO -     return _copytree(entries=entries, src=src, dst=dst, symlinks=symlinks,
[2025-09-21T23:22:40.255+0000] {subprocess.py:106} INFO -            ^^^^^^^^^^^^^^^^^^^^^^^^^^^^^^^^^^^^^^^^^^^^^^^^^^^^^^^^^^^^^^^
[2025-09-21T23:22:40.256+0000] {subprocess.py:106} INFO -   File "/usr/local/lib/python3.12/shutil.py", line 498, in _copytree
[2025-09-21T23:22:40.257+0000] {subprocess.py:106} INFO -     os.makedirs(dst, exist_ok=dirs_exist_ok)
[2025-09-21T23:22:40.258+0000] {subprocess.py:106} INFO -   File "<frozen os>", line 225, in makedirs
[2025-09-21T23:22:40.260+0000] {subprocess.py:106} INFO - FileExistsError: [Errno 17] File exists: 'dbt_packages/dbt_utils'
[2025-09-21T23:22:40.261+0000] {subprocess.py:106} INFO - 
[2025-09-21T23:22:41.269+0000] {subprocess.py:110} INFO - Command exited with return code 2
[2025-09-21T23:22:41.596+0000] {taskinstance.py:3313} ERROR - Task failed with exception
Traceback (most recent call last):
  File "/home/airflow/.local/lib/python3.12/site-packages/airflow/models/taskinstance.py", line 768, in _execute_task
    result = _execute_callable(context=context, **execute_callable_kwargs)
             ^^^^^^^^^^^^^^^^^^^^^^^^^^^^^^^^^^^^^^^^^^^^^^^^^^^^^^^^^^^^^
  File "/home/airflow/.local/lib/python3.12/site-packages/airflow/models/taskinstance.py", line 734, in _execute_callable
    return ExecutionCallableRunner(
           ^^^^^^^^^^^^^^^^^^^^^^^^
  File "/home/airflow/.local/lib/python3.12/site-packages/airflow/utils/operator_helpers.py", line 252, in run
    return self.func(*args, **kwargs)
           ^^^^^^^^^^^^^^^^^^^^^^^^^^
  File "/home/airflow/.local/lib/python3.12/site-packages/airflow/models/baseoperator.py", line 424, in wrapper
    return func(self, *args, **kwargs)
           ^^^^^^^^^^^^^^^^^^^^^^^^^^^
  File "/home/airflow/.local/lib/python3.12/site-packages/airflow/operators/bash.py", line 276, in execute
    raise AirflowException(
airflow.exceptions.AirflowException: Bash command failed. The command returned a non-zero exit code 2.
[2025-09-21T23:22:41.605+0000] {logging_mixin.py:190} INFO - Task instance in failure state
[2025-09-21T23:22:41.606+0000] {logging_mixin.py:190} INFO - Task start:2025-09-21 23:22:17.230681+00:00 end:2025-09-21 23:22:41.604940+00:00 duration:24.374259
[2025-09-21T23:22:41.607+0000] {logging_mixin.py:190} INFO - Task:<Task(BashOperator): installing_required_dependencies> dag:<DAG: nawy_real_estate_pipeline> dagrun:<DagRun nawy_real_estate_pipeline @ 2025-09-21 13:56:02.427086+00:00: manual__2025-09-21T13:56:02.427086+00:00, state:running, queued_at: 2025-09-21 23:03:47.690914+00:00. externally triggered: True>
[2025-09-21T23:22:41.608+0000] {logging_mixin.py:190} INFO - Failure caused by Bash command failed. The command returned a non-zero exit code 2.
[2025-09-21T23:22:41.608+0000] {taskinstance.py:1226} INFO - Marking task as FAILED. dag_id=nawy_real_estate_pipeline, task_id=installing_required_dependencies, run_id=manual__2025-09-21T13:56:02.427086+00:00, execution_date=20250921T135602, start_date=20250921T232217, end_date=20250921T232241
[2025-09-21T23:22:41.955+0000] {taskinstance.py:341} INFO - ::group::Post task execution logs
[2025-09-21T23:22:41.956+0000] {standard_task_runner.py:124} ERROR - Failed to execute job 381 for task installing_required_dependencies (Bash command failed. The command returned a non-zero exit code 2.; 471)
Traceback (most recent call last):
  File "/home/airflow/.local/lib/python3.12/site-packages/airflow/task/task_runner/standard_task_runner.py", line 117, in _start_by_fork
    ret = args.func(args, dag=self.dag)
          ^^^^^^^^^^^^^^^^^^^^^^^^^^^^^
  File "/home/airflow/.local/lib/python3.12/site-packages/airflow/cli/cli_config.py", line 49, in command
    return func(*args, **kwargs)
           ^^^^^^^^^^^^^^^^^^^^^
  File "/home/airflow/.local/lib/python3.12/site-packages/airflow/utils/cli.py", line 116, in wrapper
    return f(*args, **kwargs)
           ^^^^^^^^^^^^^^^^^^
  File "/home/airflow/.local/lib/python3.12/site-packages/airflow/cli/commands/task_command.py", line 483, in task_run
    task_return_code = _run_task_by_selected_method(args, _dag, ti)
                       ^^^^^^^^^^^^^^^^^^^^^^^^^^^^^^^^^^^^^^^^^^^^
  File "/home/airflow/.local/lib/python3.12/site-packages/airflow/cli/commands/task_command.py", line 256, in _run_task_by_selected_method
    return _run_raw_task(args, ti)
           ^^^^^^^^^^^^^^^^^^^^^^^
  File "/home/airflow/.local/lib/python3.12/site-packages/airflow/cli/commands/task_command.py", line 341, in _run_raw_task
    return ti._run_raw_task(
           ^^^^^^^^^^^^^^^^^
  File "/home/airflow/.local/lib/python3.12/site-packages/airflow/utils/session.py", line 97, in wrapper
    return func(*args, session=session, **kwargs)
           ^^^^^^^^^^^^^^^^^^^^^^^^^^^^^^^^^^^^^^
  File "/home/airflow/.local/lib/python3.12/site-packages/airflow/models/taskinstance.py", line 3006, in _run_raw_task
    return _run_raw_task(
           ^^^^^^^^^^^^^^
  File "/home/airflow/.local/lib/python3.12/site-packages/airflow/models/taskinstance.py", line 274, in _run_raw_task
    TaskInstance._execute_task_with_callbacks(
  File "/home/airflow/.local/lib/python3.12/site-packages/airflow/models/taskinstance.py", line 3161, in _execute_task_with_callbacks
    result = self._execute_task(context, task_orig)
             ^^^^^^^^^^^^^^^^^^^^^^^^^^^^^^^^^^^^^^
  File "/home/airflow/.local/lib/python3.12/site-packages/airflow/models/taskinstance.py", line 3185, in _execute_task
    return _execute_task(self, context, task_orig)
           ^^^^^^^^^^^^^^^^^^^^^^^^^^^^^^^^^^^^^^^
  File "/home/airflow/.local/lib/python3.12/site-packages/airflow/models/taskinstance.py", line 768, in _execute_task
    result = _execute_callable(context=context, **execute_callable_kwargs)
             ^^^^^^^^^^^^^^^^^^^^^^^^^^^^^^^^^^^^^^^^^^^^^^^^^^^^^^^^^^^^^
  File "/home/airflow/.local/lib/python3.12/site-packages/airflow/models/taskinstance.py", line 734, in _execute_callable
    return ExecutionCallableRunner(
           ^^^^^^^^^^^^^^^^^^^^^^^^
  File "/home/airflow/.local/lib/python3.12/site-packages/airflow/utils/operator_helpers.py", line 252, in run
    return self.func(*args, **kwargs)
           ^^^^^^^^^^^^^^^^^^^^^^^^^^
  File "/home/airflow/.local/lib/python3.12/site-packages/airflow/models/baseoperator.py", line 424, in wrapper
    return func(self, *args, **kwargs)
           ^^^^^^^^^^^^^^^^^^^^^^^^^^^
  File "/home/airflow/.local/lib/python3.12/site-packages/airflow/operators/bash.py", line 276, in execute
    raise AirflowException(
airflow.exceptions.AirflowException: Bash command failed. The command returned a non-zero exit code 2.
[2025-09-21T23:22:42.009+0000] {local_task_job_runner.py:266} INFO - Task exited with return code 1
[2025-09-21T23:22:42.077+0000] {taskinstance.py:3901} INFO - 0 downstream tasks scheduled from follow-on schedule check
[2025-09-21T23:22:42.105+0000] {local_task_job_runner.py:245} INFO - ::endgroup::
