[2025-09-21T23:17:44.724+0000] {local_task_job_runner.py:123} INFO - ::group::Pre task execution logs
[2025-09-21T23:17:44.760+0000] {taskinstance.py:2614} INFO - Dependencies all met for dep_context=non-requeueable deps ti=<TaskInstance: nawy_real_estate_pipeline.installing_required_dependencies manual__2025-09-20T00:05:31.907723+00:00 [queued]>
[2025-09-21T23:17:44.777+0000] {taskinstance.py:2614} INFO - Dependencies all met for dep_context=requeueable deps ti=<TaskInstance: nawy_real_estate_pipeline.installing_required_dependencies manual__2025-09-20T00:05:31.907723+00:00 [queued]>
[2025-09-21T23:17:44.780+0000] {taskinstance.py:2867} INFO - Starting attempt 2 of 2
[2025-09-21T23:17:44.936+0000] {taskinstance.py:2890} INFO - Executing <Task(BashOperator): installing_required_dependencies> on 2025-09-20 00:05:31.907723+00:00
[2025-09-21T23:17:44.962+0000] {standard_task_runner.py:104} INFO - Running: ['***', 'tasks', 'run', 'nawy_real_estate_pipeline', 'installing_required_dependencies', 'manual__2025-09-20T00:05:31.907723+00:00', '--job-id', '350', '--raw', '--subdir', 'DAGS_FOLDER/nawy_dag.py', '--cfg-path', '/tmp/tmpj2u_uhhy']
[2025-09-21T23:17:44.964+0000] {warnings.py:112} WARNING - /home/***/.local/lib/python3.12/site-packages/***/task/task_runner/standard_task_runner.py:70: DeprecationWarning: This process (pid=102) is multi-threaded, use of fork() may lead to deadlocks in the child.
  pid = os.fork()

[2025-09-21T23:17:44.971+0000] {standard_task_runner.py:72} INFO - Started process 142 to run task
[2025-09-21T23:17:44.972+0000] {standard_task_runner.py:105} INFO - Job 350: Subtask installing_required_dependencies
[2025-09-21T23:17:45.260+0000] {task_command.py:467} INFO - Running <TaskInstance: nawy_real_estate_pipeline.installing_required_dependencies manual__2025-09-20T00:05:31.907723+00:00 [running]> on host b65782a7021d
[2025-09-21T23:17:46.559+0000] {taskinstance.py:3134} INFO - Exporting env vars: AIRFLOW_CTX_DAG_OWNER='***' AIRFLOW_CTX_DAG_ID='nawy_real_estate_pipeline' AIRFLOW_CTX_TASK_ID='installing_required_dependencies' AIRFLOW_CTX_EXECUTION_DATE='2025-09-20T00:05:31.907723+00:00' AIRFLOW_CTX_TRY_NUMBER='2' AIRFLOW_CTX_DAG_RUN_ID='manual__2025-09-20T00:05:31.907723+00:00'
[2025-09-21T23:17:46.562+0000] {logging_mixin.py:190} INFO - Task instance is in running state
[2025-09-21T23:17:46.563+0000] {logging_mixin.py:190} INFO -  Previous state of the Task instance: queued
[2025-09-21T23:17:46.564+0000] {logging_mixin.py:190} INFO - Current task name:installing_required_dependencies state:running start_date:2025-09-21 23:17:44.761202+00:00
[2025-09-21T23:17:46.565+0000] {logging_mixin.py:190} INFO - Dag name:nawy_real_estate_pipeline and current dag run status:running
[2025-09-21T23:17:46.565+0000] {taskinstance.py:732} INFO - ::endgroup::
[2025-09-21T23:17:46.567+0000] {subprocess.py:78} INFO - Tmp dir root location: /tmp
[2025-09-21T23:17:46.568+0000] {subprocess.py:88} INFO - Running command: ['/usr/bin/bash', '-c', ' cd /opt/***/dags/../include/nawy_dbt_project && dbt clean &&  dbt deps --no-version-check ']
[2025-09-21T23:17:46.586+0000] {subprocess.py:99} INFO - Output:
[2025-09-21T23:19:09.714+0000] {subprocess.py:106} INFO - [0m23:19:09  Running with dbt=1.10.11
[2025-09-21T23:19:46.366+0000] {subprocess.py:106} INFO - [0m23:19:46  Checking /opt/***/include/nawy_dbt_project/target/*
[2025-09-21T23:19:47.270+0000] {subprocess.py:106} INFO - [0m23:19:47  Cleaned /opt/***/include/nawy_dbt_project/target/*
[2025-09-21T23:19:47.271+0000] {subprocess.py:106} INFO - [0m23:19:47  Checking /opt/***/include/nawy_dbt_project/dbt_packages/*
[2025-09-21T23:19:49.118+0000] {subprocess.py:106} INFO - [0m23:19:49  Cleaned /opt/***/include/nawy_dbt_project/dbt_packages/*
[2025-09-21T23:19:49.119+0000] {subprocess.py:106} INFO - [0m23:19:49  Finished cleaning all paths.
[2025-09-21T23:20:49.689+0000] {subprocess.py:106} INFO - [0m23:20:49  Running with dbt=1.10.11
[2025-09-21T23:20:54.613+0000] {subprocess.py:106} INFO - [0m23:20:54  Installing dbt-labs/dbt_utils
[2025-09-21T23:20:58.605+0000] {subprocess.py:106} INFO - [0m23:20:58  Encountered an error:
[2025-09-21T23:20:58.606+0000] {subprocess.py:106} INFO - [Errno 2] No such file or directory: 'dbt_packages/dbt-utils-1.3.0/.github/workflows/create-table-of-contents.yml'
[2025-09-21T23:20:59.657+0000] {subprocess.py:106} INFO - [0m23:20:59  Traceback (most recent call last):
[2025-09-21T23:20:59.658+0000] {subprocess.py:106} INFO -   File "/home/***/.local/lib/python3.12/site-packages/dbt/cli/requires.py", line 178, in wrapper
[2025-09-21T23:20:59.662+0000] {subprocess.py:106} INFO -     result, success = func(*args, **kwargs)
[2025-09-21T23:20:59.664+0000] {subprocess.py:106} INFO -                       ^^^^^^^^^^^^^^^^^^^^^
[2025-09-21T23:20:59.665+0000] {subprocess.py:106} INFO -   File "/home/***/.local/lib/python3.12/site-packages/dbt/cli/requires.py", line 128, in wrapper
[2025-09-21T23:20:59.667+0000] {subprocess.py:106} INFO -     return func(*args, **kwargs)
[2025-09-21T23:20:59.669+0000] {subprocess.py:106} INFO -            ^^^^^^^^^^^^^^^^^^^^^
[2025-09-21T23:20:59.671+0000] {subprocess.py:106} INFO -   File "/home/***/.local/lib/python3.12/site-packages/dbt/cli/requires.py", line 254, in wrapper
[2025-09-21T23:20:59.672+0000] {subprocess.py:106} INFO -     return func(*args, **kwargs)
[2025-09-21T23:20:59.673+0000] {subprocess.py:106} INFO -            ^^^^^^^^^^^^^^^^^^^^^
[2025-09-21T23:20:59.677+0000] {subprocess.py:106} INFO -   File "/home/***/.local/lib/python3.12/site-packages/dbt/cli/requires.py", line 303, in wrapper
[2025-09-21T23:20:59.678+0000] {subprocess.py:106} INFO -     return func(*args, **kwargs)
[2025-09-21T23:20:59.680+0000] {subprocess.py:106} INFO -            ^^^^^^^^^^^^^^^^^^^^^
[2025-09-21T23:20:59.681+0000] {subprocess.py:106} INFO -   File "/home/***/.local/lib/python3.12/site-packages/dbt/cli/main.py", line 461, in deps
[2025-09-21T23:20:59.682+0000] {subprocess.py:106} INFO -     results = task.run()
[2025-09-21T23:20:59.683+0000] {subprocess.py:106} INFO -               ^^^^^^^^^^
[2025-09-21T23:20:59.684+0000] {subprocess.py:106} INFO -   File "/home/***/.local/lib/python3.12/site-packages/dbt/task/deps.py", line 258, in run
[2025-09-21T23:20:59.686+0000] {subprocess.py:106} INFO -     package.install(self.project, renderer)
[2025-09-21T23:20:59.691+0000] {subprocess.py:106} INFO -   File "/home/***/.local/lib/python3.12/site-packages/dbt/deps/registry.py", line 63, in install
[2025-09-21T23:20:59.692+0000] {subprocess.py:106} INFO -     self._install(project, renderer)
[2025-09-21T23:20:59.693+0000] {subprocess.py:106} INFO -   File "/home/***/.local/lib/python3.12/site-packages/dbt/deps/base.py", line 121, in _install
[2025-09-21T23:20:59.694+0000] {subprocess.py:106} INFO -     connection_exception_retry(download_untar_fn, 5)
[2025-09-21T23:20:59.695+0000] {subprocess.py:106} INFO -   File "/home/***/.local/lib/python3.12/site-packages/dbt_common/utils/connection.py", line 22, in connection_exception_retry
[2025-09-21T23:20:59.697+0000] {subprocess.py:106} INFO -     return fn()
[2025-09-21T23:20:59.699+0000] {subprocess.py:106} INFO -            ^^^^
[2025-09-21T23:20:59.700+0000] {subprocess.py:106} INFO -   File "/home/***/.local/lib/python3.12/site-packages/dbt/deps/base.py", line 133, in download_and_untar
[2025-09-21T23:20:59.702+0000] {subprocess.py:106} INFO -     system.untar_package(tar_path, deps_path, package_name)
[2025-09-21T23:20:59.704+0000] {subprocess.py:106} INFO -   File "/home/***/.local/lib/python3.12/site-packages/dbt_common/clients/system.py", line 644, in untar_package
[2025-09-21T23:20:59.706+0000] {subprocess.py:106} INFO -     safe_extract(tarball, dest_dir)
[2025-09-21T23:20:59.710+0000] {subprocess.py:106} INFO -   File "/home/***/.local/lib/python3.12/site-packages/dbt_common/clients/system.py", line 637, in safe_extract
[2025-09-21T23:20:59.714+0000] {subprocess.py:106} INFO -     tarball.extractall(path, members=members)
[2025-09-21T23:20:59.716+0000] {subprocess.py:106} INFO -   File "/usr/local/lib/python3.12/tarfile.py", line 2302, in extractall
[2025-09-21T23:20:59.720+0000] {subprocess.py:106} INFO -     self._extract_one(tarinfo, path, set_attrs=not tarinfo.isdir(),
[2025-09-21T23:20:59.723+0000] {subprocess.py:106} INFO -   File "/usr/local/lib/python3.12/tarfile.py", line 2369, in _extract_one
[2025-09-21T23:20:59.726+0000] {subprocess.py:106} INFO -     self._handle_fatal_error(e)
[2025-09-21T23:20:59.727+0000] {subprocess.py:106} INFO -   File "/usr/local/lib/python3.12/tarfile.py", line 2365, in _extract_one
[2025-09-21T23:20:59.729+0000] {subprocess.py:106} INFO -     self._extract_member(tarinfo, os.path.join(path, tarinfo.name),
[2025-09-21T23:20:59.737+0000] {subprocess.py:106} INFO -   File "/usr/local/lib/python3.12/tarfile.py", line 2448, in _extract_member
[2025-09-21T23:20:59.739+0000] {subprocess.py:106} INFO -     self.makefile(tarinfo, targetpath)
[2025-09-21T23:20:59.741+0000] {subprocess.py:106} INFO -   File "/usr/local/lib/python3.12/tarfile.py", line 2494, in makefile
[2025-09-21T23:20:59.745+0000] {subprocess.py:106} INFO -     with bltn_open(targetpath, "wb") as target:
[2025-09-21T23:20:59.747+0000] {subprocess.py:106} INFO -          ^^^^^^^^^^^^^^^^^^^^^^^^^^^
[2025-09-21T23:20:59.748+0000] {subprocess.py:106} INFO - FileNotFoundError: [Errno 2] No such file or directory: 'dbt_packages/dbt-utils-1.3.0/.github/workflows/create-table-of-contents.yml'
[2025-09-21T23:20:59.749+0000] {subprocess.py:106} INFO - 
[2025-09-21T23:21:00.860+0000] {subprocess.py:110} INFO - Command exited with return code 2
[2025-09-21T23:21:01.718+0000] {taskinstance.py:3313} ERROR - Task failed with exception
Traceback (most recent call last):
  File "/home/airflow/.local/lib/python3.12/site-packages/airflow/models/taskinstance.py", line 768, in _execute_task
    result = _execute_callable(context=context, **execute_callable_kwargs)
             ^^^^^^^^^^^^^^^^^^^^^^^^^^^^^^^^^^^^^^^^^^^^^^^^^^^^^^^^^^^^^
  File "/home/airflow/.local/lib/python3.12/site-packages/airflow/models/taskinstance.py", line 734, in _execute_callable
    return ExecutionCallableRunner(
           ^^^^^^^^^^^^^^^^^^^^^^^^
  File "/home/airflow/.local/lib/python3.12/site-packages/airflow/utils/operator_helpers.py", line 252, in run
    return self.func(*args, **kwargs)
           ^^^^^^^^^^^^^^^^^^^^^^^^^^
  File "/home/airflow/.local/lib/python3.12/site-packages/airflow/models/baseoperator.py", line 424, in wrapper
    return func(self, *args, **kwargs)
           ^^^^^^^^^^^^^^^^^^^^^^^^^^^
  File "/home/airflow/.local/lib/python3.12/site-packages/airflow/operators/bash.py", line 276, in execute
    raise AirflowException(
airflow.exceptions.AirflowException: Bash command failed. The command returned a non-zero exit code 2.
[2025-09-21T23:21:01.735+0000] {logging_mixin.py:190} INFO - Task instance in failure state
[2025-09-21T23:21:01.736+0000] {logging_mixin.py:190} INFO - Task start:2025-09-21 23:17:44.761202+00:00 end:2025-09-21 23:21:01.734692+00:00 duration:196.97349
[2025-09-21T23:21:01.738+0000] {logging_mixin.py:190} INFO - Task:<Task(BashOperator): installing_required_dependencies> dag:<DAG: nawy_real_estate_pipeline> dagrun:<DagRun nawy_real_estate_pipeline @ 2025-09-20 00:05:31.907723+00:00: manual__2025-09-20T00:05:31.907723+00:00, state:running, queued_at: 2025-09-21 23:03:47.690246+00:00. externally triggered: True>
[2025-09-21T23:21:01.739+0000] {logging_mixin.py:190} INFO - Failure caused by Bash command failed. The command returned a non-zero exit code 2.
[2025-09-21T23:21:01.741+0000] {taskinstance.py:1226} INFO - Marking task as FAILED. dag_id=nawy_real_estate_pipeline, task_id=installing_required_dependencies, run_id=manual__2025-09-20T00:05:31.907723+00:00, execution_date=20250920T000531, start_date=20250921T231744, end_date=20250921T232101
[2025-09-21T23:21:01.983+0000] {taskinstance.py:341} INFO - ::group::Post task execution logs
[2025-09-21T23:21:01.987+0000] {standard_task_runner.py:124} ERROR - Failed to execute job 350 for task installing_required_dependencies (Bash command failed. The command returned a non-zero exit code 2.; 142)
Traceback (most recent call last):
  File "/home/airflow/.local/lib/python3.12/site-packages/airflow/task/task_runner/standard_task_runner.py", line 117, in _start_by_fork
    ret = args.func(args, dag=self.dag)
          ^^^^^^^^^^^^^^^^^^^^^^^^^^^^^
  File "/home/airflow/.local/lib/python3.12/site-packages/airflow/cli/cli_config.py", line 49, in command
    return func(*args, **kwargs)
           ^^^^^^^^^^^^^^^^^^^^^
  File "/home/airflow/.local/lib/python3.12/site-packages/airflow/utils/cli.py", line 116, in wrapper
    return f(*args, **kwargs)
           ^^^^^^^^^^^^^^^^^^
  File "/home/airflow/.local/lib/python3.12/site-packages/airflow/cli/commands/task_command.py", line 483, in task_run
    task_return_code = _run_task_by_selected_method(args, _dag, ti)
                       ^^^^^^^^^^^^^^^^^^^^^^^^^^^^^^^^^^^^^^^^^^^^
  File "/home/airflow/.local/lib/python3.12/site-packages/airflow/cli/commands/task_command.py", line 256, in _run_task_by_selected_method
    return _run_raw_task(args, ti)
           ^^^^^^^^^^^^^^^^^^^^^^^
  File "/home/airflow/.local/lib/python3.12/site-packages/airflow/cli/commands/task_command.py", line 341, in _run_raw_task
    return ti._run_raw_task(
           ^^^^^^^^^^^^^^^^^
  File "/home/airflow/.local/lib/python3.12/site-packages/airflow/utils/session.py", line 97, in wrapper
    return func(*args, session=session, **kwargs)
           ^^^^^^^^^^^^^^^^^^^^^^^^^^^^^^^^^^^^^^
  File "/home/airflow/.local/lib/python3.12/site-packages/airflow/models/taskinstance.py", line 3006, in _run_raw_task
    return _run_raw_task(
           ^^^^^^^^^^^^^^
  File "/home/airflow/.local/lib/python3.12/site-packages/airflow/models/taskinstance.py", line 274, in _run_raw_task
    TaskInstance._execute_task_with_callbacks(
  File "/home/airflow/.local/lib/python3.12/site-packages/airflow/models/taskinstance.py", line 3161, in _execute_task_with_callbacks
    result = self._execute_task(context, task_orig)
             ^^^^^^^^^^^^^^^^^^^^^^^^^^^^^^^^^^^^^^
  File "/home/airflow/.local/lib/python3.12/site-packages/airflow/models/taskinstance.py", line 3185, in _execute_task
    return _execute_task(self, context, task_orig)
           ^^^^^^^^^^^^^^^^^^^^^^^^^^^^^^^^^^^^^^^
  File "/home/airflow/.local/lib/python3.12/site-packages/airflow/models/taskinstance.py", line 768, in _execute_task
    result = _execute_callable(context=context, **execute_callable_kwargs)
             ^^^^^^^^^^^^^^^^^^^^^^^^^^^^^^^^^^^^^^^^^^^^^^^^^^^^^^^^^^^^^
  File "/home/airflow/.local/lib/python3.12/site-packages/airflow/models/taskinstance.py", line 734, in _execute_callable
    return ExecutionCallableRunner(
           ^^^^^^^^^^^^^^^^^^^^^^^^
  File "/home/airflow/.local/lib/python3.12/site-packages/airflow/utils/operator_helpers.py", line 252, in run
    return self.func(*args, **kwargs)
           ^^^^^^^^^^^^^^^^^^^^^^^^^^
  File "/home/airflow/.local/lib/python3.12/site-packages/airflow/models/baseoperator.py", line 424, in wrapper
    return func(self, *args, **kwargs)
           ^^^^^^^^^^^^^^^^^^^^^^^^^^^
  File "/home/airflow/.local/lib/python3.12/site-packages/airflow/operators/bash.py", line 276, in execute
    raise AirflowException(
airflow.exceptions.AirflowException: Bash command failed. The command returned a non-zero exit code 2.
[2025-09-21T23:21:02.035+0000] {local_task_job_runner.py:266} INFO - Task exited with return code 1
[2025-09-21T23:21:02.092+0000] {taskinstance.py:3901} INFO - 0 downstream tasks scheduled from follow-on schedule check
[2025-09-21T23:21:02.164+0000] {local_task_job_runner.py:245} INFO - ::endgroup::
