[2025-09-21T13:42:09.284+0000] {local_task_job_runner.py:123} INFO - ::group::Pre task execution logs
[2025-09-21T13:42:09.312+0000] {taskinstance.py:2614} INFO - Dependencies all met for dep_context=non-requeueable deps ti=<TaskInstance: nawy_real_estate_pipeline.ingesting_data_from_sheets scheduled__2025-09-20T00:00:00+00:00 [queued]>
[2025-09-21T13:42:09.325+0000] {taskinstance.py:2614} INFO - Dependencies all met for dep_context=requeueable deps ti=<TaskInstance: nawy_real_estate_pipeline.ingesting_data_from_sheets scheduled__2025-09-20T00:00:00+00:00 [queued]>
[2025-09-21T13:42:09.326+0000] {taskinstance.py:2867} INFO - Starting attempt 1 of 1
[2025-09-21T13:42:09.368+0000] {taskinstance.py:2890} INFO - Executing <Task(BashOperator): ingesting_data_from_sheets> on 2025-09-20 00:00:00+00:00
[2025-09-21T13:42:09.377+0000] {warnings.py:112} WARNING - /home/***/.local/lib/python3.12/site-packages/***/task/task_runner/standard_task_runner.py:70: DeprecationWarning: This process (pid=181) is multi-threaded, use of fork() may lead to deadlocks in the child.
  pid = os.fork()

[2025-09-21T13:42:09.379+0000] {standard_task_runner.py:72} INFO - Started process 183 to run task
[2025-09-21T13:42:09.380+0000] {standard_task_runner.py:104} INFO - Running: ['***', 'tasks', 'run', 'nawy_real_estate_pipeline', 'ingesting_data_from_sheets', 'scheduled__2025-09-20T00:00:00+00:00', '--job-id', '302', '--raw', '--subdir', 'DAGS_FOLDER/nawy_dag.py', '--cfg-path', '/tmp/tmpbn_rzl5_']
[2025-09-21T13:42:09.381+0000] {standard_task_runner.py:105} INFO - Job 302: Subtask ingesting_data_from_sheets
[2025-09-21T13:42:09.472+0000] {task_command.py:467} INFO - Running <TaskInstance: nawy_real_estate_pipeline.ingesting_data_from_sheets scheduled__2025-09-20T00:00:00+00:00 [running]> on host b65782a7021d
[2025-09-21T13:42:09.934+0000] {taskinstance.py:3134} INFO - Exporting env vars: AIRFLOW_CTX_DAG_OWNER='***' AIRFLOW_CTX_DAG_ID='nawy_real_estate_pipeline' AIRFLOW_CTX_TASK_ID='ingesting_data_from_sheets' AIRFLOW_CTX_EXECUTION_DATE='2025-09-20T00:00:00+00:00' AIRFLOW_CTX_TRY_NUMBER='1' AIRFLOW_CTX_DAG_RUN_ID='scheduled__2025-09-20T00:00:00+00:00'
[2025-09-21T13:42:09.935+0000] {logging_mixin.py:190} INFO - Task instance is in running state
[2025-09-21T13:42:09.936+0000] {logging_mixin.py:190} INFO -  Previous state of the Task instance: queued
[2025-09-21T13:42:09.937+0000] {logging_mixin.py:190} INFO - Current task name:ingesting_data_from_sheets state:running start_date:2025-09-21 13:42:09.313606+00:00
[2025-09-21T13:42:09.937+0000] {logging_mixin.py:190} INFO - Dag name:nawy_real_estate_pipeline and current dag run status:running
[2025-09-21T13:42:09.938+0000] {taskinstance.py:732} INFO - ::endgroup::
[2025-09-21T13:42:09.939+0000] {subprocess.py:78} INFO - Tmp dir root location: /tmp
[2025-09-21T13:42:09.966+0000] {subprocess.py:88} INFO - Running command: ['/usr/bin/bash', '-c', ' cd /opt/***/dags/../include/nawy_dbt_project && dbt seed  ']
[2025-09-21T13:42:09.981+0000] {subprocess.py:99} INFO - Output:
[2025-09-21T13:42:13.333+0000] {subprocess.py:106} INFO - [0m13:42:13  Running with dbt=1.10.11
[2025-09-21T13:42:14.401+0000] {subprocess.py:106} INFO - [0m13:42:14  Registered adapter: postgres=1.9.1
[2025-09-21T13:42:14.736+0000] {subprocess.py:106} INFO - [0m13:42:14  Unable to do partial parsing because saved manifest not found. Starting full parse.
[2025-09-21T13:42:21.505+0000] {subprocess.py:106} INFO - [0m13:42:21  Found 15 models, 1 snapshot, 2 seeds, 553 macros
[2025-09-21T13:42:21.511+0000] {subprocess.py:106} INFO - [0m13:42:21
[2025-09-21T13:42:21.512+0000] {subprocess.py:106} INFO - [0m13:42:21  Concurrency: 1 threads (target='dev')
[2025-09-21T13:42:21.513+0000] {subprocess.py:106} INFO - [0m13:42:21
[2025-09-21T13:42:22.904+0000] {subprocess.py:106} INFO - [0m13:42:22  1 of 2 START seed file dwh.de_leads ............................................ [RUN]
[2025-09-21T13:42:37.377+0000] {subprocess.py:106} INFO - [0m13:42:37  1 of 2 ERROR loading seed file dwh.de_leads .................................... [[31mERROR[0m in 14.46s]
[2025-09-21T13:42:37.382+0000] {subprocess.py:106} INFO - [0m13:42:37  2 of 2 START seed file dwh.de_sales ............................................ [RUN]
[2025-09-21T13:42:37.827+0000] {subprocess.py:106} INFO - [0m13:42:37  2 of 2 ERROR loading seed file dwh.de_sales .................................... [[31mERROR[0m in 0.44s]
[2025-09-21T13:42:38.004+0000] {subprocess.py:106} INFO - [0m13:42:38
[2025-09-21T13:42:38.005+0000] {subprocess.py:106} INFO - [0m13:42:38  Finished running 2 seeds in 0 hours 0 minutes and 16.49 seconds (16.49s).
[2025-09-21T13:42:38.135+0000] {subprocess.py:106} INFO - [0m13:42:38
[2025-09-21T13:42:38.136+0000] {subprocess.py:106} INFO - [0m13:42:38  [31mCompleted with 2 errors, 0 partial successes, and 0 warnings:[0m
[2025-09-21T13:42:38.137+0000] {subprocess.py:106} INFO - [0m13:42:38
[2025-09-21T13:42:38.138+0000] {subprocess.py:106} INFO - [0m13:42:38  [31mFailure in seed de_leads (seeds/de_leads.csv)[0m
[2025-09-21T13:42:38.140+0000] {subprocess.py:106} INFO - [0m13:42:38    Database Error in seed de_leads (seeds/de_leads.csv)
[2025-09-21T13:42:38.141+0000] {subprocess.py:106} INFO -   relation "dwh.de_leads" does not exist
[2025-09-21T13:42:38.142+0000] {subprocess.py:106} INFO - [0m13:42:38
[2025-09-21T13:42:38.143+0000] {subprocess.py:106} INFO - [0m13:42:38  [31mFailure in seed de_sales (seeds/de_sales.csv)[0m
[2025-09-21T13:42:38.144+0000] {subprocess.py:106} INFO - [0m13:42:38    Database Error in seed de_sales (seeds/de_sales.csv)
[2025-09-21T13:42:38.145+0000] {subprocess.py:106} INFO -   relation "dwh.de_sales" does not exist
[2025-09-21T13:42:38.145+0000] {subprocess.py:106} INFO - [0m13:42:38
[2025-09-21T13:42:38.146+0000] {subprocess.py:106} INFO - [0m13:42:38  Done. PASS=0 WARN=0 ERROR=2 SKIP=0 NO-OP=0 TOTAL=2
[2025-09-21T13:42:39.388+0000] {subprocess.py:110} INFO - Command exited with return code 1
[2025-09-21T13:42:39.402+0000] {taskinstance.py:3313} ERROR - Task failed with exception
Traceback (most recent call last):
  File "/home/airflow/.local/lib/python3.12/site-packages/airflow/models/taskinstance.py", line 768, in _execute_task
    result = _execute_callable(context=context, **execute_callable_kwargs)
             ^^^^^^^^^^^^^^^^^^^^^^^^^^^^^^^^^^^^^^^^^^^^^^^^^^^^^^^^^^^^^
  File "/home/airflow/.local/lib/python3.12/site-packages/airflow/models/taskinstance.py", line 734, in _execute_callable
    return ExecutionCallableRunner(
           ^^^^^^^^^^^^^^^^^^^^^^^^
  File "/home/airflow/.local/lib/python3.12/site-packages/airflow/utils/operator_helpers.py", line 252, in run
    return self.func(*args, **kwargs)
           ^^^^^^^^^^^^^^^^^^^^^^^^^^
  File "/home/airflow/.local/lib/python3.12/site-packages/airflow/models/baseoperator.py", line 424, in wrapper
    return func(self, *args, **kwargs)
           ^^^^^^^^^^^^^^^^^^^^^^^^^^^
  File "/home/airflow/.local/lib/python3.12/site-packages/airflow/operators/bash.py", line 276, in execute
    raise AirflowException(
airflow.exceptions.AirflowException: Bash command failed. The command returned a non-zero exit code 1.
[2025-09-21T13:42:39.464+0000] {logging_mixin.py:190} INFO - Task instance in failure state
[2025-09-21T13:42:39.464+0000] {logging_mixin.py:190} INFO - Task start:2025-09-21 13:42:09.313606+00:00 end:2025-09-21 13:42:39.463382+00:00 duration:30.149776
[2025-09-21T13:42:39.465+0000] {logging_mixin.py:190} INFO - Task:<Task(BashOperator): ingesting_data_from_sheets> dag:<DAG: nawy_real_estate_pipeline> dagrun:<DagRun nawy_real_estate_pipeline @ 2025-09-20 00:00:00+00:00: scheduled__2025-09-20T00:00:00+00:00, state:running, queued_at: 2025-09-21 13:40:37.371010+00:00. externally triggered: False>
[2025-09-21T13:42:39.466+0000] {logging_mixin.py:190} INFO - Failure caused by Bash command failed. The command returned a non-zero exit code 1.
[2025-09-21T13:42:39.467+0000] {taskinstance.py:1226} INFO - Marking task as FAILED. dag_id=nawy_real_estate_pipeline, task_id=ingesting_data_from_sheets, run_id=scheduled__2025-09-20T00:00:00+00:00, execution_date=20250920T000000, start_date=20250921T134209, end_date=20250921T134239
[2025-09-21T13:42:39.677+0000] {taskinstance.py:341} INFO - ::group::Post task execution logs
[2025-09-21T13:42:39.678+0000] {standard_task_runner.py:124} ERROR - Failed to execute job 302 for task ingesting_data_from_sheets (Bash command failed. The command returned a non-zero exit code 1.; 183)
Traceback (most recent call last):
  File "/home/airflow/.local/lib/python3.12/site-packages/airflow/task/task_runner/standard_task_runner.py", line 117, in _start_by_fork
    ret = args.func(args, dag=self.dag)
          ^^^^^^^^^^^^^^^^^^^^^^^^^^^^^
  File "/home/airflow/.local/lib/python3.12/site-packages/airflow/cli/cli_config.py", line 49, in command
    return func(*args, **kwargs)
           ^^^^^^^^^^^^^^^^^^^^^
  File "/home/airflow/.local/lib/python3.12/site-packages/airflow/utils/cli.py", line 116, in wrapper
    return f(*args, **kwargs)
           ^^^^^^^^^^^^^^^^^^
  File "/home/airflow/.local/lib/python3.12/site-packages/airflow/cli/commands/task_command.py", line 483, in task_run
    task_return_code = _run_task_by_selected_method(args, _dag, ti)
                       ^^^^^^^^^^^^^^^^^^^^^^^^^^^^^^^^^^^^^^^^^^^^
  File "/home/airflow/.local/lib/python3.12/site-packages/airflow/cli/commands/task_command.py", line 256, in _run_task_by_selected_method
    return _run_raw_task(args, ti)
           ^^^^^^^^^^^^^^^^^^^^^^^
  File "/home/airflow/.local/lib/python3.12/site-packages/airflow/cli/commands/task_command.py", line 341, in _run_raw_task
    return ti._run_raw_task(
           ^^^^^^^^^^^^^^^^^
  File "/home/airflow/.local/lib/python3.12/site-packages/airflow/utils/session.py", line 97, in wrapper
    return func(*args, session=session, **kwargs)
           ^^^^^^^^^^^^^^^^^^^^^^^^^^^^^^^^^^^^^^
  File "/home/airflow/.local/lib/python3.12/site-packages/airflow/models/taskinstance.py", line 3006, in _run_raw_task
    return _run_raw_task(
           ^^^^^^^^^^^^^^
  File "/home/airflow/.local/lib/python3.12/site-packages/airflow/models/taskinstance.py", line 274, in _run_raw_task
    TaskInstance._execute_task_with_callbacks(
  File "/home/airflow/.local/lib/python3.12/site-packages/airflow/models/taskinstance.py", line 3161, in _execute_task_with_callbacks
    result = self._execute_task(context, task_orig)
             ^^^^^^^^^^^^^^^^^^^^^^^^^^^^^^^^^^^^^^
  File "/home/airflow/.local/lib/python3.12/site-packages/airflow/models/taskinstance.py", line 3185, in _execute_task
    return _execute_task(self, context, task_orig)
           ^^^^^^^^^^^^^^^^^^^^^^^^^^^^^^^^^^^^^^^
  File "/home/airflow/.local/lib/python3.12/site-packages/airflow/models/taskinstance.py", line 768, in _execute_task
    result = _execute_callable(context=context, **execute_callable_kwargs)
             ^^^^^^^^^^^^^^^^^^^^^^^^^^^^^^^^^^^^^^^^^^^^^^^^^^^^^^^^^^^^^
  File "/home/airflow/.local/lib/python3.12/site-packages/airflow/models/taskinstance.py", line 734, in _execute_callable
    return ExecutionCallableRunner(
           ^^^^^^^^^^^^^^^^^^^^^^^^
  File "/home/airflow/.local/lib/python3.12/site-packages/airflow/utils/operator_helpers.py", line 252, in run
    return self.func(*args, **kwargs)
           ^^^^^^^^^^^^^^^^^^^^^^^^^^
  File "/home/airflow/.local/lib/python3.12/site-packages/airflow/models/baseoperator.py", line 424, in wrapper
    return func(self, *args, **kwargs)
           ^^^^^^^^^^^^^^^^^^^^^^^^^^^
  File "/home/airflow/.local/lib/python3.12/site-packages/airflow/operators/bash.py", line 276, in execute
    raise AirflowException(
airflow.exceptions.AirflowException: Bash command failed. The command returned a non-zero exit code 1.
[2025-09-21T13:42:39.725+0000] {local_task_job_runner.py:266} INFO - Task exited with return code 1
[2025-09-21T13:42:39.759+0000] {taskinstance.py:3901} INFO - 0 downstream tasks scheduled from follow-on schedule check
[2025-09-21T13:42:39.812+0000] {local_task_job_runner.py:245} INFO - ::endgroup::
