[2025-09-21T23:17:44.724+0000] {local_task_job_runner.py:123} INFO - ::group::Pre task execution logs
[2025-09-21T23:17:44.764+0000] {taskinstance.py:2614} INFO - Dependencies all met for dep_context=non-requeueable deps ti=<TaskInstance: nawy_real_estate_pipeline.installing_required_dependencies manual__2025-09-20T00:14:34.809359+00:00 [queued]>
[2025-09-21T23:17:44.800+0000] {taskinstance.py:2614} INFO - Dependencies all met for dep_context=requeueable deps ti=<TaskInstance: nawy_real_estate_pipeline.installing_required_dependencies manual__2025-09-20T00:14:34.809359+00:00 [queued]>
[2025-09-21T23:17:44.806+0000] {taskinstance.py:2867} INFO - Starting attempt 2 of 2
[2025-09-21T23:17:44.936+0000] {taskinstance.py:2890} INFO - Executing <Task(BashOperator): installing_required_dependencies> on 2025-09-20 00:14:34.809359+00:00
[2025-09-21T23:17:44.957+0000] {standard_task_runner.py:104} INFO - Running: ['***', 'tasks', 'run', 'nawy_real_estate_pipeline', 'installing_required_dependencies', 'manual__2025-09-20T00:14:34.809359+00:00', '--job-id', '349', '--raw', '--subdir', 'DAGS_FOLDER/nawy_dag.py', '--cfg-path', '/tmp/tmp3tehvwp9']
[2025-09-21T23:17:44.962+0000] {warnings.py:112} WARNING - /home/***/.local/lib/python3.12/site-packages/***/task/task_runner/standard_task_runner.py:70: DeprecationWarning: This process (pid=96) is multi-threaded, use of fork() may lead to deadlocks in the child.
  pid = os.fork()

[2025-09-21T23:17:44.963+0000] {standard_task_runner.py:105} INFO - Job 349: Subtask installing_required_dependencies
[2025-09-21T23:17:44.964+0000] {standard_task_runner.py:72} INFO - Started process 140 to run task
[2025-09-21T23:17:45.161+0000] {task_command.py:467} INFO - Running <TaskInstance: nawy_real_estate_pipeline.installing_required_dependencies manual__2025-09-20T00:14:34.809359+00:00 [running]> on host b65782a7021d
[2025-09-21T23:17:46.559+0000] {taskinstance.py:3134} INFO - Exporting env vars: AIRFLOW_CTX_DAG_OWNER='***' AIRFLOW_CTX_DAG_ID='nawy_real_estate_pipeline' AIRFLOW_CTX_TASK_ID='installing_required_dependencies' AIRFLOW_CTX_EXECUTION_DATE='2025-09-20T00:14:34.809359+00:00' AIRFLOW_CTX_TRY_NUMBER='2' AIRFLOW_CTX_DAG_RUN_ID='manual__2025-09-20T00:14:34.809359+00:00'
[2025-09-21T23:17:46.562+0000] {logging_mixin.py:190} INFO - Task instance is in running state
[2025-09-21T23:17:46.563+0000] {logging_mixin.py:190} INFO -  Previous state of the Task instance: queued
[2025-09-21T23:17:46.564+0000] {logging_mixin.py:190} INFO - Current task name:installing_required_dependencies state:running start_date:2025-09-21 23:17:44.765438+00:00
[2025-09-21T23:17:46.564+0000] {logging_mixin.py:190} INFO - Dag name:nawy_real_estate_pipeline and current dag run status:running
[2025-09-21T23:17:46.565+0000] {taskinstance.py:732} INFO - ::endgroup::
[2025-09-21T23:17:46.566+0000] {subprocess.py:78} INFO - Tmp dir root location: /tmp
[2025-09-21T23:17:46.568+0000] {subprocess.py:88} INFO - Running command: ['/usr/bin/bash', '-c', ' cd /opt/***/dags/../include/nawy_dbt_project && dbt clean &&  dbt deps --no-version-check ']
[2025-09-21T23:17:46.586+0000] {subprocess.py:99} INFO - Output:
[2025-09-21T23:19:09.712+0000] {subprocess.py:106} INFO - [0m23:19:09  Running with dbt=1.10.11
[2025-09-21T23:19:46.377+0000] {subprocess.py:106} INFO - [0m23:19:46  Checking /opt/***/include/nawy_dbt_project/target/*
[2025-09-21T23:19:47.268+0000] {subprocess.py:106} INFO - [0m23:19:47  Cleaned /opt/***/include/nawy_dbt_project/target/*
[2025-09-21T23:19:47.269+0000] {subprocess.py:106} INFO - [0m23:19:47  Checking /opt/***/include/nawy_dbt_project/dbt_packages/*
[2025-09-21T23:19:49.125+0000] {subprocess.py:106} INFO - [0m23:19:49  Cleaned /opt/***/include/nawy_dbt_project/dbt_packages/*
[2025-09-21T23:19:49.125+0000] {subprocess.py:106} INFO - [0m23:19:49  Finished cleaning all paths.
[2025-09-21T23:20:49.684+0000] {subprocess.py:106} INFO - [0m23:20:49  Running with dbt=1.10.11
[2025-09-21T23:20:54.610+0000] {subprocess.py:106} INFO - [0m23:20:54  Installing dbt-labs/dbt_utils
[2025-09-21T23:21:04.555+0000] {subprocess.py:106} INFO - [0m23:21:04  Encountered an error:
[2025-09-21T23:21:04.556+0000] {subprocess.py:106} INFO - [Errno 17] File exists: 'dbt_packages/dbt-utils-1.3.0'
[2025-09-21T23:21:04.565+0000] {subprocess.py:106} INFO - [0m23:21:04  Traceback (most recent call last):
[2025-09-21T23:21:04.567+0000] {subprocess.py:106} INFO -   File "/home/***/.local/lib/python3.12/site-packages/dbt/cli/requires.py", line 178, in wrapper
[2025-09-21T23:21:04.568+0000] {subprocess.py:106} INFO -     result, success = func(*args, **kwargs)
[2025-09-21T23:21:04.569+0000] {subprocess.py:106} INFO -                       ^^^^^^^^^^^^^^^^^^^^^
[2025-09-21T23:21:04.570+0000] {subprocess.py:106} INFO -   File "/home/***/.local/lib/python3.12/site-packages/dbt/cli/requires.py", line 128, in wrapper
[2025-09-21T23:21:04.572+0000] {subprocess.py:106} INFO -     return func(*args, **kwargs)
[2025-09-21T23:21:04.574+0000] {subprocess.py:106} INFO -            ^^^^^^^^^^^^^^^^^^^^^
[2025-09-21T23:21:04.575+0000] {subprocess.py:106} INFO -   File "/home/***/.local/lib/python3.12/site-packages/dbt/cli/requires.py", line 254, in wrapper
[2025-09-21T23:21:04.576+0000] {subprocess.py:106} INFO -     return func(*args, **kwargs)
[2025-09-21T23:21:04.578+0000] {subprocess.py:106} INFO -            ^^^^^^^^^^^^^^^^^^^^^
[2025-09-21T23:21:04.579+0000] {subprocess.py:106} INFO -   File "/home/***/.local/lib/python3.12/site-packages/dbt/cli/requires.py", line 303, in wrapper
[2025-09-21T23:21:04.581+0000] {subprocess.py:106} INFO -     return func(*args, **kwargs)
[2025-09-21T23:21:04.583+0000] {subprocess.py:106} INFO -            ^^^^^^^^^^^^^^^^^^^^^
[2025-09-21T23:21:04.584+0000] {subprocess.py:106} INFO -   File "/home/***/.local/lib/python3.12/site-packages/dbt/cli/main.py", line 461, in deps
[2025-09-21T23:21:04.586+0000] {subprocess.py:106} INFO -     results = task.run()
[2025-09-21T23:21:04.587+0000] {subprocess.py:106} INFO -               ^^^^^^^^^^
[2025-09-21T23:21:04.588+0000] {subprocess.py:106} INFO -   File "/home/***/.local/lib/python3.12/site-packages/dbt/task/deps.py", line 258, in run
[2025-09-21T23:21:04.589+0000] {subprocess.py:106} INFO -     package.install(self.project, renderer)
[2025-09-21T23:21:04.591+0000] {subprocess.py:106} INFO -   File "/home/***/.local/lib/python3.12/site-packages/dbt/deps/registry.py", line 63, in install
[2025-09-21T23:21:04.593+0000] {subprocess.py:106} INFO -     self._install(project, renderer)
[2025-09-21T23:21:04.594+0000] {subprocess.py:106} INFO -   File "/home/***/.local/lib/python3.12/site-packages/dbt/deps/base.py", line 121, in _install
[2025-09-21T23:21:04.597+0000] {subprocess.py:106} INFO -     connection_exception_retry(download_untar_fn, 5)
[2025-09-21T23:21:04.598+0000] {subprocess.py:106} INFO -   File "/home/***/.local/lib/python3.12/site-packages/dbt_common/utils/connection.py", line 22, in connection_exception_retry
[2025-09-21T23:21:04.599+0000] {subprocess.py:106} INFO -     return fn()
[2025-09-21T23:21:04.601+0000] {subprocess.py:106} INFO -            ^^^^
[2025-09-21T23:21:04.603+0000] {subprocess.py:106} INFO -   File "/home/***/.local/lib/python3.12/site-packages/dbt/deps/base.py", line 133, in download_and_untar
[2025-09-21T23:21:04.604+0000] {subprocess.py:106} INFO -     system.untar_package(tar_path, deps_path, package_name)
[2025-09-21T23:21:04.605+0000] {subprocess.py:106} INFO -   File "/home/***/.local/lib/python3.12/site-packages/dbt_common/clients/system.py", line 644, in untar_package
[2025-09-21T23:21:04.606+0000] {subprocess.py:106} INFO -     safe_extract(tarball, dest_dir)
[2025-09-21T23:21:04.608+0000] {subprocess.py:106} INFO -   File "/home/***/.local/lib/python3.12/site-packages/dbt_common/clients/system.py", line 637, in safe_extract
[2025-09-21T23:21:04.609+0000] {subprocess.py:106} INFO -     tarball.extractall(path, members=members)
[2025-09-21T23:21:04.610+0000] {subprocess.py:106} INFO -   File "/usr/local/lib/python3.12/tarfile.py", line 2302, in extractall
[2025-09-21T23:21:04.611+0000] {subprocess.py:106} INFO -     self._extract_one(tarinfo, path, set_attrs=not tarinfo.isdir(),
[2025-09-21T23:21:04.612+0000] {subprocess.py:106} INFO -   File "/usr/local/lib/python3.12/tarfile.py", line 2369, in _extract_one
[2025-09-21T23:21:04.613+0000] {subprocess.py:106} INFO -     self._handle_fatal_error(e)
[2025-09-21T23:21:04.615+0000] {subprocess.py:106} INFO -   File "/usr/local/lib/python3.12/tarfile.py", line 2365, in _extract_one
[2025-09-21T23:21:04.620+0000] {subprocess.py:106} INFO -     self._extract_member(tarinfo, os.path.join(path, tarinfo.name),
[2025-09-21T23:21:04.621+0000] {subprocess.py:106} INFO -   File "/usr/local/lib/python3.12/tarfile.py", line 2440, in _extract_member
[2025-09-21T23:21:04.622+0000] {subprocess.py:106} INFO -     os.makedirs(upperdirs)
[2025-09-21T23:21:04.622+0000] {subprocess.py:106} INFO -   File "<frozen os>", line 225, in makedirs
[2025-09-21T23:21:04.624+0000] {subprocess.py:106} INFO - FileExistsError: [Errno 17] File exists: 'dbt_packages/dbt-utils-1.3.0'
[2025-09-21T23:21:04.627+0000] {subprocess.py:106} INFO - 
[2025-09-21T23:21:05.937+0000] {subprocess.py:110} INFO - Command exited with return code 2
[2025-09-21T23:21:06.868+0000] {taskinstance.py:3313} ERROR - Task failed with exception
Traceback (most recent call last):
  File "/home/airflow/.local/lib/python3.12/site-packages/airflow/models/taskinstance.py", line 768, in _execute_task
    result = _execute_callable(context=context, **execute_callable_kwargs)
             ^^^^^^^^^^^^^^^^^^^^^^^^^^^^^^^^^^^^^^^^^^^^^^^^^^^^^^^^^^^^^
  File "/home/airflow/.local/lib/python3.12/site-packages/airflow/models/taskinstance.py", line 734, in _execute_callable
    return ExecutionCallableRunner(
           ^^^^^^^^^^^^^^^^^^^^^^^^
  File "/home/airflow/.local/lib/python3.12/site-packages/airflow/utils/operator_helpers.py", line 252, in run
    return self.func(*args, **kwargs)
           ^^^^^^^^^^^^^^^^^^^^^^^^^^
  File "/home/airflow/.local/lib/python3.12/site-packages/airflow/models/baseoperator.py", line 424, in wrapper
    return func(self, *args, **kwargs)
           ^^^^^^^^^^^^^^^^^^^^^^^^^^^
  File "/home/airflow/.local/lib/python3.12/site-packages/airflow/operators/bash.py", line 276, in execute
    raise AirflowException(
airflow.exceptions.AirflowException: Bash command failed. The command returned a non-zero exit code 2.
[2025-09-21T23:21:06.876+0000] {logging_mixin.py:190} INFO - Task instance in failure state
[2025-09-21T23:21:06.877+0000] {logging_mixin.py:190} INFO - Task start:2025-09-21 23:17:44.765438+00:00 end:2025-09-21 23:21:06.875254+00:00 duration:202.109816
[2025-09-21T23:21:06.878+0000] {logging_mixin.py:190} INFO - Task:<Task(BashOperator): installing_required_dependencies> dag:<DAG: nawy_real_estate_pipeline> dagrun:<DagRun nawy_real_estate_pipeline @ 2025-09-20 00:14:34.809359+00:00: manual__2025-09-20T00:14:34.809359+00:00, state:running, queued_at: 2025-09-21 23:03:47.690441+00:00. externally triggered: True>
[2025-09-21T23:21:06.879+0000] {logging_mixin.py:190} INFO - Failure caused by Bash command failed. The command returned a non-zero exit code 2.
[2025-09-21T23:21:06.880+0000] {taskinstance.py:1226} INFO - Marking task as FAILED. dag_id=nawy_real_estate_pipeline, task_id=installing_required_dependencies, run_id=manual__2025-09-20T00:14:34.809359+00:00, execution_date=20250920T001434, start_date=20250921T231744, end_date=20250921T232106
[2025-09-21T23:21:07.275+0000] {taskinstance.py:341} INFO - ::group::Post task execution logs
[2025-09-21T23:21:07.275+0000] {standard_task_runner.py:124} ERROR - Failed to execute job 349 for task installing_required_dependencies (Bash command failed. The command returned a non-zero exit code 2.; 140)
Traceback (most recent call last):
  File "/home/airflow/.local/lib/python3.12/site-packages/airflow/task/task_runner/standard_task_runner.py", line 117, in _start_by_fork
    ret = args.func(args, dag=self.dag)
          ^^^^^^^^^^^^^^^^^^^^^^^^^^^^^
  File "/home/airflow/.local/lib/python3.12/site-packages/airflow/cli/cli_config.py", line 49, in command
    return func(*args, **kwargs)
           ^^^^^^^^^^^^^^^^^^^^^
  File "/home/airflow/.local/lib/python3.12/site-packages/airflow/utils/cli.py", line 116, in wrapper
    return f(*args, **kwargs)
           ^^^^^^^^^^^^^^^^^^
  File "/home/airflow/.local/lib/python3.12/site-packages/airflow/cli/commands/task_command.py", line 483, in task_run
    task_return_code = _run_task_by_selected_method(args, _dag, ti)
                       ^^^^^^^^^^^^^^^^^^^^^^^^^^^^^^^^^^^^^^^^^^^^
  File "/home/airflow/.local/lib/python3.12/site-packages/airflow/cli/commands/task_command.py", line 256, in _run_task_by_selected_method
    return _run_raw_task(args, ti)
           ^^^^^^^^^^^^^^^^^^^^^^^
  File "/home/airflow/.local/lib/python3.12/site-packages/airflow/cli/commands/task_command.py", line 341, in _run_raw_task
    return ti._run_raw_task(
           ^^^^^^^^^^^^^^^^^
  File "/home/airflow/.local/lib/python3.12/site-packages/airflow/utils/session.py", line 97, in wrapper
    return func(*args, session=session, **kwargs)
           ^^^^^^^^^^^^^^^^^^^^^^^^^^^^^^^^^^^^^^
  File "/home/airflow/.local/lib/python3.12/site-packages/airflow/models/taskinstance.py", line 3006, in _run_raw_task
    return _run_raw_task(
           ^^^^^^^^^^^^^^
  File "/home/airflow/.local/lib/python3.12/site-packages/airflow/models/taskinstance.py", line 274, in _run_raw_task
    TaskInstance._execute_task_with_callbacks(
  File "/home/airflow/.local/lib/python3.12/site-packages/airflow/models/taskinstance.py", line 3161, in _execute_task_with_callbacks
    result = self._execute_task(context, task_orig)
             ^^^^^^^^^^^^^^^^^^^^^^^^^^^^^^^^^^^^^^
  File "/home/airflow/.local/lib/python3.12/site-packages/airflow/models/taskinstance.py", line 3185, in _execute_task
    return _execute_task(self, context, task_orig)
           ^^^^^^^^^^^^^^^^^^^^^^^^^^^^^^^^^^^^^^^
  File "/home/airflow/.local/lib/python3.12/site-packages/airflow/models/taskinstance.py", line 768, in _execute_task
    result = _execute_callable(context=context, **execute_callable_kwargs)
             ^^^^^^^^^^^^^^^^^^^^^^^^^^^^^^^^^^^^^^^^^^^^^^^^^^^^^^^^^^^^^
  File "/home/airflow/.local/lib/python3.12/site-packages/airflow/models/taskinstance.py", line 734, in _execute_callable
    return ExecutionCallableRunner(
           ^^^^^^^^^^^^^^^^^^^^^^^^
  File "/home/airflow/.local/lib/python3.12/site-packages/airflow/utils/operator_helpers.py", line 252, in run
    return self.func(*args, **kwargs)
           ^^^^^^^^^^^^^^^^^^^^^^^^^^
  File "/home/airflow/.local/lib/python3.12/site-packages/airflow/models/baseoperator.py", line 424, in wrapper
    return func(self, *args, **kwargs)
           ^^^^^^^^^^^^^^^^^^^^^^^^^^^
  File "/home/airflow/.local/lib/python3.12/site-packages/airflow/operators/bash.py", line 276, in execute
    raise AirflowException(
airflow.exceptions.AirflowException: Bash command failed. The command returned a non-zero exit code 2.
[2025-09-21T23:21:07.322+0000] {local_task_job_runner.py:266} INFO - Task exited with return code 1
[2025-09-21T23:21:07.382+0000] {taskinstance.py:3901} INFO - 0 downstream tasks scheduled from follow-on schedule check
[2025-09-21T23:21:07.505+0000] {local_task_job_runner.py:245} INFO - ::endgroup::
