[2025-09-21T23:22:11.388+0000] {local_task_job_runner.py:123} INFO - ::group::Pre task execution logs
[2025-09-21T23:22:11.414+0000] {taskinstance.py:2614} INFO - Dependencies all met for dep_context=non-requeueable deps ti=<TaskInstance: nawy_real_estate_pipeline.ingesting_data_from_sheets manual__2025-09-20T00:32:42.999536+00:00 [queued]>
[2025-09-21T23:22:11.425+0000] {taskinstance.py:2614} INFO - Dependencies all met for dep_context=requeueable deps ti=<TaskInstance: nawy_real_estate_pipeline.ingesting_data_from_sheets manual__2025-09-20T00:32:42.999536+00:00 [queued]>
[2025-09-21T23:22:11.425+0000] {taskinstance.py:2867} INFO - Starting attempt 2 of 2
[2025-09-21T23:22:11.579+0000] {taskinstance.py:2890} INFO - Executing <Task(BashOperator): ingesting_data_from_sheets> on 2025-09-20 00:32:42.999536+00:00
[2025-09-21T23:22:11.585+0000] {warnings.py:112} WARNING - /home/***/.local/lib/python3.12/site-packages/***/task/task_runner/standard_task_runner.py:70: DeprecationWarning: This process (pid=443) is multi-threaded, use of fork() may lead to deadlocks in the child.
  pid = os.fork()

[2025-09-21T23:22:11.587+0000] {standard_task_runner.py:72} INFO - Started process 447 to run task
[2025-09-21T23:22:11.587+0000] {standard_task_runner.py:104} INFO - Running: ['***', 'tasks', 'run', 'nawy_real_estate_pipeline', 'ingesting_data_from_sheets', 'manual__2025-09-20T00:32:42.999536+00:00', '--job-id', '378', '--raw', '--subdir', 'DAGS_FOLDER/nawy_dag.py', '--cfg-path', '/tmp/tmp641c04e2']
[2025-09-21T23:22:11.588+0000] {standard_task_runner.py:105} INFO - Job 378: Subtask ingesting_data_from_sheets
[2025-09-21T23:22:11.749+0000] {task_command.py:467} INFO - Running <TaskInstance: nawy_real_estate_pipeline.ingesting_data_from_sheets manual__2025-09-20T00:32:42.999536+00:00 [running]> on host b65782a7021d
[2025-09-21T23:22:12.139+0000] {taskinstance.py:3134} INFO - Exporting env vars: AIRFLOW_CTX_DAG_OWNER='***' AIRFLOW_CTX_DAG_ID='nawy_real_estate_pipeline' AIRFLOW_CTX_TASK_ID='ingesting_data_from_sheets' AIRFLOW_CTX_EXECUTION_DATE='2025-09-20T00:32:42.999536+00:00' AIRFLOW_CTX_TRY_NUMBER='2' AIRFLOW_CTX_DAG_RUN_ID='manual__2025-09-20T00:32:42.999536+00:00'
[2025-09-21T23:22:12.140+0000] {logging_mixin.py:190} INFO - Task instance is in running state
[2025-09-21T23:22:12.140+0000] {logging_mixin.py:190} INFO -  Previous state of the Task instance: queued
[2025-09-21T23:22:12.141+0000] {logging_mixin.py:190} INFO - Current task name:ingesting_data_from_sheets state:running start_date:2025-09-21 23:22:11.415000+00:00
[2025-09-21T23:22:12.141+0000] {logging_mixin.py:190} INFO - Dag name:nawy_real_estate_pipeline and current dag run status:running
[2025-09-21T23:22:12.142+0000] {taskinstance.py:732} INFO - ::endgroup::
[2025-09-21T23:22:12.143+0000] {subprocess.py:78} INFO - Tmp dir root location: /tmp
[2025-09-21T23:22:12.170+0000] {subprocess.py:88} INFO - Running command: ['/usr/bin/bash', '-c', ' cd /opt/***/dags/../include/nawy_dbt_project && dbt seed  ']
[2025-09-21T23:22:12.195+0000] {subprocess.py:99} INFO - Output:
[2025-09-21T23:22:18.708+0000] {subprocess.py:106} INFO - [0m23:22:18  Running with dbt=1.10.11
[2025-09-21T23:22:19.631+0000] {subprocess.py:106} INFO - [0m23:22:19  Registered adapter: postgres=1.9.1
[2025-09-21T23:22:19.996+0000] {subprocess.py:106} INFO - [0m23:22:19  Encountered an error:
[2025-09-21T23:22:19.997+0000] {subprocess.py:106} INFO - Compilation Error
[2025-09-21T23:22:19.999+0000] {subprocess.py:106} INFO -   dbt found 1 package(s) specified in packages.yml, but only 0 package(s) installed in dbt_packages. Run "dbt deps" to install package dependencies.
[2025-09-21T23:22:22.734+0000] {subprocess.py:110} INFO - Command exited with return code 2
[2025-09-21T23:22:22.756+0000] {taskinstance.py:3313} ERROR - Task failed with exception
Traceback (most recent call last):
  File "/home/airflow/.local/lib/python3.12/site-packages/airflow/models/taskinstance.py", line 768, in _execute_task
    result = _execute_callable(context=context, **execute_callable_kwargs)
             ^^^^^^^^^^^^^^^^^^^^^^^^^^^^^^^^^^^^^^^^^^^^^^^^^^^^^^^^^^^^^
  File "/home/airflow/.local/lib/python3.12/site-packages/airflow/models/taskinstance.py", line 734, in _execute_callable
    return ExecutionCallableRunner(
           ^^^^^^^^^^^^^^^^^^^^^^^^
  File "/home/airflow/.local/lib/python3.12/site-packages/airflow/utils/operator_helpers.py", line 252, in run
    return self.func(*args, **kwargs)
           ^^^^^^^^^^^^^^^^^^^^^^^^^^
  File "/home/airflow/.local/lib/python3.12/site-packages/airflow/models/baseoperator.py", line 424, in wrapper
    return func(self, *args, **kwargs)
           ^^^^^^^^^^^^^^^^^^^^^^^^^^^
  File "/home/airflow/.local/lib/python3.12/site-packages/airflow/operators/bash.py", line 276, in execute
    raise AirflowException(
airflow.exceptions.AirflowException: Bash command failed. The command returned a non-zero exit code 2.
[2025-09-21T23:22:22.765+0000] {logging_mixin.py:190} INFO - Task instance in failure state
[2025-09-21T23:22:22.766+0000] {logging_mixin.py:190} INFO - Task start:2025-09-21 23:22:11.415000+00:00 end:2025-09-21 23:22:22.764307+00:00 duration:11.349307
[2025-09-21T23:22:22.767+0000] {logging_mixin.py:190} INFO - Task:<Task(BashOperator): ingesting_data_from_sheets> dag:<DAG: nawy_real_estate_pipeline> dagrun:<DagRun nawy_real_estate_pipeline @ 2025-09-20 00:32:42.999536+00:00: manual__2025-09-20T00:32:42.999536+00:00, state:running, queued_at: 2025-09-21 23:03:47.690417+00:00. externally triggered: True>
[2025-09-21T23:22:22.768+0000] {logging_mixin.py:190} INFO - Failure caused by Bash command failed. The command returned a non-zero exit code 2.
[2025-09-21T23:22:22.768+0000] {taskinstance.py:1226} INFO - Marking task as FAILED. dag_id=nawy_real_estate_pipeline, task_id=ingesting_data_from_sheets, run_id=manual__2025-09-20T00:32:42.999536+00:00, execution_date=20250920T003242, start_date=20250921T232211, end_date=20250921T232222
[2025-09-21T23:22:22.921+0000] {taskinstance.py:341} INFO - ::group::Post task execution logs
[2025-09-21T23:22:22.923+0000] {standard_task_runner.py:124} ERROR - Failed to execute job 378 for task ingesting_data_from_sheets (Bash command failed. The command returned a non-zero exit code 2.; 447)
Traceback (most recent call last):
  File "/home/airflow/.local/lib/python3.12/site-packages/airflow/task/task_runner/standard_task_runner.py", line 117, in _start_by_fork
    ret = args.func(args, dag=self.dag)
          ^^^^^^^^^^^^^^^^^^^^^^^^^^^^^
  File "/home/airflow/.local/lib/python3.12/site-packages/airflow/cli/cli_config.py", line 49, in command
    return func(*args, **kwargs)
           ^^^^^^^^^^^^^^^^^^^^^
  File "/home/airflow/.local/lib/python3.12/site-packages/airflow/utils/cli.py", line 116, in wrapper
    return f(*args, **kwargs)
           ^^^^^^^^^^^^^^^^^^
  File "/home/airflow/.local/lib/python3.12/site-packages/airflow/cli/commands/task_command.py", line 483, in task_run
    task_return_code = _run_task_by_selected_method(args, _dag, ti)
                       ^^^^^^^^^^^^^^^^^^^^^^^^^^^^^^^^^^^^^^^^^^^^
  File "/home/airflow/.local/lib/python3.12/site-packages/airflow/cli/commands/task_command.py", line 256, in _run_task_by_selected_method
    return _run_raw_task(args, ti)
           ^^^^^^^^^^^^^^^^^^^^^^^
  File "/home/airflow/.local/lib/python3.12/site-packages/airflow/cli/commands/task_command.py", line 341, in _run_raw_task
    return ti._run_raw_task(
           ^^^^^^^^^^^^^^^^^
  File "/home/airflow/.local/lib/python3.12/site-packages/airflow/utils/session.py", line 97, in wrapper
    return func(*args, session=session, **kwargs)
           ^^^^^^^^^^^^^^^^^^^^^^^^^^^^^^^^^^^^^^
  File "/home/airflow/.local/lib/python3.12/site-packages/airflow/models/taskinstance.py", line 3006, in _run_raw_task
    return _run_raw_task(
           ^^^^^^^^^^^^^^
  File "/home/airflow/.local/lib/python3.12/site-packages/airflow/models/taskinstance.py", line 274, in _run_raw_task
    TaskInstance._execute_task_with_callbacks(
  File "/home/airflow/.local/lib/python3.12/site-packages/airflow/models/taskinstance.py", line 3161, in _execute_task_with_callbacks
    result = self._execute_task(context, task_orig)
             ^^^^^^^^^^^^^^^^^^^^^^^^^^^^^^^^^^^^^^
  File "/home/airflow/.local/lib/python3.12/site-packages/airflow/models/taskinstance.py", line 3185, in _execute_task
    return _execute_task(self, context, task_orig)
           ^^^^^^^^^^^^^^^^^^^^^^^^^^^^^^^^^^^^^^^
  File "/home/airflow/.local/lib/python3.12/site-packages/airflow/models/taskinstance.py", line 768, in _execute_task
    result = _execute_callable(context=context, **execute_callable_kwargs)
             ^^^^^^^^^^^^^^^^^^^^^^^^^^^^^^^^^^^^^^^^^^^^^^^^^^^^^^^^^^^^^
  File "/home/airflow/.local/lib/python3.12/site-packages/airflow/models/taskinstance.py", line 734, in _execute_callable
    return ExecutionCallableRunner(
           ^^^^^^^^^^^^^^^^^^^^^^^^
  File "/home/airflow/.local/lib/python3.12/site-packages/airflow/utils/operator_helpers.py", line 252, in run
    return self.func(*args, **kwargs)
           ^^^^^^^^^^^^^^^^^^^^^^^^^^
  File "/home/airflow/.local/lib/python3.12/site-packages/airflow/models/baseoperator.py", line 424, in wrapper
    return func(self, *args, **kwargs)
           ^^^^^^^^^^^^^^^^^^^^^^^^^^^
  File "/home/airflow/.local/lib/python3.12/site-packages/airflow/operators/bash.py", line 276, in execute
    raise AirflowException(
airflow.exceptions.AirflowException: Bash command failed. The command returned a non-zero exit code 2.
[2025-09-21T23:22:22.966+0000] {local_task_job_runner.py:266} INFO - Task exited with return code 1
[2025-09-21T23:22:23.020+0000] {taskinstance.py:3901} INFO - 0 downstream tasks scheduled from follow-on schedule check
[2025-09-21T23:22:23.076+0000] {local_task_job_runner.py:245} INFO - ::endgroup::
