[2025-09-21T23:22:19.315+0000] {local_task_job_runner.py:123} INFO - ::group::Pre task execution logs
[2025-09-21T23:22:19.357+0000] {taskinstance.py:2614} INFO - Dependencies all met for dep_context=non-requeueable deps ti=<TaskInstance: nawy_real_estate_pipeline.installing_required_dependencies manual__2025-09-21T13:43:16.523289+00:00 [queued]>
[2025-09-21T23:22:19.374+0000] {taskinstance.py:2614} INFO - Dependencies all met for dep_context=requeueable deps ti=<TaskInstance: nawy_real_estate_pipeline.installing_required_dependencies manual__2025-09-21T13:43:16.523289+00:00 [queued]>
[2025-09-21T23:22:19.375+0000] {taskinstance.py:2867} INFO - Starting attempt 2 of 2
[2025-09-21T23:22:19.455+0000] {taskinstance.py:2890} INFO - Executing <Task(BashOperator): installing_required_dependencies> on 2025-09-21 13:43:16.523289+00:00
[2025-09-21T23:22:19.466+0000] {warnings.py:112} WARNING - /home/***/.local/lib/python3.12/site-packages/***/task/task_runner/standard_task_runner.py:70: DeprecationWarning: This process (pid=452) is multi-threaded, use of fork() may lead to deadlocks in the child.
  pid = os.fork()

[2025-09-21T23:22:19.468+0000] {standard_task_runner.py:72} INFO - Started process 489 to run task
[2025-09-21T23:22:19.470+0000] {standard_task_runner.py:104} INFO - Running: ['***', 'tasks', 'run', 'nawy_real_estate_pipeline', 'installing_required_dependencies', 'manual__2025-09-21T13:43:16.523289+00:00', '--job-id', '384', '--raw', '--subdir', 'DAGS_FOLDER/nawy_dag.py', '--cfg-path', '/tmp/tmpsyev5lm_']
[2025-09-21T23:22:19.473+0000] {standard_task_runner.py:105} INFO - Job 384: Subtask installing_required_dependencies
[2025-09-21T23:22:19.613+0000] {task_command.py:467} INFO - Running <TaskInstance: nawy_real_estate_pipeline.installing_required_dependencies manual__2025-09-21T13:43:16.523289+00:00 [running]> on host b65782a7021d
[2025-09-21T23:22:19.884+0000] {taskinstance.py:3134} INFO - Exporting env vars: AIRFLOW_CTX_DAG_OWNER='***' AIRFLOW_CTX_DAG_ID='nawy_real_estate_pipeline' AIRFLOW_CTX_TASK_ID='installing_required_dependencies' AIRFLOW_CTX_EXECUTION_DATE='2025-09-21T13:43:16.523289+00:00' AIRFLOW_CTX_TRY_NUMBER='2' AIRFLOW_CTX_DAG_RUN_ID='manual__2025-09-21T13:43:16.523289+00:00'
[2025-09-21T23:22:19.886+0000] {logging_mixin.py:190} INFO - Task instance is in running state
[2025-09-21T23:22:19.887+0000] {logging_mixin.py:190} INFO -  Previous state of the Task instance: queued
[2025-09-21T23:22:19.888+0000] {logging_mixin.py:190} INFO - Current task name:installing_required_dependencies state:running start_date:2025-09-21 23:22:19.358825+00:00
[2025-09-21T23:22:19.889+0000] {logging_mixin.py:190} INFO - Dag name:nawy_real_estate_pipeline and current dag run status:running
[2025-09-21T23:22:19.889+0000] {taskinstance.py:732} INFO - ::endgroup::
[2025-09-21T23:22:19.891+0000] {subprocess.py:78} INFO - Tmp dir root location: /tmp
[2025-09-21T23:22:19.910+0000] {subprocess.py:88} INFO - Running command: ['/usr/bin/bash', '-c', ' cd /opt/***/dags/../include/nawy_dbt_project && dbt clean &&  dbt deps --no-version-check ']
[2025-09-21T23:22:19.938+0000] {subprocess.py:99} INFO - Output:
[2025-09-21T23:22:26.196+0000] {subprocess.py:106} INFO - [0m23:22:26  Running with dbt=1.10.11
[2025-09-21T23:22:26.871+0000] {subprocess.py:106} INFO - [0m23:22:26  Checking /opt/***/include/nawy_dbt_project/dbt_packages/*
[2025-09-21T23:22:26.873+0000] {subprocess.py:106} INFO - [0m23:22:26  Cleaned /opt/***/include/nawy_dbt_project/dbt_packages/*
[2025-09-21T23:22:26.876+0000] {subprocess.py:106} INFO - [0m23:22:26  Checking /opt/***/include/nawy_dbt_project/target/*
[2025-09-21T23:22:26.878+0000] {subprocess.py:106} INFO - [0m23:22:26  Cleaned /opt/***/include/nawy_dbt_project/target/*
[2025-09-21T23:22:26.880+0000] {subprocess.py:106} INFO - [0m23:22:26  Finished cleaning all paths.
[2025-09-21T23:22:36.505+0000] {subprocess.py:106} INFO - [0m23:22:36  Running with dbt=1.10.11
[2025-09-21T23:22:37.304+0000] {subprocess.py:106} INFO - [0m23:22:37  Encountered an error:
[2025-09-21T23:22:37.305+0000] {subprocess.py:106} INFO - [Errno 39] Directory not empty: 'dbt_packages/dbt-utils-1.3.0/integration_tests/data/schema_tests'
[2025-09-21T23:22:37.310+0000] {subprocess.py:106} INFO - [0m23:22:37  Traceback (most recent call last):
[2025-09-21T23:22:37.312+0000] {subprocess.py:106} INFO -   File "/home/***/.local/lib/python3.12/site-packages/dbt/cli/requires.py", line 178, in wrapper
[2025-09-21T23:22:37.312+0000] {subprocess.py:106} INFO -     result, success = func(*args, **kwargs)
[2025-09-21T23:22:37.313+0000] {subprocess.py:106} INFO -                       ^^^^^^^^^^^^^^^^^^^^^
[2025-09-21T23:22:37.314+0000] {subprocess.py:106} INFO -   File "/home/***/.local/lib/python3.12/site-packages/dbt/cli/requires.py", line 128, in wrapper
[2025-09-21T23:22:37.315+0000] {subprocess.py:106} INFO -     return func(*args, **kwargs)
[2025-09-21T23:22:37.316+0000] {subprocess.py:106} INFO -            ^^^^^^^^^^^^^^^^^^^^^
[2025-09-21T23:22:37.318+0000] {subprocess.py:106} INFO -   File "/home/***/.local/lib/python3.12/site-packages/dbt/cli/requires.py", line 254, in wrapper
[2025-09-21T23:22:37.319+0000] {subprocess.py:106} INFO -     return func(*args, **kwargs)
[2025-09-21T23:22:37.320+0000] {subprocess.py:106} INFO -            ^^^^^^^^^^^^^^^^^^^^^
[2025-09-21T23:22:37.322+0000] {subprocess.py:106} INFO -   File "/home/***/.local/lib/python3.12/site-packages/dbt/cli/requires.py", line 303, in wrapper
[2025-09-21T23:22:37.323+0000] {subprocess.py:106} INFO -     return func(*args, **kwargs)
[2025-09-21T23:22:37.323+0000] {subprocess.py:106} INFO -            ^^^^^^^^^^^^^^^^^^^^^
[2025-09-21T23:22:37.325+0000] {subprocess.py:106} INFO -   File "/home/***/.local/lib/python3.12/site-packages/dbt/cli/main.py", line 461, in deps
[2025-09-21T23:22:37.325+0000] {subprocess.py:106} INFO -     results = task.run()
[2025-09-21T23:22:37.326+0000] {subprocess.py:106} INFO -               ^^^^^^^^^^
[2025-09-21T23:22:37.327+0000] {subprocess.py:106} INFO -   File "/home/***/.local/lib/python3.12/site-packages/dbt/task/deps.py", line 231, in run
[2025-09-21T23:22:37.328+0000] {subprocess.py:106} INFO -     system.rmtree(self.project.packages_install_path)
[2025-09-21T23:22:37.330+0000] {subprocess.py:106} INFO -   File "/home/***/.local/lib/python3.12/site-packages/dbt_common/clients/system.py", line 718, in rmtree
[2025-09-21T23:22:37.331+0000] {subprocess.py:106} INFO -     return shutil.rmtree(path, onerror=chmod_and_retry)
[2025-09-21T23:22:37.332+0000] {subprocess.py:106} INFO -            ^^^^^^^^^^^^^^^^^^^^^^^^^^^^^^^^^^^^^^^^^^^^
[2025-09-21T23:22:37.335+0000] {subprocess.py:106} INFO -   File "/usr/local/lib/python3.12/shutil.py", line 759, in rmtree
[2025-09-21T23:22:37.337+0000] {subprocess.py:106} INFO -     _rmtree_safe_fd(stack, onexc)
[2025-09-21T23:22:37.339+0000] {subprocess.py:106} INFO -   File "/usr/local/lib/python3.12/shutil.py", line 703, in _rmtree_safe_fd
[2025-09-21T23:22:37.341+0000] {subprocess.py:106} INFO -     onexc(func, path, err)
[2025-09-21T23:22:37.342+0000] {subprocess.py:106} INFO -   File "/usr/local/lib/python3.12/shutil.py", line 750, in onexc
[2025-09-21T23:22:37.344+0000] {subprocess.py:106} INFO -     return onerror(func, path, exc_info)
[2025-09-21T23:22:37.345+0000] {subprocess.py:106} INFO -            ^^^^^^^^^^^^^^^^^^^^^^^^^^^^^
[2025-09-21T23:22:37.346+0000] {subprocess.py:106} INFO -   File "/usr/local/lib/python3.12/shutil.py", line 662, in _rmtree_safe_fd
[2025-09-21T23:22:37.347+0000] {subprocess.py:106} INFO -     os.rmdir(name, dir_fd=dirfd)
[2025-09-21T23:22:37.349+0000] {subprocess.py:106} INFO - OSError: [Errno 39] Directory not empty: 'dbt_packages/dbt-utils-1.3.0/integration_tests/data/schema_tests'
[2025-09-21T23:22:37.351+0000] {subprocess.py:106} INFO - 
[2025-09-21T23:22:38.476+0000] {subprocess.py:110} INFO - Command exited with return code 2
[2025-09-21T23:22:38.905+0000] {taskinstance.py:3313} ERROR - Task failed with exception
Traceback (most recent call last):
  File "/home/airflow/.local/lib/python3.12/site-packages/airflow/models/taskinstance.py", line 768, in _execute_task
    result = _execute_callable(context=context, **execute_callable_kwargs)
             ^^^^^^^^^^^^^^^^^^^^^^^^^^^^^^^^^^^^^^^^^^^^^^^^^^^^^^^^^^^^^
  File "/home/airflow/.local/lib/python3.12/site-packages/airflow/models/taskinstance.py", line 734, in _execute_callable
    return ExecutionCallableRunner(
           ^^^^^^^^^^^^^^^^^^^^^^^^
  File "/home/airflow/.local/lib/python3.12/site-packages/airflow/utils/operator_helpers.py", line 252, in run
    return self.func(*args, **kwargs)
           ^^^^^^^^^^^^^^^^^^^^^^^^^^
  File "/home/airflow/.local/lib/python3.12/site-packages/airflow/models/baseoperator.py", line 424, in wrapper
    return func(self, *args, **kwargs)
           ^^^^^^^^^^^^^^^^^^^^^^^^^^^
  File "/home/airflow/.local/lib/python3.12/site-packages/airflow/operators/bash.py", line 276, in execute
    raise AirflowException(
airflow.exceptions.AirflowException: Bash command failed. The command returned a non-zero exit code 2.
[2025-09-21T23:22:38.916+0000] {logging_mixin.py:190} INFO - Task instance in failure state
[2025-09-21T23:22:38.918+0000] {logging_mixin.py:190} INFO - Task start:2025-09-21 23:22:19.358825+00:00 end:2025-09-21 23:22:38.915719+00:00 duration:19.556894
[2025-09-21T23:22:38.919+0000] {logging_mixin.py:190} INFO - Task:<Task(BashOperator): installing_required_dependencies> dag:<DAG: nawy_real_estate_pipeline> dagrun:<DagRun nawy_real_estate_pipeline @ 2025-09-21 13:43:16.523289+00:00: manual__2025-09-21T13:43:16.523289+00:00, state:running, queued_at: 2025-09-21 23:03:47.690465+00:00. externally triggered: True>
[2025-09-21T23:22:38.920+0000] {logging_mixin.py:190} INFO - Failure caused by Bash command failed. The command returned a non-zero exit code 2.
[2025-09-21T23:22:38.921+0000] {taskinstance.py:1226} INFO - Marking task as FAILED. dag_id=nawy_real_estate_pipeline, task_id=installing_required_dependencies, run_id=manual__2025-09-21T13:43:16.523289+00:00, execution_date=20250921T134316, start_date=20250921T232219, end_date=20250921T232238
[2025-09-21T23:22:39.130+0000] {taskinstance.py:341} INFO - ::group::Post task execution logs
[2025-09-21T23:22:39.131+0000] {standard_task_runner.py:124} ERROR - Failed to execute job 384 for task installing_required_dependencies (Bash command failed. The command returned a non-zero exit code 2.; 489)
Traceback (most recent call last):
  File "/home/airflow/.local/lib/python3.12/site-packages/airflow/task/task_runner/standard_task_runner.py", line 117, in _start_by_fork
    ret = args.func(args, dag=self.dag)
          ^^^^^^^^^^^^^^^^^^^^^^^^^^^^^
  File "/home/airflow/.local/lib/python3.12/site-packages/airflow/cli/cli_config.py", line 49, in command
    return func(*args, **kwargs)
           ^^^^^^^^^^^^^^^^^^^^^
  File "/home/airflow/.local/lib/python3.12/site-packages/airflow/utils/cli.py", line 116, in wrapper
    return f(*args, **kwargs)
           ^^^^^^^^^^^^^^^^^^
  File "/home/airflow/.local/lib/python3.12/site-packages/airflow/cli/commands/task_command.py", line 483, in task_run
    task_return_code = _run_task_by_selected_method(args, _dag, ti)
                       ^^^^^^^^^^^^^^^^^^^^^^^^^^^^^^^^^^^^^^^^^^^^
  File "/home/airflow/.local/lib/python3.12/site-packages/airflow/cli/commands/task_command.py", line 256, in _run_task_by_selected_method
    return _run_raw_task(args, ti)
           ^^^^^^^^^^^^^^^^^^^^^^^
  File "/home/airflow/.local/lib/python3.12/site-packages/airflow/cli/commands/task_command.py", line 341, in _run_raw_task
    return ti._run_raw_task(
           ^^^^^^^^^^^^^^^^^
  File "/home/airflow/.local/lib/python3.12/site-packages/airflow/utils/session.py", line 97, in wrapper
    return func(*args, session=session, **kwargs)
           ^^^^^^^^^^^^^^^^^^^^^^^^^^^^^^^^^^^^^^
  File "/home/airflow/.local/lib/python3.12/site-packages/airflow/models/taskinstance.py", line 3006, in _run_raw_task
    return _run_raw_task(
           ^^^^^^^^^^^^^^
  File "/home/airflow/.local/lib/python3.12/site-packages/airflow/models/taskinstance.py", line 274, in _run_raw_task
    TaskInstance._execute_task_with_callbacks(
  File "/home/airflow/.local/lib/python3.12/site-packages/airflow/models/taskinstance.py", line 3161, in _execute_task_with_callbacks
    result = self._execute_task(context, task_orig)
             ^^^^^^^^^^^^^^^^^^^^^^^^^^^^^^^^^^^^^^
  File "/home/airflow/.local/lib/python3.12/site-packages/airflow/models/taskinstance.py", line 3185, in _execute_task
    return _execute_task(self, context, task_orig)
           ^^^^^^^^^^^^^^^^^^^^^^^^^^^^^^^^^^^^^^^
  File "/home/airflow/.local/lib/python3.12/site-packages/airflow/models/taskinstance.py", line 768, in _execute_task
    result = _execute_callable(context=context, **execute_callable_kwargs)
             ^^^^^^^^^^^^^^^^^^^^^^^^^^^^^^^^^^^^^^^^^^^^^^^^^^^^^^^^^^^^^
  File "/home/airflow/.local/lib/python3.12/site-packages/airflow/models/taskinstance.py", line 734, in _execute_callable
    return ExecutionCallableRunner(
           ^^^^^^^^^^^^^^^^^^^^^^^^
  File "/home/airflow/.local/lib/python3.12/site-packages/airflow/utils/operator_helpers.py", line 252, in run
    return self.func(*args, **kwargs)
           ^^^^^^^^^^^^^^^^^^^^^^^^^^
  File "/home/airflow/.local/lib/python3.12/site-packages/airflow/models/baseoperator.py", line 424, in wrapper
    return func(self, *args, **kwargs)
           ^^^^^^^^^^^^^^^^^^^^^^^^^^^
  File "/home/airflow/.local/lib/python3.12/site-packages/airflow/operators/bash.py", line 276, in execute
    raise AirflowException(
airflow.exceptions.AirflowException: Bash command failed. The command returned a non-zero exit code 2.
[2025-09-21T23:22:39.206+0000] {local_task_job_runner.py:266} INFO - Task exited with return code 1
[2025-09-21T23:22:39.281+0000] {taskinstance.py:3901} INFO - 0 downstream tasks scheduled from follow-on schedule check
[2025-09-21T23:22:39.314+0000] {local_task_job_runner.py:245} INFO - ::endgroup::
