[2025-09-21T23:21:30.190+0000] {local_task_job_runner.py:123} INFO - ::group::Pre task execution logs
[2025-09-21T23:21:30.235+0000] {taskinstance.py:2614} INFO - Dependencies all met for dep_context=non-requeueable deps ti=<TaskInstance: nawy_real_estate_pipeline.installing_required_dependencies manual__2025-09-20T05:58:46.185111+00:00 [queued]>
[2025-09-21T23:21:30.276+0000] {taskinstance.py:2614} INFO - Dependencies all met for dep_context=requeueable deps ti=<TaskInstance: nawy_real_estate_pipeline.installing_required_dependencies manual__2025-09-20T05:58:46.185111+00:00 [queued]>
[2025-09-21T23:21:30.277+0000] {taskinstance.py:2867} INFO - Starting attempt 1 of 1
[2025-09-21T23:21:30.468+0000] {taskinstance.py:2890} INFO - Executing <Task(BashOperator): installing_required_dependencies> on 2025-09-20 05:58:46.185111+00:00
[2025-09-21T23:21:30.483+0000] {warnings.py:112} WARNING - /home/***/.local/lib/python3.12/site-packages/***/task/task_runner/standard_task_runner.py:70: DeprecationWarning: This process (pid=288) is multi-threaded, use of fork() may lead to deadlocks in the child.
  pid = os.fork()

[2025-09-21T23:21:30.488+0000] {standard_task_runner.py:72} INFO - Started process 342 to run task
[2025-09-21T23:21:30.489+0000] {standard_task_runner.py:104} INFO - Running: ['***', 'tasks', 'run', 'nawy_real_estate_pipeline', 'installing_required_dependencies', 'manual__2025-09-20T05:58:46.185111+00:00', '--job-id', '370', '--raw', '--subdir', 'DAGS_FOLDER/nawy_dag.py', '--cfg-path', '/tmp/tmpczmg1qad']
[2025-09-21T23:21:30.495+0000] {standard_task_runner.py:105} INFO - Job 370: Subtask installing_required_dependencies
[2025-09-21T23:21:30.754+0000] {task_command.py:467} INFO - Running <TaskInstance: nawy_real_estate_pipeline.installing_required_dependencies manual__2025-09-20T05:58:46.185111+00:00 [running]> on host b65782a7021d
[2025-09-21T23:21:31.166+0000] {taskinstance.py:3134} INFO - Exporting env vars: AIRFLOW_CTX_DAG_OWNER='***' AIRFLOW_CTX_DAG_ID='nawy_real_estate_pipeline' AIRFLOW_CTX_TASK_ID='installing_required_dependencies' AIRFLOW_CTX_EXECUTION_DATE='2025-09-20T05:58:46.185111+00:00' AIRFLOW_CTX_TRY_NUMBER='1' AIRFLOW_CTX_DAG_RUN_ID='manual__2025-09-20T05:58:46.185111+00:00'
[2025-09-21T23:21:31.168+0000] {logging_mixin.py:190} INFO - Task instance is in running state
[2025-09-21T23:21:31.169+0000] {logging_mixin.py:190} INFO -  Previous state of the Task instance: queued
[2025-09-21T23:21:31.170+0000] {logging_mixin.py:190} INFO - Current task name:installing_required_dependencies state:running start_date:2025-09-21 23:21:30.236587+00:00
[2025-09-21T23:21:31.171+0000] {logging_mixin.py:190} INFO - Dag name:nawy_real_estate_pipeline and current dag run status:running
[2025-09-21T23:21:31.172+0000] {taskinstance.py:732} INFO - ::endgroup::
[2025-09-21T23:21:31.173+0000] {subprocess.py:78} INFO - Tmp dir root location: /tmp
[2025-09-21T23:21:31.216+0000] {subprocess.py:88} INFO - Running command: ['/usr/bin/bash', '-c', ' cd /opt/***/dags/../include/nawy_dbt_project && dbt clean &&  dbt deps --no-version-check ']
[2025-09-21T23:21:31.275+0000] {subprocess.py:99} INFO - Output:
[2025-09-21T23:21:43.493+0000] {subprocess.py:106} INFO - [0m23:21:43  Running with dbt=1.10.11
[2025-09-21T23:21:44.174+0000] {subprocess.py:106} INFO - [0m23:21:44  Checking /opt/***/include/nawy_dbt_project/target/*
[2025-09-21T23:21:44.175+0000] {subprocess.py:106} INFO - [0m23:21:44  Cleaned /opt/***/include/nawy_dbt_project/target/*
[2025-09-21T23:21:44.176+0000] {subprocess.py:106} INFO - [0m23:21:44  Checking /opt/***/include/nawy_dbt_project/dbt_packages/*
[2025-09-21T23:21:44.252+0000] {subprocess.py:106} INFO - [0m23:21:44  Cleaned /opt/***/include/nawy_dbt_project/dbt_packages/*
[2025-09-21T23:21:44.253+0000] {subprocess.py:106} INFO - [0m23:21:44  Finished cleaning all paths.
[2025-09-21T23:21:54.066+0000] {subprocess.py:106} INFO - [0m23:21:54  Running with dbt=1.10.11
[2025-09-21T23:21:54.908+0000] {subprocess.py:106} INFO - [0m23:21:54  Encountered an error:
[2025-09-21T23:21:54.910+0000] {subprocess.py:106} INFO - [Errno 2] No such file or directory: 'dbt_packages/dbt_utils/macros/sql'
[2025-09-21T23:21:54.923+0000] {subprocess.py:106} INFO - [0m23:21:54  Traceback (most recent call last):
[2025-09-21T23:21:54.925+0000] {subprocess.py:106} INFO -   File "/home/***/.local/lib/python3.12/site-packages/dbt/cli/requires.py", line 178, in wrapper
[2025-09-21T23:21:54.926+0000] {subprocess.py:106} INFO -     result, success = func(*args, **kwargs)
[2025-09-21T23:21:54.928+0000] {subprocess.py:106} INFO -                       ^^^^^^^^^^^^^^^^^^^^^
[2025-09-21T23:21:54.929+0000] {subprocess.py:106} INFO -   File "/home/***/.local/lib/python3.12/site-packages/dbt/cli/requires.py", line 128, in wrapper
[2025-09-21T23:21:54.931+0000] {subprocess.py:106} INFO -     return func(*args, **kwargs)
[2025-09-21T23:21:54.934+0000] {subprocess.py:106} INFO -            ^^^^^^^^^^^^^^^^^^^^^
[2025-09-21T23:21:54.936+0000] {subprocess.py:106} INFO -   File "/home/***/.local/lib/python3.12/site-packages/dbt/cli/requires.py", line 254, in wrapper
[2025-09-21T23:21:54.940+0000] {subprocess.py:106} INFO -     return func(*args, **kwargs)
[2025-09-21T23:21:54.941+0000] {subprocess.py:106} INFO -            ^^^^^^^^^^^^^^^^^^^^^
[2025-09-21T23:21:54.943+0000] {subprocess.py:106} INFO -   File "/home/***/.local/lib/python3.12/site-packages/dbt/cli/requires.py", line 303, in wrapper
[2025-09-21T23:21:54.944+0000] {subprocess.py:106} INFO -     return func(*args, **kwargs)
[2025-09-21T23:21:54.945+0000] {subprocess.py:106} INFO -            ^^^^^^^^^^^^^^^^^^^^^
[2025-09-21T23:21:54.946+0000] {subprocess.py:106} INFO -   File "/home/***/.local/lib/python3.12/site-packages/dbt/cli/main.py", line 461, in deps
[2025-09-21T23:21:54.947+0000] {subprocess.py:106} INFO -     results = task.run()
[2025-09-21T23:21:54.948+0000] {subprocess.py:106} INFO -               ^^^^^^^^^^
[2025-09-21T23:21:54.949+0000] {subprocess.py:106} INFO -   File "/home/***/.local/lib/python3.12/site-packages/dbt/task/deps.py", line 231, in run
[2025-09-21T23:21:54.951+0000] {subprocess.py:106} INFO -     system.rmtree(self.project.packages_install_path)
[2025-09-21T23:21:54.953+0000] {subprocess.py:106} INFO -   File "/home/***/.local/lib/python3.12/site-packages/dbt_common/clients/system.py", line 718, in rmtree
[2025-09-21T23:21:54.954+0000] {subprocess.py:106} INFO -     return shutil.rmtree(path, onerror=chmod_and_retry)
[2025-09-21T23:21:54.955+0000] {subprocess.py:106} INFO -            ^^^^^^^^^^^^^^^^^^^^^^^^^^^^^^^^^^^^^^^^^^^^
[2025-09-21T23:21:54.957+0000] {subprocess.py:106} INFO -   File "/usr/local/lib/python3.12/shutil.py", line 759, in rmtree
[2025-09-21T23:21:54.961+0000] {subprocess.py:106} INFO -     _rmtree_safe_fd(stack, onexc)
[2025-09-21T23:21:54.962+0000] {subprocess.py:106} INFO -   File "/usr/local/lib/python3.12/shutil.py", line 703, in _rmtree_safe_fd
[2025-09-21T23:21:54.963+0000] {subprocess.py:106} INFO -     onexc(func, path, err)
[2025-09-21T23:21:54.966+0000] {subprocess.py:106} INFO -   File "/usr/local/lib/python3.12/shutil.py", line 750, in onexc
[2025-09-21T23:21:54.967+0000] {subprocess.py:106} INFO -     return onerror(func, path, exc_info)
[2025-09-21T23:21:54.969+0000] {subprocess.py:106} INFO -            ^^^^^^^^^^^^^^^^^^^^^^^^^^^^^
[2025-09-21T23:21:54.970+0000] {subprocess.py:106} INFO -   File "/usr/local/lib/python3.12/shutil.py", line 700, in _rmtree_safe_fd
[2025-09-21T23:21:54.972+0000] {subprocess.py:106} INFO -     onexc(os.unlink, fullname, err)
[2025-09-21T23:21:54.973+0000] {subprocess.py:106} INFO -   File "/usr/local/lib/python3.12/shutil.py", line 750, in onexc
[2025-09-21T23:21:54.976+0000] {subprocess.py:106} INFO -     return onerror(func, path, exc_info)
[2025-09-21T23:21:54.977+0000] {subprocess.py:106} INFO -            ^^^^^^^^^^^^^^^^^^^^^^^^^^^^^
[2025-09-21T23:21:54.978+0000] {subprocess.py:106} INFO -   File "/usr/local/lib/python3.12/shutil.py", line 698, in _rmtree_safe_fd
[2025-09-21T23:21:54.979+0000] {subprocess.py:106} INFO -     os.unlink(entry.name, dir_fd=topfd)
[2025-09-21T23:21:54.980+0000] {subprocess.py:106} INFO - FileNotFoundError: [Errno 2] No such file or directory: 'dbt_packages/dbt_utils/macros/sql'
[2025-09-21T23:21:54.981+0000] {subprocess.py:106} INFO - 
[2025-09-21T23:21:56.171+0000] {subprocess.py:110} INFO - Command exited with return code 2
[2025-09-21T23:21:56.711+0000] {taskinstance.py:3313} ERROR - Task failed with exception
Traceback (most recent call last):
  File "/home/airflow/.local/lib/python3.12/site-packages/airflow/models/taskinstance.py", line 768, in _execute_task
    result = _execute_callable(context=context, **execute_callable_kwargs)
             ^^^^^^^^^^^^^^^^^^^^^^^^^^^^^^^^^^^^^^^^^^^^^^^^^^^^^^^^^^^^^
  File "/home/airflow/.local/lib/python3.12/site-packages/airflow/models/taskinstance.py", line 734, in _execute_callable
    return ExecutionCallableRunner(
           ^^^^^^^^^^^^^^^^^^^^^^^^
  File "/home/airflow/.local/lib/python3.12/site-packages/airflow/utils/operator_helpers.py", line 252, in run
    return self.func(*args, **kwargs)
           ^^^^^^^^^^^^^^^^^^^^^^^^^^
  File "/home/airflow/.local/lib/python3.12/site-packages/airflow/models/baseoperator.py", line 424, in wrapper
    return func(self, *args, **kwargs)
           ^^^^^^^^^^^^^^^^^^^^^^^^^^^
  File "/home/airflow/.local/lib/python3.12/site-packages/airflow/operators/bash.py", line 276, in execute
    raise AirflowException(
airflow.exceptions.AirflowException: Bash command failed. The command returned a non-zero exit code 2.
[2025-09-21T23:21:56.720+0000] {logging_mixin.py:190} INFO - Task instance in failure state
[2025-09-21T23:21:56.731+0000] {logging_mixin.py:190} INFO - Task start:2025-09-21 23:21:30.236587+00:00 end:2025-09-21 23:21:56.719560+00:00 duration:26.482973
[2025-09-21T23:21:56.733+0000] {logging_mixin.py:190} INFO - Task:<Task(BashOperator): installing_required_dependencies> dag:<DAG: nawy_real_estate_pipeline> dagrun:<DagRun nawy_real_estate_pipeline @ 2025-09-20 05:58:46.185111+00:00: manual__2025-09-20T05:58:46.185111+00:00, state:running, queued_at: 2025-09-21 23:03:47.691015+00:00. externally triggered: True>
[2025-09-21T23:21:56.740+0000] {logging_mixin.py:190} INFO - Failure caused by Bash command failed. The command returned a non-zero exit code 2.
[2025-09-21T23:21:56.744+0000] {taskinstance.py:1226} INFO - Marking task as FAILED. dag_id=nawy_real_estate_pipeline, task_id=installing_required_dependencies, run_id=manual__2025-09-20T05:58:46.185111+00:00, execution_date=20250920T055846, start_date=20250921T232130, end_date=20250921T232156
[2025-09-21T23:21:57.100+0000] {taskinstance.py:341} INFO - ::group::Post task execution logs
[2025-09-21T23:21:57.104+0000] {standard_task_runner.py:124} ERROR - Failed to execute job 370 for task installing_required_dependencies (Bash command failed. The command returned a non-zero exit code 2.; 342)
Traceback (most recent call last):
  File "/home/airflow/.local/lib/python3.12/site-packages/airflow/task/task_runner/standard_task_runner.py", line 117, in _start_by_fork
    ret = args.func(args, dag=self.dag)
          ^^^^^^^^^^^^^^^^^^^^^^^^^^^^^
  File "/home/airflow/.local/lib/python3.12/site-packages/airflow/cli/cli_config.py", line 49, in command
    return func(*args, **kwargs)
           ^^^^^^^^^^^^^^^^^^^^^
  File "/home/airflow/.local/lib/python3.12/site-packages/airflow/utils/cli.py", line 116, in wrapper
    return f(*args, **kwargs)
           ^^^^^^^^^^^^^^^^^^
  File "/home/airflow/.local/lib/python3.12/site-packages/airflow/cli/commands/task_command.py", line 483, in task_run
    task_return_code = _run_task_by_selected_method(args, _dag, ti)
                       ^^^^^^^^^^^^^^^^^^^^^^^^^^^^^^^^^^^^^^^^^^^^
  File "/home/airflow/.local/lib/python3.12/site-packages/airflow/cli/commands/task_command.py", line 256, in _run_task_by_selected_method
    return _run_raw_task(args, ti)
           ^^^^^^^^^^^^^^^^^^^^^^^
  File "/home/airflow/.local/lib/python3.12/site-packages/airflow/cli/commands/task_command.py", line 341, in _run_raw_task
    return ti._run_raw_task(
           ^^^^^^^^^^^^^^^^^
  File "/home/airflow/.local/lib/python3.12/site-packages/airflow/utils/session.py", line 97, in wrapper
    return func(*args, session=session, **kwargs)
           ^^^^^^^^^^^^^^^^^^^^^^^^^^^^^^^^^^^^^^
  File "/home/airflow/.local/lib/python3.12/site-packages/airflow/models/taskinstance.py", line 3006, in _run_raw_task
    return _run_raw_task(
           ^^^^^^^^^^^^^^
  File "/home/airflow/.local/lib/python3.12/site-packages/airflow/models/taskinstance.py", line 274, in _run_raw_task
    TaskInstance._execute_task_with_callbacks(
  File "/home/airflow/.local/lib/python3.12/site-packages/airflow/models/taskinstance.py", line 3161, in _execute_task_with_callbacks
    result = self._execute_task(context, task_orig)
             ^^^^^^^^^^^^^^^^^^^^^^^^^^^^^^^^^^^^^^
  File "/home/airflow/.local/lib/python3.12/site-packages/airflow/models/taskinstance.py", line 3185, in _execute_task
    return _execute_task(self, context, task_orig)
           ^^^^^^^^^^^^^^^^^^^^^^^^^^^^^^^^^^^^^^^
  File "/home/airflow/.local/lib/python3.12/site-packages/airflow/models/taskinstance.py", line 768, in _execute_task
    result = _execute_callable(context=context, **execute_callable_kwargs)
             ^^^^^^^^^^^^^^^^^^^^^^^^^^^^^^^^^^^^^^^^^^^^^^^^^^^^^^^^^^^^^
  File "/home/airflow/.local/lib/python3.12/site-packages/airflow/models/taskinstance.py", line 734, in _execute_callable
    return ExecutionCallableRunner(
           ^^^^^^^^^^^^^^^^^^^^^^^^
  File "/home/airflow/.local/lib/python3.12/site-packages/airflow/utils/operator_helpers.py", line 252, in run
    return self.func(*args, **kwargs)
           ^^^^^^^^^^^^^^^^^^^^^^^^^^
  File "/home/airflow/.local/lib/python3.12/site-packages/airflow/models/baseoperator.py", line 424, in wrapper
    return func(self, *args, **kwargs)
           ^^^^^^^^^^^^^^^^^^^^^^^^^^^
  File "/home/airflow/.local/lib/python3.12/site-packages/airflow/operators/bash.py", line 276, in execute
    raise AirflowException(
airflow.exceptions.AirflowException: Bash command failed. The command returned a non-zero exit code 2.
[2025-09-21T23:21:57.164+0000] {local_task_job_runner.py:266} INFO - Task exited with return code 1
[2025-09-21T23:21:57.212+0000] {taskinstance.py:3901} INFO - 0 downstream tasks scheduled from follow-on schedule check
[2025-09-21T23:21:57.327+0000] {local_task_job_runner.py:245} INFO - ::endgroup::
