[2025-09-21T23:22:18.292+0000] {local_task_job_runner.py:123} INFO - ::group::Pre task execution logs
[2025-09-21T23:22:18.336+0000] {taskinstance.py:2614} INFO - Dependencies all met for dep_context=non-requeueable deps ti=<TaskInstance: nawy_real_estate_pipeline.installing_required_dependencies manual__2025-09-21T14:08:54.593600+00:00 [queued]>
[2025-09-21T23:22:18.354+0000] {taskinstance.py:2614} INFO - Dependencies all met for dep_context=requeueable deps ti=<TaskInstance: nawy_real_estate_pipeline.installing_required_dependencies manual__2025-09-21T14:08:54.593600+00:00 [queued]>
[2025-09-21T23:22:18.355+0000] {taskinstance.py:2867} INFO - Starting attempt 2 of 2
[2025-09-21T23:22:18.475+0000] {taskinstance.py:2890} INFO - Executing <Task(BashOperator): installing_required_dependencies> on 2025-09-21 14:08:54.593600+00:00
[2025-09-21T23:22:18.487+0000] {warnings.py:112} WARNING - /home/***/.local/lib/python3.12/site-packages/***/task/task_runner/standard_task_runner.py:70: DeprecationWarning: This process (pid=455) is multi-threaded, use of fork() may lead to deadlocks in the child.
  pid = os.fork()

[2025-09-21T23:22:18.489+0000] {standard_task_runner.py:72} INFO - Started process 483 to run task
[2025-09-21T23:22:18.491+0000] {standard_task_runner.py:104} INFO - Running: ['***', 'tasks', 'run', 'nawy_real_estate_pipeline', 'installing_required_dependencies', 'manual__2025-09-21T14:08:54.593600+00:00', '--job-id', '383', '--raw', '--subdir', 'DAGS_FOLDER/nawy_dag.py', '--cfg-path', '/tmp/tmpsi6p2uyk']
[2025-09-21T23:22:18.493+0000] {standard_task_runner.py:105} INFO - Job 383: Subtask installing_required_dependencies
[2025-09-21T23:22:18.655+0000] {task_command.py:467} INFO - Running <TaskInstance: nawy_real_estate_pipeline.installing_required_dependencies manual__2025-09-21T14:08:54.593600+00:00 [running]> on host b65782a7021d
[2025-09-21T23:22:18.935+0000] {taskinstance.py:3134} INFO - Exporting env vars: AIRFLOW_CTX_DAG_OWNER='***' AIRFLOW_CTX_DAG_ID='nawy_real_estate_pipeline' AIRFLOW_CTX_TASK_ID='installing_required_dependencies' AIRFLOW_CTX_EXECUTION_DATE='2025-09-21T14:08:54.593600+00:00' AIRFLOW_CTX_TRY_NUMBER='2' AIRFLOW_CTX_DAG_RUN_ID='manual__2025-09-21T14:08:54.593600+00:00'
[2025-09-21T23:22:18.938+0000] {logging_mixin.py:190} INFO - Task instance is in running state
[2025-09-21T23:22:18.939+0000] {logging_mixin.py:190} INFO -  Previous state of the Task instance: queued
[2025-09-21T23:22:18.940+0000] {logging_mixin.py:190} INFO - Current task name:installing_required_dependencies state:running start_date:2025-09-21 23:22:18.337287+00:00
[2025-09-21T23:22:18.941+0000] {logging_mixin.py:190} INFO - Dag name:nawy_real_estate_pipeline and current dag run status:running
[2025-09-21T23:22:18.942+0000] {taskinstance.py:732} INFO - ::endgroup::
[2025-09-21T23:22:18.944+0000] {subprocess.py:78} INFO - Tmp dir root location: /tmp
[2025-09-21T23:22:18.959+0000] {subprocess.py:88} INFO - Running command: ['/usr/bin/bash', '-c', ' cd /opt/***/dags/../include/nawy_dbt_project && dbt clean &&  dbt deps --no-version-check ']
[2025-09-21T23:22:18.982+0000] {subprocess.py:99} INFO - Output:
[2025-09-21T23:22:25.364+0000] {subprocess.py:106} INFO - [0m23:22:25  Running with dbt=1.10.11
[2025-09-21T23:22:25.856+0000] {subprocess.py:106} INFO - [0m23:22:25  Checking /opt/***/include/nawy_dbt_project/dbt_packages/*
[2025-09-21T23:22:25.857+0000] {subprocess.py:106} INFO - [0m23:22:25  Cleaned /opt/***/include/nawy_dbt_project/dbt_packages/*
[2025-09-21T23:22:25.858+0000] {subprocess.py:106} INFO - [0m23:22:25  Checking /opt/***/include/nawy_dbt_project/target/*
[2025-09-21T23:22:25.859+0000] {subprocess.py:106} INFO - [0m23:22:25  Cleaned /opt/***/include/nawy_dbt_project/target/*
[2025-09-21T23:22:25.860+0000] {subprocess.py:106} INFO - [0m23:22:25  Finished cleaning all paths.
[2025-09-21T23:22:35.687+0000] {subprocess.py:106} INFO - [0m23:22:35  Running with dbt=1.10.11
[2025-09-21T23:22:36.423+0000] {subprocess.py:106} INFO - [0m23:22:36  Installing dbt-labs/dbt_utils
[2025-09-21T23:22:40.305+0000] {subprocess.py:106} INFO - [0m23:22:40  Encountered an error:
[2025-09-21T23:22:40.306+0000] {subprocess.py:106} INFO - [Errno 2] No such file or directory: 'dbt_packages/dbt-utils-1.3.0/integration_tests/models/sql/test_star_uppercase.sql'
[2025-09-21T23:22:40.313+0000] {subprocess.py:106} INFO - [0m23:22:40  Traceback (most recent call last):
[2025-09-21T23:22:40.314+0000] {subprocess.py:106} INFO -   File "/home/***/.local/lib/python3.12/site-packages/dbt/cli/requires.py", line 178, in wrapper
[2025-09-21T23:22:40.315+0000] {subprocess.py:106} INFO -     result, success = func(*args, **kwargs)
[2025-09-21T23:22:40.316+0000] {subprocess.py:106} INFO -                       ^^^^^^^^^^^^^^^^^^^^^
[2025-09-21T23:22:40.317+0000] {subprocess.py:106} INFO -   File "/home/***/.local/lib/python3.12/site-packages/dbt/cli/requires.py", line 128, in wrapper
[2025-09-21T23:22:40.319+0000] {subprocess.py:106} INFO -     return func(*args, **kwargs)
[2025-09-21T23:22:40.320+0000] {subprocess.py:106} INFO -            ^^^^^^^^^^^^^^^^^^^^^
[2025-09-21T23:22:40.321+0000] {subprocess.py:106} INFO -   File "/home/***/.local/lib/python3.12/site-packages/dbt/cli/requires.py", line 254, in wrapper
[2025-09-21T23:22:40.322+0000] {subprocess.py:106} INFO -     return func(*args, **kwargs)
[2025-09-21T23:22:40.323+0000] {subprocess.py:106} INFO -            ^^^^^^^^^^^^^^^^^^^^^
[2025-09-21T23:22:40.324+0000] {subprocess.py:106} INFO -   File "/home/***/.local/lib/python3.12/site-packages/dbt/cli/requires.py", line 303, in wrapper
[2025-09-21T23:22:40.325+0000] {subprocess.py:106} INFO -     return func(*args, **kwargs)
[2025-09-21T23:22:40.326+0000] {subprocess.py:106} INFO -            ^^^^^^^^^^^^^^^^^^^^^
[2025-09-21T23:22:40.327+0000] {subprocess.py:106} INFO -   File "/home/***/.local/lib/python3.12/site-packages/dbt/cli/main.py", line 461, in deps
[2025-09-21T23:22:40.329+0000] {subprocess.py:106} INFO -     results = task.run()
[2025-09-21T23:22:40.330+0000] {subprocess.py:106} INFO -               ^^^^^^^^^^
[2025-09-21T23:22:40.331+0000] {subprocess.py:106} INFO -   File "/home/***/.local/lib/python3.12/site-packages/dbt/task/deps.py", line 258, in run
[2025-09-21T23:22:40.333+0000] {subprocess.py:106} INFO -     package.install(self.project, renderer)
[2025-09-21T23:22:40.334+0000] {subprocess.py:106} INFO -   File "/home/***/.local/lib/python3.12/site-packages/dbt/deps/registry.py", line 63, in install
[2025-09-21T23:22:40.335+0000] {subprocess.py:106} INFO -     self._install(project, renderer)
[2025-09-21T23:22:40.336+0000] {subprocess.py:106} INFO -   File "/home/***/.local/lib/python3.12/site-packages/dbt/deps/base.py", line 121, in _install
[2025-09-21T23:22:40.337+0000] {subprocess.py:106} INFO -     connection_exception_retry(download_untar_fn, 5)
[2025-09-21T23:22:40.338+0000] {subprocess.py:106} INFO -   File "/home/***/.local/lib/python3.12/site-packages/dbt_common/utils/connection.py", line 22, in connection_exception_retry
[2025-09-21T23:22:40.342+0000] {subprocess.py:106} INFO -     return fn()
[2025-09-21T23:22:40.343+0000] {subprocess.py:106} INFO -            ^^^^
[2025-09-21T23:22:40.344+0000] {subprocess.py:106} INFO -   File "/home/***/.local/lib/python3.12/site-packages/dbt/deps/base.py", line 133, in download_and_untar
[2025-09-21T23:22:40.345+0000] {subprocess.py:106} INFO -     system.untar_package(tar_path, deps_path, package_name)
[2025-09-21T23:22:40.346+0000] {subprocess.py:106} INFO -   File "/home/***/.local/lib/python3.12/site-packages/dbt_common/clients/system.py", line 644, in untar_package
[2025-09-21T23:22:40.347+0000] {subprocess.py:106} INFO -     safe_extract(tarball, dest_dir)
[2025-09-21T23:22:40.348+0000] {subprocess.py:106} INFO -   File "/home/***/.local/lib/python3.12/site-packages/dbt_common/clients/system.py", line 637, in safe_extract
[2025-09-21T23:22:40.349+0000] {subprocess.py:106} INFO -     tarball.extractall(path, members=members)
[2025-09-21T23:22:40.350+0000] {subprocess.py:106} INFO -   File "/usr/local/lib/python3.12/tarfile.py", line 2302, in extractall
[2025-09-21T23:22:40.351+0000] {subprocess.py:106} INFO -     self._extract_one(tarinfo, path, set_attrs=not tarinfo.isdir(),
[2025-09-21T23:22:40.352+0000] {subprocess.py:106} INFO -   File "/usr/local/lib/python3.12/tarfile.py", line 2369, in _extract_one
[2025-09-21T23:22:40.352+0000] {subprocess.py:106} INFO -     self._handle_fatal_error(e)
[2025-09-21T23:22:40.353+0000] {subprocess.py:106} INFO -   File "/usr/local/lib/python3.12/tarfile.py", line 2365, in _extract_one
[2025-09-21T23:22:40.354+0000] {subprocess.py:106} INFO -     self._extract_member(tarinfo, os.path.join(path, tarinfo.name),
[2025-09-21T23:22:40.355+0000] {subprocess.py:106} INFO -   File "/usr/local/lib/python3.12/tarfile.py", line 2448, in _extract_member
[2025-09-21T23:22:40.356+0000] {subprocess.py:106} INFO -     self.makefile(tarinfo, targetpath)
[2025-09-21T23:22:40.357+0000] {subprocess.py:106} INFO -   File "/usr/local/lib/python3.12/tarfile.py", line 2494, in makefile
[2025-09-21T23:22:40.358+0000] {subprocess.py:106} INFO -     with bltn_open(targetpath, "wb") as target:
[2025-09-21T23:22:40.358+0000] {subprocess.py:106} INFO -          ^^^^^^^^^^^^^^^^^^^^^^^^^^^
[2025-09-21T23:22:40.359+0000] {subprocess.py:106} INFO - FileNotFoundError: [Errno 2] No such file or directory: 'dbt_packages/dbt-utils-1.3.0/integration_tests/models/sql/test_star_uppercase.sql'
[2025-09-21T23:22:40.360+0000] {subprocess.py:106} INFO - 
[2025-09-21T23:22:41.408+0000] {subprocess.py:110} INFO - Command exited with return code 2
[2025-09-21T23:22:41.776+0000] {taskinstance.py:3313} ERROR - Task failed with exception
Traceback (most recent call last):
  File "/home/airflow/.local/lib/python3.12/site-packages/airflow/models/taskinstance.py", line 768, in _execute_task
    result = _execute_callable(context=context, **execute_callable_kwargs)
             ^^^^^^^^^^^^^^^^^^^^^^^^^^^^^^^^^^^^^^^^^^^^^^^^^^^^^^^^^^^^^
  File "/home/airflow/.local/lib/python3.12/site-packages/airflow/models/taskinstance.py", line 734, in _execute_callable
    return ExecutionCallableRunner(
           ^^^^^^^^^^^^^^^^^^^^^^^^
  File "/home/airflow/.local/lib/python3.12/site-packages/airflow/utils/operator_helpers.py", line 252, in run
    return self.func(*args, **kwargs)
           ^^^^^^^^^^^^^^^^^^^^^^^^^^
  File "/home/airflow/.local/lib/python3.12/site-packages/airflow/models/baseoperator.py", line 424, in wrapper
    return func(self, *args, **kwargs)
           ^^^^^^^^^^^^^^^^^^^^^^^^^^^
  File "/home/airflow/.local/lib/python3.12/site-packages/airflow/operators/bash.py", line 276, in execute
    raise AirflowException(
airflow.exceptions.AirflowException: Bash command failed. The command returned a non-zero exit code 2.
[2025-09-21T23:22:41.783+0000] {logging_mixin.py:190} INFO - Task instance in failure state
[2025-09-21T23:22:41.784+0000] {logging_mixin.py:190} INFO - Task start:2025-09-21 23:22:18.337287+00:00 end:2025-09-21 23:22:41.782510+00:00 duration:23.445223
[2025-09-21T23:22:41.785+0000] {logging_mixin.py:190} INFO - Task:<Task(BashOperator): installing_required_dependencies> dag:<DAG: nawy_real_estate_pipeline> dagrun:<DagRun nawy_real_estate_pipeline @ 2025-09-21 14:08:54.593600+00:00: manual__2025-09-21T14:08:54.593600+00:00, state:running, queued_at: 2025-09-21 23:03:47.690990+00:00. externally triggered: True>
[2025-09-21T23:22:41.785+0000] {logging_mixin.py:190} INFO - Failure caused by Bash command failed. The command returned a non-zero exit code 2.
[2025-09-21T23:22:41.786+0000] {taskinstance.py:1226} INFO - Marking task as FAILED. dag_id=nawy_real_estate_pipeline, task_id=installing_required_dependencies, run_id=manual__2025-09-21T14:08:54.593600+00:00, execution_date=20250921T140854, start_date=20250921T232218, end_date=20250921T232241
[2025-09-21T23:22:41.981+0000] {taskinstance.py:341} INFO - ::group::Post task execution logs
[2025-09-21T23:22:41.983+0000] {standard_task_runner.py:124} ERROR - Failed to execute job 383 for task installing_required_dependencies (Bash command failed. The command returned a non-zero exit code 2.; 483)
Traceback (most recent call last):
  File "/home/airflow/.local/lib/python3.12/site-packages/airflow/task/task_runner/standard_task_runner.py", line 117, in _start_by_fork
    ret = args.func(args, dag=self.dag)
          ^^^^^^^^^^^^^^^^^^^^^^^^^^^^^
  File "/home/airflow/.local/lib/python3.12/site-packages/airflow/cli/cli_config.py", line 49, in command
    return func(*args, **kwargs)
           ^^^^^^^^^^^^^^^^^^^^^
  File "/home/airflow/.local/lib/python3.12/site-packages/airflow/utils/cli.py", line 116, in wrapper
    return f(*args, **kwargs)
           ^^^^^^^^^^^^^^^^^^
  File "/home/airflow/.local/lib/python3.12/site-packages/airflow/cli/commands/task_command.py", line 483, in task_run
    task_return_code = _run_task_by_selected_method(args, _dag, ti)
                       ^^^^^^^^^^^^^^^^^^^^^^^^^^^^^^^^^^^^^^^^^^^^
  File "/home/airflow/.local/lib/python3.12/site-packages/airflow/cli/commands/task_command.py", line 256, in _run_task_by_selected_method
    return _run_raw_task(args, ti)
           ^^^^^^^^^^^^^^^^^^^^^^^
  File "/home/airflow/.local/lib/python3.12/site-packages/airflow/cli/commands/task_command.py", line 341, in _run_raw_task
    return ti._run_raw_task(
           ^^^^^^^^^^^^^^^^^
  File "/home/airflow/.local/lib/python3.12/site-packages/airflow/utils/session.py", line 97, in wrapper
    return func(*args, session=session, **kwargs)
           ^^^^^^^^^^^^^^^^^^^^^^^^^^^^^^^^^^^^^^
  File "/home/airflow/.local/lib/python3.12/site-packages/airflow/models/taskinstance.py", line 3006, in _run_raw_task
    return _run_raw_task(
           ^^^^^^^^^^^^^^
  File "/home/airflow/.local/lib/python3.12/site-packages/airflow/models/taskinstance.py", line 274, in _run_raw_task
    TaskInstance._execute_task_with_callbacks(
  File "/home/airflow/.local/lib/python3.12/site-packages/airflow/models/taskinstance.py", line 3161, in _execute_task_with_callbacks
    result = self._execute_task(context, task_orig)
             ^^^^^^^^^^^^^^^^^^^^^^^^^^^^^^^^^^^^^^
  File "/home/airflow/.local/lib/python3.12/site-packages/airflow/models/taskinstance.py", line 3185, in _execute_task
    return _execute_task(self, context, task_orig)
           ^^^^^^^^^^^^^^^^^^^^^^^^^^^^^^^^^^^^^^^
  File "/home/airflow/.local/lib/python3.12/site-packages/airflow/models/taskinstance.py", line 768, in _execute_task
    result = _execute_callable(context=context, **execute_callable_kwargs)
             ^^^^^^^^^^^^^^^^^^^^^^^^^^^^^^^^^^^^^^^^^^^^^^^^^^^^^^^^^^^^^
  File "/home/airflow/.local/lib/python3.12/site-packages/airflow/models/taskinstance.py", line 734, in _execute_callable
    return ExecutionCallableRunner(
           ^^^^^^^^^^^^^^^^^^^^^^^^
  File "/home/airflow/.local/lib/python3.12/site-packages/airflow/utils/operator_helpers.py", line 252, in run
    return self.func(*args, **kwargs)
           ^^^^^^^^^^^^^^^^^^^^^^^^^^
  File "/home/airflow/.local/lib/python3.12/site-packages/airflow/models/baseoperator.py", line 424, in wrapper
    return func(self, *args, **kwargs)
           ^^^^^^^^^^^^^^^^^^^^^^^^^^^
  File "/home/airflow/.local/lib/python3.12/site-packages/airflow/operators/bash.py", line 276, in execute
    raise AirflowException(
airflow.exceptions.AirflowException: Bash command failed. The command returned a non-zero exit code 2.
[2025-09-21T23:22:42.058+0000] {local_task_job_runner.py:266} INFO - Task exited with return code 1
[2025-09-21T23:22:42.115+0000] {taskinstance.py:3901} INFO - 0 downstream tasks scheduled from follow-on schedule check
[2025-09-21T23:22:42.151+0000] {local_task_job_runner.py:245} INFO - ::endgroup::
