[2025-09-21T23:22:20.953+0000] {local_task_job_runner.py:123} INFO - ::group::Pre task execution logs
[2025-09-21T23:22:20.997+0000] {taskinstance.py:2614} INFO - Dependencies all met for dep_context=non-requeueable deps ti=<TaskInstance: nawy_real_estate_pipeline.installing_required_dependencies manual__2025-09-20T07:54:34.754250+00:00 [queued]>
[2025-09-21T23:22:21.015+0000] {taskinstance.py:2614} INFO - Dependencies all met for dep_context=requeueable deps ti=<TaskInstance: nawy_real_estate_pipeline.installing_required_dependencies manual__2025-09-20T07:54:34.754250+00:00 [queued]>
[2025-09-21T23:22:21.016+0000] {taskinstance.py:2867} INFO - Starting attempt 2 of 2
[2025-09-21T23:22:21.072+0000] {taskinstance.py:2890} INFO - Executing <Task(BashOperator): installing_required_dependencies> on 2025-09-20 07:54:34.754250+00:00
[2025-09-21T23:22:21.082+0000] {warnings.py:112} WARNING - /home/***/.local/lib/python3.12/site-packages/***/task/task_runner/standard_task_runner.py:70: DeprecationWarning: This process (pid=446) is multi-threaded, use of fork() may lead to deadlocks in the child.
  pid = os.fork()

[2025-09-21T23:22:21.086+0000] {standard_task_runner.py:72} INFO - Started process 494 to run task
[2025-09-21T23:22:21.086+0000] {standard_task_runner.py:104} INFO - Running: ['***', 'tasks', 'run', 'nawy_real_estate_pipeline', 'installing_required_dependencies', 'manual__2025-09-20T07:54:34.754250+00:00', '--job-id', '385', '--raw', '--subdir', 'DAGS_FOLDER/nawy_dag.py', '--cfg-path', '/tmp/tmpbu0m5x7i']
[2025-09-21T23:22:21.088+0000] {standard_task_runner.py:105} INFO - Job 385: Subtask installing_required_dependencies
[2025-09-21T23:22:21.204+0000] {task_command.py:467} INFO - Running <TaskInstance: nawy_real_estate_pipeline.installing_required_dependencies manual__2025-09-20T07:54:34.754250+00:00 [running]> on host b65782a7021d
[2025-09-21T23:22:21.797+0000] {taskinstance.py:3134} INFO - Exporting env vars: AIRFLOW_CTX_DAG_OWNER='***' AIRFLOW_CTX_DAG_ID='nawy_real_estate_pipeline' AIRFLOW_CTX_TASK_ID='installing_required_dependencies' AIRFLOW_CTX_EXECUTION_DATE='2025-09-20T07:54:34.754250+00:00' AIRFLOW_CTX_TRY_NUMBER='2' AIRFLOW_CTX_DAG_RUN_ID='manual__2025-09-20T07:54:34.754250+00:00'
[2025-09-21T23:22:21.799+0000] {logging_mixin.py:190} INFO - Task instance is in running state
[2025-09-21T23:22:21.800+0000] {logging_mixin.py:190} INFO -  Previous state of the Task instance: queued
[2025-09-21T23:22:21.801+0000] {logging_mixin.py:190} INFO - Current task name:installing_required_dependencies state:running start_date:2025-09-21 23:22:20.998306+00:00
[2025-09-21T23:22:21.802+0000] {logging_mixin.py:190} INFO - Dag name:nawy_real_estate_pipeline and current dag run status:running
[2025-09-21T23:22:21.803+0000] {taskinstance.py:732} INFO - ::endgroup::
[2025-09-21T23:22:21.805+0000] {subprocess.py:78} INFO - Tmp dir root location: /tmp
[2025-09-21T23:22:21.874+0000] {subprocess.py:88} INFO - Running command: ['/usr/bin/bash', '-c', ' cd /opt/***/dags/../include/nawy_dbt_project && dbt clean &&  dbt deps --no-version-check ']
[2025-09-21T23:22:21.891+0000] {subprocess.py:99} INFO - Output:
[2025-09-21T23:22:28.449+0000] {subprocess.py:106} INFO - [0m23:22:28  Running with dbt=1.10.11
[2025-09-21T23:22:28.970+0000] {subprocess.py:106} INFO - [0m23:22:28  Checking /opt/***/include/nawy_dbt_project/target/*
[2025-09-21T23:22:28.973+0000] {subprocess.py:106} INFO - [0m23:22:28  Cleaned /opt/***/include/nawy_dbt_project/target/*
[2025-09-21T23:22:28.974+0000] {subprocess.py:106} INFO - [0m23:22:28  Checking /opt/***/include/nawy_dbt_project/dbt_packages/*
[2025-09-21T23:22:28.976+0000] {subprocess.py:106} INFO - [0m23:22:28  Cleaned /opt/***/include/nawy_dbt_project/dbt_packages/*
[2025-09-21T23:22:28.978+0000] {subprocess.py:106} INFO - [0m23:22:28  Finished cleaning all paths.
[2025-09-21T23:22:38.707+0000] {subprocess.py:106} INFO - [0m23:22:38  Running with dbt=1.10.11
[2025-09-21T23:22:39.469+0000] {subprocess.py:106} INFO - [0m23:22:39  Encountered an error:
[2025-09-21T23:22:39.470+0000] {subprocess.py:106} INFO - [Errno 39] Directory not empty: 'dbt_packages/dbt-utils-1.3.0/macros/generic_tests'
[2025-09-21T23:22:39.476+0000] {subprocess.py:106} INFO - [0m23:22:39  Traceback (most recent call last):
[2025-09-21T23:22:39.478+0000] {subprocess.py:106} INFO -   File "/home/***/.local/lib/python3.12/site-packages/dbt/cli/requires.py", line 178, in wrapper
[2025-09-21T23:22:39.479+0000] {subprocess.py:106} INFO -     result, success = func(*args, **kwargs)
[2025-09-21T23:22:39.480+0000] {subprocess.py:106} INFO -                       ^^^^^^^^^^^^^^^^^^^^^
[2025-09-21T23:22:39.481+0000] {subprocess.py:106} INFO -   File "/home/***/.local/lib/python3.12/site-packages/dbt/cli/requires.py", line 128, in wrapper
[2025-09-21T23:22:39.482+0000] {subprocess.py:106} INFO -     return func(*args, **kwargs)
[2025-09-21T23:22:39.483+0000] {subprocess.py:106} INFO -            ^^^^^^^^^^^^^^^^^^^^^
[2025-09-21T23:22:39.485+0000] {subprocess.py:106} INFO -   File "/home/***/.local/lib/python3.12/site-packages/dbt/cli/requires.py", line 254, in wrapper
[2025-09-21T23:22:39.486+0000] {subprocess.py:106} INFO -     return func(*args, **kwargs)
[2025-09-21T23:22:39.488+0000] {subprocess.py:106} INFO -            ^^^^^^^^^^^^^^^^^^^^^
[2025-09-21T23:22:39.490+0000] {subprocess.py:106} INFO -   File "/home/***/.local/lib/python3.12/site-packages/dbt/cli/requires.py", line 303, in wrapper
[2025-09-21T23:22:39.491+0000] {subprocess.py:106} INFO -     return func(*args, **kwargs)
[2025-09-21T23:22:39.493+0000] {subprocess.py:106} INFO -            ^^^^^^^^^^^^^^^^^^^^^
[2025-09-21T23:22:39.494+0000] {subprocess.py:106} INFO -   File "/home/***/.local/lib/python3.12/site-packages/dbt/cli/main.py", line 461, in deps
[2025-09-21T23:22:39.495+0000] {subprocess.py:106} INFO -     results = task.run()
[2025-09-21T23:22:39.496+0000] {subprocess.py:106} INFO -               ^^^^^^^^^^
[2025-09-21T23:22:39.498+0000] {subprocess.py:106} INFO -   File "/home/***/.local/lib/python3.12/site-packages/dbt/task/deps.py", line 231, in run
[2025-09-21T23:22:39.499+0000] {subprocess.py:106} INFO -     system.rmtree(self.project.packages_install_path)
[2025-09-21T23:22:39.500+0000] {subprocess.py:106} INFO -   File "/home/***/.local/lib/python3.12/site-packages/dbt_common/clients/system.py", line 718, in rmtree
[2025-09-21T23:22:39.502+0000] {subprocess.py:106} INFO -     return shutil.rmtree(path, onerror=chmod_and_retry)
[2025-09-21T23:22:39.503+0000] {subprocess.py:106} INFO -            ^^^^^^^^^^^^^^^^^^^^^^^^^^^^^^^^^^^^^^^^^^^^
[2025-09-21T23:22:39.504+0000] {subprocess.py:106} INFO -   File "/usr/local/lib/python3.12/shutil.py", line 759, in rmtree
[2025-09-21T23:22:39.505+0000] {subprocess.py:106} INFO -     _rmtree_safe_fd(stack, onexc)
[2025-09-21T23:22:39.506+0000] {subprocess.py:106} INFO -   File "/usr/local/lib/python3.12/shutil.py", line 703, in _rmtree_safe_fd
[2025-09-21T23:22:39.508+0000] {subprocess.py:106} INFO -     onexc(func, path, err)
[2025-09-21T23:22:39.509+0000] {subprocess.py:106} INFO -   File "/usr/local/lib/python3.12/shutil.py", line 750, in onexc
[2025-09-21T23:22:39.510+0000] {subprocess.py:106} INFO -     return onerror(func, path, exc_info)
[2025-09-21T23:22:39.512+0000] {subprocess.py:106} INFO -            ^^^^^^^^^^^^^^^^^^^^^^^^^^^^^
[2025-09-21T23:22:39.513+0000] {subprocess.py:106} INFO -   File "/usr/local/lib/python3.12/shutil.py", line 662, in _rmtree_safe_fd
[2025-09-21T23:22:39.514+0000] {subprocess.py:106} INFO -     os.rmdir(name, dir_fd=dirfd)
[2025-09-21T23:22:39.516+0000] {subprocess.py:106} INFO - OSError: [Errno 39] Directory not empty: 'dbt_packages/dbt-utils-1.3.0/macros/generic_tests'
[2025-09-21T23:22:39.517+0000] {subprocess.py:106} INFO - 
[2025-09-21T23:22:40.700+0000] {subprocess.py:110} INFO - Command exited with return code 2
[2025-09-21T23:22:40.723+0000] {taskinstance.py:3313} ERROR - Task failed with exception
Traceback (most recent call last):
  File "/home/airflow/.local/lib/python3.12/site-packages/airflow/models/taskinstance.py", line 768, in _execute_task
    result = _execute_callable(context=context, **execute_callable_kwargs)
             ^^^^^^^^^^^^^^^^^^^^^^^^^^^^^^^^^^^^^^^^^^^^^^^^^^^^^^^^^^^^^
  File "/home/airflow/.local/lib/python3.12/site-packages/airflow/models/taskinstance.py", line 734, in _execute_callable
    return ExecutionCallableRunner(
           ^^^^^^^^^^^^^^^^^^^^^^^^
  File "/home/airflow/.local/lib/python3.12/site-packages/airflow/utils/operator_helpers.py", line 252, in run
    return self.func(*args, **kwargs)
           ^^^^^^^^^^^^^^^^^^^^^^^^^^
  File "/home/airflow/.local/lib/python3.12/site-packages/airflow/models/baseoperator.py", line 424, in wrapper
    return func(self, *args, **kwargs)
           ^^^^^^^^^^^^^^^^^^^^^^^^^^^
  File "/home/airflow/.local/lib/python3.12/site-packages/airflow/operators/bash.py", line 276, in execute
    raise AirflowException(
airflow.exceptions.AirflowException: Bash command failed. The command returned a non-zero exit code 2.
[2025-09-21T23:22:40.730+0000] {logging_mixin.py:190} INFO - Task instance in failure state
[2025-09-21T23:22:40.731+0000] {logging_mixin.py:190} INFO - Task start:2025-09-21 23:22:20.998306+00:00 end:2025-09-21 23:22:40.729734+00:00 duration:19.731428
[2025-09-21T23:22:40.732+0000] {logging_mixin.py:190} INFO - Task:<Task(BashOperator): installing_required_dependencies> dag:<DAG: nawy_real_estate_pipeline> dagrun:<DagRun nawy_real_estate_pipeline @ 2025-09-20 07:54:34.754250+00:00: manual__2025-09-20T07:54:34.754250+00:00, state:running, queued_at: 2025-09-21 23:03:47.690587+00:00. externally triggered: True>
[2025-09-21T23:22:40.732+0000] {logging_mixin.py:190} INFO - Failure caused by Bash command failed. The command returned a non-zero exit code 2.
[2025-09-21T23:22:40.733+0000] {taskinstance.py:1226} INFO - Marking task as FAILED. dag_id=nawy_real_estate_pipeline, task_id=installing_required_dependencies, run_id=manual__2025-09-20T07:54:34.754250+00:00, execution_date=20250920T075434, start_date=20250921T232220, end_date=20250921T232240
[2025-09-21T23:22:40.942+0000] {taskinstance.py:341} INFO - ::group::Post task execution logs
[2025-09-21T23:22:40.944+0000] {standard_task_runner.py:124} ERROR - Failed to execute job 385 for task installing_required_dependencies (Bash command failed. The command returned a non-zero exit code 2.; 494)
Traceback (most recent call last):
  File "/home/airflow/.local/lib/python3.12/site-packages/airflow/task/task_runner/standard_task_runner.py", line 117, in _start_by_fork
    ret = args.func(args, dag=self.dag)
          ^^^^^^^^^^^^^^^^^^^^^^^^^^^^^
  File "/home/airflow/.local/lib/python3.12/site-packages/airflow/cli/cli_config.py", line 49, in command
    return func(*args, **kwargs)
           ^^^^^^^^^^^^^^^^^^^^^
  File "/home/airflow/.local/lib/python3.12/site-packages/airflow/utils/cli.py", line 116, in wrapper
    return f(*args, **kwargs)
           ^^^^^^^^^^^^^^^^^^
  File "/home/airflow/.local/lib/python3.12/site-packages/airflow/cli/commands/task_command.py", line 483, in task_run
    task_return_code = _run_task_by_selected_method(args, _dag, ti)
                       ^^^^^^^^^^^^^^^^^^^^^^^^^^^^^^^^^^^^^^^^^^^^
  File "/home/airflow/.local/lib/python3.12/site-packages/airflow/cli/commands/task_command.py", line 256, in _run_task_by_selected_method
    return _run_raw_task(args, ti)
           ^^^^^^^^^^^^^^^^^^^^^^^
  File "/home/airflow/.local/lib/python3.12/site-packages/airflow/cli/commands/task_command.py", line 341, in _run_raw_task
    return ti._run_raw_task(
           ^^^^^^^^^^^^^^^^^
  File "/home/airflow/.local/lib/python3.12/site-packages/airflow/utils/session.py", line 97, in wrapper
    return func(*args, session=session, **kwargs)
           ^^^^^^^^^^^^^^^^^^^^^^^^^^^^^^^^^^^^^^
  File "/home/airflow/.local/lib/python3.12/site-packages/airflow/models/taskinstance.py", line 3006, in _run_raw_task
    return _run_raw_task(
           ^^^^^^^^^^^^^^
  File "/home/airflow/.local/lib/python3.12/site-packages/airflow/models/taskinstance.py", line 274, in _run_raw_task
    TaskInstance._execute_task_with_callbacks(
  File "/home/airflow/.local/lib/python3.12/site-packages/airflow/models/taskinstance.py", line 3161, in _execute_task_with_callbacks
    result = self._execute_task(context, task_orig)
             ^^^^^^^^^^^^^^^^^^^^^^^^^^^^^^^^^^^^^^
  File "/home/airflow/.local/lib/python3.12/site-packages/airflow/models/taskinstance.py", line 3185, in _execute_task
    return _execute_task(self, context, task_orig)
           ^^^^^^^^^^^^^^^^^^^^^^^^^^^^^^^^^^^^^^^
  File "/home/airflow/.local/lib/python3.12/site-packages/airflow/models/taskinstance.py", line 768, in _execute_task
    result = _execute_callable(context=context, **execute_callable_kwargs)
             ^^^^^^^^^^^^^^^^^^^^^^^^^^^^^^^^^^^^^^^^^^^^^^^^^^^^^^^^^^^^^
  File "/home/airflow/.local/lib/python3.12/site-packages/airflow/models/taskinstance.py", line 734, in _execute_callable
    return ExecutionCallableRunner(
           ^^^^^^^^^^^^^^^^^^^^^^^^
  File "/home/airflow/.local/lib/python3.12/site-packages/airflow/utils/operator_helpers.py", line 252, in run
    return self.func(*args, **kwargs)
           ^^^^^^^^^^^^^^^^^^^^^^^^^^
  File "/home/airflow/.local/lib/python3.12/site-packages/airflow/models/baseoperator.py", line 424, in wrapper
    return func(self, *args, **kwargs)
           ^^^^^^^^^^^^^^^^^^^^^^^^^^^
  File "/home/airflow/.local/lib/python3.12/site-packages/airflow/operators/bash.py", line 276, in execute
    raise AirflowException(
airflow.exceptions.AirflowException: Bash command failed. The command returned a non-zero exit code 2.
[2025-09-21T23:22:40.998+0000] {local_task_job_runner.py:266} INFO - Task exited with return code 1
[2025-09-21T23:22:41.063+0000] {taskinstance.py:3901} INFO - 0 downstream tasks scheduled from follow-on schedule check
[2025-09-21T23:22:41.100+0000] {local_task_job_runner.py:245} INFO - ::endgroup::
