[2025-09-21T23:21:30.668+0000] {local_task_job_runner.py:123} INFO - ::group::Pre task execution logs
[2025-09-21T23:21:30.737+0000] {taskinstance.py:2614} INFO - Dependencies all met for dep_context=non-requeueable deps ti=<TaskInstance: nawy_real_estate_pipeline.installing_required_dependencies manual__2025-09-20T07:36:00.100023+00:00 [queued]>
[2025-09-21T23:21:30.754+0000] {taskinstance.py:2614} INFO - Dependencies all met for dep_context=requeueable deps ti=<TaskInstance: nawy_real_estate_pipeline.installing_required_dependencies manual__2025-09-20T07:36:00.100023+00:00 [queued]>
[2025-09-21T23:21:30.755+0000] {taskinstance.py:2867} INFO - Starting attempt 2 of 2
[2025-09-21T23:21:31.033+0000] {taskinstance.py:2890} INFO - Executing <Task(BashOperator): installing_required_dependencies> on 2025-09-20 07:36:00.100023+00:00
[2025-09-21T23:21:31.048+0000] {warnings.py:112} WARNING - /home/***/.local/lib/python3.12/site-packages/***/task/task_runner/standard_task_runner.py:70: DeprecationWarning: This process (pid=296) is multi-threaded, use of fork() may lead to deadlocks in the child.
  pid = os.fork()

[2025-09-21T23:21:31.059+0000] {standard_task_runner.py:104} INFO - Running: ['***', 'tasks', 'run', 'nawy_real_estate_pipeline', 'installing_required_dependencies', 'manual__2025-09-20T07:36:00.100023+00:00', '--job-id', '373', '--raw', '--subdir', 'DAGS_FOLDER/nawy_dag.py', '--cfg-path', '/tmp/tmpa87ivmg4']
[2025-09-21T23:21:31.070+0000] {standard_task_runner.py:72} INFO - Started process 351 to run task
[2025-09-21T23:21:31.070+0000] {standard_task_runner.py:105} INFO - Job 373: Subtask installing_required_dependencies
[2025-09-21T23:21:31.342+0000] {task_command.py:467} INFO - Running <TaskInstance: nawy_real_estate_pipeline.installing_required_dependencies manual__2025-09-20T07:36:00.100023+00:00 [running]> on host b65782a7021d
[2025-09-21T23:21:31.895+0000] {taskinstance.py:3134} INFO - Exporting env vars: AIRFLOW_CTX_DAG_OWNER='***' AIRFLOW_CTX_DAG_ID='nawy_real_estate_pipeline' AIRFLOW_CTX_TASK_ID='installing_required_dependencies' AIRFLOW_CTX_EXECUTION_DATE='2025-09-20T07:36:00.100023+00:00' AIRFLOW_CTX_TRY_NUMBER='2' AIRFLOW_CTX_DAG_RUN_ID='manual__2025-09-20T07:36:00.100023+00:00'
[2025-09-21T23:21:31.899+0000] {logging_mixin.py:190} INFO - Task instance is in running state
[2025-09-21T23:21:31.900+0000] {logging_mixin.py:190} INFO -  Previous state of the Task instance: queued
[2025-09-21T23:21:31.901+0000] {logging_mixin.py:190} INFO - Current task name:installing_required_dependencies state:running start_date:2025-09-21 23:21:30.737881+00:00
[2025-09-21T23:21:31.902+0000] {logging_mixin.py:190} INFO - Dag name:nawy_real_estate_pipeline and current dag run status:running
[2025-09-21T23:21:31.904+0000] {taskinstance.py:732} INFO - ::endgroup::
[2025-09-21T23:21:31.906+0000] {subprocess.py:78} INFO - Tmp dir root location: /tmp
[2025-09-21T23:21:31.910+0000] {subprocess.py:88} INFO - Running command: ['/usr/bin/bash', '-c', ' cd /opt/***/dags/../include/nawy_dbt_project && dbt clean &&  dbt deps --no-version-check ']
[2025-09-21T23:21:31.980+0000] {subprocess.py:99} INFO - Output:
[2025-09-21T23:21:44.466+0000] {subprocess.py:106} INFO - [0m23:21:44  Running with dbt=1.10.11
[2025-09-21T23:21:45.005+0000] {subprocess.py:106} INFO - [0m23:21:45  Checking /opt/***/include/nawy_dbt_project/dbt_packages/*
[2025-09-21T23:21:45.009+0000] {subprocess.py:106} INFO - [0m23:21:45  Cleaned /opt/***/include/nawy_dbt_project/dbt_packages/*
[2025-09-21T23:21:45.011+0000] {subprocess.py:106} INFO - [0m23:21:45  Checking /opt/***/include/nawy_dbt_project/target/*
[2025-09-21T23:21:45.015+0000] {subprocess.py:106} INFO - [0m23:21:45  Cleaned /opt/***/include/nawy_dbt_project/target/*
[2025-09-21T23:21:45.017+0000] {subprocess.py:106} INFO - [0m23:21:45  Finished cleaning all paths.
[2025-09-21T23:21:55.006+0000] {subprocess.py:106} INFO - [0m23:21:55  Running with dbt=1.10.11
[2025-09-21T23:21:55.705+0000] {subprocess.py:106} INFO - [0m23:21:55  Encountered an error:
[2025-09-21T23:21:55.706+0000] {subprocess.py:106} INFO - [Errno 39] Directory not empty: 'dbt_packages/dbt_utils/integration_tests/data/sql'
[2025-09-21T23:21:55.712+0000] {subprocess.py:106} INFO - [0m23:21:55  Traceback (most recent call last):
[2025-09-21T23:21:55.713+0000] {subprocess.py:106} INFO -   File "/home/***/.local/lib/python3.12/site-packages/dbt/cli/requires.py", line 178, in wrapper
[2025-09-21T23:21:55.715+0000] {subprocess.py:106} INFO -     result, success = func(*args, **kwargs)
[2025-09-21T23:21:55.716+0000] {subprocess.py:106} INFO -                       ^^^^^^^^^^^^^^^^^^^^^
[2025-09-21T23:21:55.718+0000] {subprocess.py:106} INFO -   File "/home/***/.local/lib/python3.12/site-packages/dbt/cli/requires.py", line 128, in wrapper
[2025-09-21T23:21:55.719+0000] {subprocess.py:106} INFO -     return func(*args, **kwargs)
[2025-09-21T23:21:55.720+0000] {subprocess.py:106} INFO -            ^^^^^^^^^^^^^^^^^^^^^
[2025-09-21T23:21:55.721+0000] {subprocess.py:106} INFO -   File "/home/***/.local/lib/python3.12/site-packages/dbt/cli/requires.py", line 254, in wrapper
[2025-09-21T23:21:55.722+0000] {subprocess.py:106} INFO -     return func(*args, **kwargs)
[2025-09-21T23:21:55.723+0000] {subprocess.py:106} INFO -            ^^^^^^^^^^^^^^^^^^^^^
[2025-09-21T23:21:55.724+0000] {subprocess.py:106} INFO -   File "/home/***/.local/lib/python3.12/site-packages/dbt/cli/requires.py", line 303, in wrapper
[2025-09-21T23:21:55.725+0000] {subprocess.py:106} INFO -     return func(*args, **kwargs)
[2025-09-21T23:21:55.726+0000] {subprocess.py:106} INFO -            ^^^^^^^^^^^^^^^^^^^^^
[2025-09-21T23:21:55.727+0000] {subprocess.py:106} INFO -   File "/home/***/.local/lib/python3.12/site-packages/dbt/cli/main.py", line 461, in deps
[2025-09-21T23:21:55.729+0000] {subprocess.py:106} INFO -     results = task.run()
[2025-09-21T23:21:55.730+0000] {subprocess.py:106} INFO -               ^^^^^^^^^^
[2025-09-21T23:21:55.731+0000] {subprocess.py:106} INFO -   File "/home/***/.local/lib/python3.12/site-packages/dbt/task/deps.py", line 231, in run
[2025-09-21T23:21:55.732+0000] {subprocess.py:106} INFO -     system.rmtree(self.project.packages_install_path)
[2025-09-21T23:21:55.734+0000] {subprocess.py:106} INFO -   File "/home/***/.local/lib/python3.12/site-packages/dbt_common/clients/system.py", line 718, in rmtree
[2025-09-21T23:21:55.735+0000] {subprocess.py:106} INFO -     return shutil.rmtree(path, onerror=chmod_and_retry)
[2025-09-21T23:21:55.736+0000] {subprocess.py:106} INFO -            ^^^^^^^^^^^^^^^^^^^^^^^^^^^^^^^^^^^^^^^^^^^^
[2025-09-21T23:21:55.737+0000] {subprocess.py:106} INFO -   File "/usr/local/lib/python3.12/shutil.py", line 759, in rmtree
[2025-09-21T23:21:55.738+0000] {subprocess.py:106} INFO -     _rmtree_safe_fd(stack, onexc)
[2025-09-21T23:21:55.739+0000] {subprocess.py:106} INFO -   File "/usr/local/lib/python3.12/shutil.py", line 703, in _rmtree_safe_fd
[2025-09-21T23:21:55.740+0000] {subprocess.py:106} INFO -     onexc(func, path, err)
[2025-09-21T23:21:55.741+0000] {subprocess.py:106} INFO -   File "/usr/local/lib/python3.12/shutil.py", line 750, in onexc
[2025-09-21T23:21:55.742+0000] {subprocess.py:106} INFO -     return onerror(func, path, exc_info)
[2025-09-21T23:21:55.743+0000] {subprocess.py:106} INFO -            ^^^^^^^^^^^^^^^^^^^^^^^^^^^^^
[2025-09-21T23:21:55.744+0000] {subprocess.py:106} INFO -   File "/usr/local/lib/python3.12/shutil.py", line 662, in _rmtree_safe_fd
[2025-09-21T23:21:55.744+0000] {subprocess.py:106} INFO -     os.rmdir(name, dir_fd=dirfd)
[2025-09-21T23:21:55.745+0000] {subprocess.py:106} INFO - OSError: [Errno 39] Directory not empty: 'dbt_packages/dbt_utils/integration_tests/data/sql'
[2025-09-21T23:21:55.746+0000] {subprocess.py:106} INFO - 
[2025-09-21T23:21:57.021+0000] {subprocess.py:110} INFO - Command exited with return code 2
[2025-09-21T23:21:57.354+0000] {taskinstance.py:3313} ERROR - Task failed with exception
Traceback (most recent call last):
  File "/home/airflow/.local/lib/python3.12/site-packages/airflow/models/taskinstance.py", line 768, in _execute_task
    result = _execute_callable(context=context, **execute_callable_kwargs)
             ^^^^^^^^^^^^^^^^^^^^^^^^^^^^^^^^^^^^^^^^^^^^^^^^^^^^^^^^^^^^^
  File "/home/airflow/.local/lib/python3.12/site-packages/airflow/models/taskinstance.py", line 734, in _execute_callable
    return ExecutionCallableRunner(
           ^^^^^^^^^^^^^^^^^^^^^^^^
  File "/home/airflow/.local/lib/python3.12/site-packages/airflow/utils/operator_helpers.py", line 252, in run
    return self.func(*args, **kwargs)
           ^^^^^^^^^^^^^^^^^^^^^^^^^^
  File "/home/airflow/.local/lib/python3.12/site-packages/airflow/models/baseoperator.py", line 424, in wrapper
    return func(self, *args, **kwargs)
           ^^^^^^^^^^^^^^^^^^^^^^^^^^^
  File "/home/airflow/.local/lib/python3.12/site-packages/airflow/operators/bash.py", line 276, in execute
    raise AirflowException(
airflow.exceptions.AirflowException: Bash command failed. The command returned a non-zero exit code 2.
[2025-09-21T23:21:57.361+0000] {logging_mixin.py:190} INFO - Task instance in failure state
[2025-09-21T23:21:57.362+0000] {logging_mixin.py:190} INFO - Task start:2025-09-21 23:21:30.737881+00:00 end:2025-09-21 23:21:57.360658+00:00 duration:26.622777
[2025-09-21T23:21:57.363+0000] {logging_mixin.py:190} INFO - Task:<Task(BashOperator): installing_required_dependencies> dag:<DAG: nawy_real_estate_pipeline> dagrun:<DagRun nawy_real_estate_pipeline @ 2025-09-20 07:36:00.100023+00:00: manual__2025-09-20T07:36:00.100023+00:00, state:running, queued_at: 2025-09-21 23:03:47.691039+00:00. externally triggered: True>
[2025-09-21T23:21:57.363+0000] {logging_mixin.py:190} INFO - Failure caused by Bash command failed. The command returned a non-zero exit code 2.
[2025-09-21T23:21:57.364+0000] {taskinstance.py:1226} INFO - Marking task as FAILED. dag_id=nawy_real_estate_pipeline, task_id=installing_required_dependencies, run_id=manual__2025-09-20T07:36:00.100023+00:00, execution_date=20250920T073600, start_date=20250921T232130, end_date=20250921T232157
[2025-09-21T23:21:57.843+0000] {taskinstance.py:341} INFO - ::group::Post task execution logs
[2025-09-21T23:21:57.847+0000] {standard_task_runner.py:124} ERROR - Failed to execute job 373 for task installing_required_dependencies (Bash command failed. The command returned a non-zero exit code 2.; 351)
Traceback (most recent call last):
  File "/home/airflow/.local/lib/python3.12/site-packages/airflow/task/task_runner/standard_task_runner.py", line 117, in _start_by_fork
    ret = args.func(args, dag=self.dag)
          ^^^^^^^^^^^^^^^^^^^^^^^^^^^^^
  File "/home/airflow/.local/lib/python3.12/site-packages/airflow/cli/cli_config.py", line 49, in command
    return func(*args, **kwargs)
           ^^^^^^^^^^^^^^^^^^^^^
  File "/home/airflow/.local/lib/python3.12/site-packages/airflow/utils/cli.py", line 116, in wrapper
    return f(*args, **kwargs)
           ^^^^^^^^^^^^^^^^^^
  File "/home/airflow/.local/lib/python3.12/site-packages/airflow/cli/commands/task_command.py", line 483, in task_run
    task_return_code = _run_task_by_selected_method(args, _dag, ti)
                       ^^^^^^^^^^^^^^^^^^^^^^^^^^^^^^^^^^^^^^^^^^^^
  File "/home/airflow/.local/lib/python3.12/site-packages/airflow/cli/commands/task_command.py", line 256, in _run_task_by_selected_method
    return _run_raw_task(args, ti)
           ^^^^^^^^^^^^^^^^^^^^^^^
  File "/home/airflow/.local/lib/python3.12/site-packages/airflow/cli/commands/task_command.py", line 341, in _run_raw_task
    return ti._run_raw_task(
           ^^^^^^^^^^^^^^^^^
  File "/home/airflow/.local/lib/python3.12/site-packages/airflow/utils/session.py", line 97, in wrapper
    return func(*args, session=session, **kwargs)
           ^^^^^^^^^^^^^^^^^^^^^^^^^^^^^^^^^^^^^^
  File "/home/airflow/.local/lib/python3.12/site-packages/airflow/models/taskinstance.py", line 3006, in _run_raw_task
    return _run_raw_task(
           ^^^^^^^^^^^^^^
  File "/home/airflow/.local/lib/python3.12/site-packages/airflow/models/taskinstance.py", line 274, in _run_raw_task
    TaskInstance._execute_task_with_callbacks(
  File "/home/airflow/.local/lib/python3.12/site-packages/airflow/models/taskinstance.py", line 3161, in _execute_task_with_callbacks
    result = self._execute_task(context, task_orig)
             ^^^^^^^^^^^^^^^^^^^^^^^^^^^^^^^^^^^^^^
  File "/home/airflow/.local/lib/python3.12/site-packages/airflow/models/taskinstance.py", line 3185, in _execute_task
    return _execute_task(self, context, task_orig)
           ^^^^^^^^^^^^^^^^^^^^^^^^^^^^^^^^^^^^^^^
  File "/home/airflow/.local/lib/python3.12/site-packages/airflow/models/taskinstance.py", line 768, in _execute_task
    result = _execute_callable(context=context, **execute_callable_kwargs)
             ^^^^^^^^^^^^^^^^^^^^^^^^^^^^^^^^^^^^^^^^^^^^^^^^^^^^^^^^^^^^^
  File "/home/airflow/.local/lib/python3.12/site-packages/airflow/models/taskinstance.py", line 734, in _execute_callable
    return ExecutionCallableRunner(
           ^^^^^^^^^^^^^^^^^^^^^^^^
  File "/home/airflow/.local/lib/python3.12/site-packages/airflow/utils/operator_helpers.py", line 252, in run
    return self.func(*args, **kwargs)
           ^^^^^^^^^^^^^^^^^^^^^^^^^^
  File "/home/airflow/.local/lib/python3.12/site-packages/airflow/models/baseoperator.py", line 424, in wrapper
    return func(self, *args, **kwargs)
           ^^^^^^^^^^^^^^^^^^^^^^^^^^^
  File "/home/airflow/.local/lib/python3.12/site-packages/airflow/operators/bash.py", line 276, in execute
    raise AirflowException(
airflow.exceptions.AirflowException: Bash command failed. The command returned a non-zero exit code 2.
[2025-09-21T23:21:57.934+0000] {local_task_job_runner.py:266} INFO - Task exited with return code 1
[2025-09-21T23:21:57.981+0000] {taskinstance.py:3901} INFO - 0 downstream tasks scheduled from follow-on schedule check
[2025-09-21T23:21:58.057+0000] {local_task_job_runner.py:245} INFO - ::endgroup::
