[2025-09-21T23:17:44.722+0000] {local_task_job_runner.py:123} INFO - ::group::Pre task execution logs
[2025-09-21T23:17:44.767+0000] {taskinstance.py:2614} INFO - Dependencies all met for dep_context=non-requeueable deps ti=<TaskInstance: nawy_real_estate_pipeline.installing_required_dependencies scheduled__2025-09-19T00:00:00+00:00 [queued]>
[2025-09-21T23:17:44.782+0000] {taskinstance.py:2614} INFO - Dependencies all met for dep_context=requeueable deps ti=<TaskInstance: nawy_real_estate_pipeline.installing_required_dependencies scheduled__2025-09-19T00:00:00+00:00 [queued]>
[2025-09-21T23:17:44.783+0000] {taskinstance.py:2867} INFO - Starting attempt 2 of 2
[2025-09-21T23:17:44.939+0000] {taskinstance.py:2890} INFO - Executing <Task(BashOperator): installing_required_dependencies> on 2025-09-19 00:00:00+00:00
[2025-09-21T23:17:44.973+0000] {warnings.py:112} WARNING - /home/***/.local/lib/python3.12/site-packages/***/task/task_runner/standard_task_runner.py:70: DeprecationWarning: This process (pid=104) is multi-threaded, use of fork() may lead to deadlocks in the child.
  pid = os.fork()

[2025-09-21T23:17:44.976+0000] {standard_task_runner.py:72} INFO - Started process 154 to run task
[2025-09-21T23:17:44.979+0000] {standard_task_runner.py:104} INFO - Running: ['***', 'tasks', 'run', 'nawy_real_estate_pipeline', 'installing_required_dependencies', 'scheduled__2025-09-19T00:00:00+00:00', '--job-id', '346', '--raw', '--subdir', 'DAGS_FOLDER/nawy_dag.py', '--cfg-path', '/tmp/tmps8v4epz6']
[2025-09-21T23:17:44.981+0000] {standard_task_runner.py:105} INFO - Job 346: Subtask installing_required_dependencies
[2025-09-21T23:17:45.263+0000] {task_command.py:467} INFO - Running <TaskInstance: nawy_real_estate_pipeline.installing_required_dependencies scheduled__2025-09-19T00:00:00+00:00 [running]> on host b65782a7021d
[2025-09-21T23:17:46.449+0000] {taskinstance.py:3134} INFO - Exporting env vars: AIRFLOW_CTX_DAG_OWNER='***' AIRFLOW_CTX_DAG_ID='nawy_real_estate_pipeline' AIRFLOW_CTX_TASK_ID='installing_required_dependencies' AIRFLOW_CTX_EXECUTION_DATE='2025-09-19T00:00:00+00:00' AIRFLOW_CTX_TRY_NUMBER='2' AIRFLOW_CTX_DAG_RUN_ID='scheduled__2025-09-19T00:00:00+00:00'
[2025-09-21T23:17:46.453+0000] {logging_mixin.py:190} INFO - Task instance is in running state
[2025-09-21T23:17:46.454+0000] {logging_mixin.py:190} INFO -  Previous state of the Task instance: queued
[2025-09-21T23:17:46.454+0000] {logging_mixin.py:190} INFO - Current task name:installing_required_dependencies state:running start_date:2025-09-21 23:17:44.768230+00:00
[2025-09-21T23:17:46.455+0000] {logging_mixin.py:190} INFO - Dag name:nawy_real_estate_pipeline and current dag run status:running
[2025-09-21T23:17:46.456+0000] {taskinstance.py:732} INFO - ::endgroup::
[2025-09-21T23:17:46.457+0000] {subprocess.py:78} INFO - Tmp dir root location: /tmp
[2025-09-21T23:17:46.458+0000] {subprocess.py:88} INFO - Running command: ['/usr/bin/bash', '-c', ' cd /opt/***/dags/../include/nawy_dbt_project && dbt clean &&  dbt deps --no-version-check ']
[2025-09-21T23:17:46.585+0000] {subprocess.py:99} INFO - Output:
[2025-09-21T23:19:09.716+0000] {subprocess.py:106} INFO - [0m23:19:09  Running with dbt=1.10.11
[2025-09-21T23:19:46.358+0000] {subprocess.py:106} INFO - [0m23:19:46  Checking /opt/***/include/nawy_dbt_project/target/*
[2025-09-21T23:19:47.268+0000] {subprocess.py:106} INFO - [0m23:19:47  Cleaned /opt/***/include/nawy_dbt_project/target/*
[2025-09-21T23:19:47.269+0000] {subprocess.py:106} INFO - [0m23:19:47  Checking /opt/***/include/nawy_dbt_project/dbt_packages/*
[2025-09-21T23:19:49.123+0000] {subprocess.py:106} INFO - [0m23:19:49  Cleaned /opt/***/include/nawy_dbt_project/dbt_packages/*
[2025-09-21T23:19:49.123+0000] {subprocess.py:106} INFO - [0m23:19:49  Finished cleaning all paths.
[2025-09-21T23:20:49.598+0000] {subprocess.py:106} INFO - [0m23:20:49  Running with dbt=1.10.11
[2025-09-21T23:20:54.615+0000] {subprocess.py:106} INFO - [0m23:20:54  Installing dbt-labs/dbt_utils
[2025-09-21T23:21:04.590+0000] {subprocess.py:106} INFO - [0m23:21:04  Encountered an error:
[2025-09-21T23:21:04.592+0000] {subprocess.py:106} INFO - [Errno 2] No such file or directory: 'dbt_packages/dbt_utils'
[2025-09-21T23:21:04.601+0000] {subprocess.py:106} INFO - [0m23:21:04  Traceback (most recent call last):
[2025-09-21T23:21:04.603+0000] {subprocess.py:106} INFO -   File "/home/***/.local/lib/python3.12/site-packages/dbt/cli/requires.py", line 178, in wrapper
[2025-09-21T23:21:04.604+0000] {subprocess.py:106} INFO -     result, success = func(*args, **kwargs)
[2025-09-21T23:21:04.608+0000] {subprocess.py:106} INFO -                       ^^^^^^^^^^^^^^^^^^^^^
[2025-09-21T23:21:04.610+0000] {subprocess.py:106} INFO -   File "/home/***/.local/lib/python3.12/site-packages/dbt/cli/requires.py", line 128, in wrapper
[2025-09-21T23:21:04.613+0000] {subprocess.py:106} INFO -     return func(*args, **kwargs)
[2025-09-21T23:21:04.615+0000] {subprocess.py:106} INFO -            ^^^^^^^^^^^^^^^^^^^^^
[2025-09-21T23:21:04.616+0000] {subprocess.py:106} INFO -   File "/home/***/.local/lib/python3.12/site-packages/dbt/cli/requires.py", line 254, in wrapper
[2025-09-21T23:21:04.617+0000] {subprocess.py:106} INFO -     return func(*args, **kwargs)
[2025-09-21T23:21:04.619+0000] {subprocess.py:106} INFO -            ^^^^^^^^^^^^^^^^^^^^^
[2025-09-21T23:21:04.621+0000] {subprocess.py:106} INFO -   File "/home/***/.local/lib/python3.12/site-packages/dbt/cli/requires.py", line 303, in wrapper
[2025-09-21T23:21:04.623+0000] {subprocess.py:106} INFO -     return func(*args, **kwargs)
[2025-09-21T23:21:04.624+0000] {subprocess.py:106} INFO -            ^^^^^^^^^^^^^^^^^^^^^
[2025-09-21T23:21:04.626+0000] {subprocess.py:106} INFO -   File "/home/***/.local/lib/python3.12/site-packages/dbt/cli/main.py", line 461, in deps
[2025-09-21T23:21:04.629+0000] {subprocess.py:106} INFO -     results = task.run()
[2025-09-21T23:21:04.630+0000] {subprocess.py:106} INFO -               ^^^^^^^^^^
[2025-09-21T23:21:04.631+0000] {subprocess.py:106} INFO -   File "/home/***/.local/lib/python3.12/site-packages/dbt/task/deps.py", line 258, in run
[2025-09-21T23:21:04.633+0000] {subprocess.py:106} INFO -     package.install(self.project, renderer)
[2025-09-21T23:21:04.634+0000] {subprocess.py:106} INFO -   File "/home/***/.local/lib/python3.12/site-packages/dbt/deps/registry.py", line 63, in install
[2025-09-21T23:21:04.636+0000] {subprocess.py:106} INFO -     self._install(project, renderer)
[2025-09-21T23:21:04.637+0000] {subprocess.py:106} INFO -   File "/home/***/.local/lib/python3.12/site-packages/dbt/deps/base.py", line 121, in _install
[2025-09-21T23:21:04.639+0000] {subprocess.py:106} INFO -     connection_exception_retry(download_untar_fn, 5)
[2025-09-21T23:21:04.640+0000] {subprocess.py:106} INFO -   File "/home/***/.local/lib/python3.12/site-packages/dbt_common/utils/connection.py", line 22, in connection_exception_retry
[2025-09-21T23:21:04.642+0000] {subprocess.py:106} INFO -     return fn()
[2025-09-21T23:21:04.643+0000] {subprocess.py:106} INFO -            ^^^^
[2025-09-21T23:21:04.644+0000] {subprocess.py:106} INFO -   File "/home/***/.local/lib/python3.12/site-packages/dbt/deps/base.py", line 133, in download_and_untar
[2025-09-21T23:21:04.645+0000] {subprocess.py:106} INFO -     system.untar_package(tar_path, deps_path, package_name)
[2025-09-21T23:21:04.646+0000] {subprocess.py:106} INFO -   File "/home/***/.local/lib/python3.12/site-packages/dbt_common/clients/system.py", line 649, in untar_package
[2025-09-21T23:21:04.647+0000] {subprocess.py:106} INFO -     dbt_common.clients.system.rename(downloaded_path, desired_path, force=True)
[2025-09-21T23:21:04.647+0000] {subprocess.py:106} INFO -   File "/home/***/.local/lib/python3.12/site-packages/dbt_common/clients/system.py", line 610, in rename
[2025-09-21T23:21:04.649+0000] {subprocess.py:106} INFO -     rmdir(to_path)
[2025-09-21T23:21:04.650+0000] {subprocess.py:106} INFO -   File "/home/***/.local/lib/python3.12/site-packages/dbt_common/clients/system.py", line 351, in rmdir
[2025-09-21T23:21:04.651+0000] {subprocess.py:106} INFO -     shutil.rmtree(path, onerror=onerror)
[2025-09-21T23:21:04.659+0000] {subprocess.py:106} INFO -   File "/usr/local/lib/python3.12/shutil.py", line 759, in rmtree
[2025-09-21T23:21:04.664+0000] {subprocess.py:106} INFO -     _rmtree_safe_fd(stack, onexc)
[2025-09-21T23:21:04.666+0000] {subprocess.py:106} INFO -   File "/usr/local/lib/python3.12/shutil.py", line 703, in _rmtree_safe_fd
[2025-09-21T23:21:04.667+0000] {subprocess.py:106} INFO -     onexc(func, path, err)
[2025-09-21T23:21:04.668+0000] {subprocess.py:106} INFO -   File "/usr/local/lib/python3.12/shutil.py", line 700, in _rmtree_safe_fd
[2025-09-21T23:21:04.669+0000] {subprocess.py:106} INFO -     onexc(os.unlink, fullname, err)
[2025-09-21T23:21:04.671+0000] {subprocess.py:106} INFO -   File "/usr/local/lib/python3.12/shutil.py", line 698, in _rmtree_safe_fd
[2025-09-21T23:21:04.672+0000] {subprocess.py:106} INFO -     os.unlink(entry.name, dir_fd=topfd)
[2025-09-21T23:21:04.674+0000] {subprocess.py:106} INFO - FileNotFoundError: [Errno 2] No such file or directory: 'dbt_packages/dbt_utils'
[2025-09-21T23:21:04.676+0000] {subprocess.py:106} INFO - 
[2025-09-21T23:21:06.005+0000] {subprocess.py:110} INFO - Command exited with return code 2
[2025-09-21T23:21:07.035+0000] {taskinstance.py:3313} ERROR - Task failed with exception
Traceback (most recent call last):
  File "/home/airflow/.local/lib/python3.12/site-packages/airflow/models/taskinstance.py", line 768, in _execute_task
    result = _execute_callable(context=context, **execute_callable_kwargs)
             ^^^^^^^^^^^^^^^^^^^^^^^^^^^^^^^^^^^^^^^^^^^^^^^^^^^^^^^^^^^^^
  File "/home/airflow/.local/lib/python3.12/site-packages/airflow/models/taskinstance.py", line 734, in _execute_callable
    return ExecutionCallableRunner(
           ^^^^^^^^^^^^^^^^^^^^^^^^
  File "/home/airflow/.local/lib/python3.12/site-packages/airflow/utils/operator_helpers.py", line 252, in run
    return self.func(*args, **kwargs)
           ^^^^^^^^^^^^^^^^^^^^^^^^^^
  File "/home/airflow/.local/lib/python3.12/site-packages/airflow/models/baseoperator.py", line 424, in wrapper
    return func(self, *args, **kwargs)
           ^^^^^^^^^^^^^^^^^^^^^^^^^^^
  File "/home/airflow/.local/lib/python3.12/site-packages/airflow/operators/bash.py", line 276, in execute
    raise AirflowException(
airflow.exceptions.AirflowException: Bash command failed. The command returned a non-zero exit code 2.
[2025-09-21T23:21:07.040+0000] {logging_mixin.py:190} INFO - Task instance in failure state
[2025-09-21T23:21:07.041+0000] {logging_mixin.py:190} INFO - Task start:2025-09-21 23:17:44.768230+00:00 end:2025-09-21 23:21:07.039996+00:00 duration:202.271766
[2025-09-21T23:21:07.042+0000] {logging_mixin.py:190} INFO - Task:<Task(BashOperator): installing_required_dependencies> dag:<DAG: nawy_real_estate_pipeline> dagrun:<DagRun nawy_real_estate_pipeline @ 2025-09-19 00:00:00+00:00: scheduled__2025-09-19T00:00:00+00:00, state:running, queued_at: 2025-09-21 23:03:47.690173+00:00. externally triggered: False>
[2025-09-21T23:21:07.042+0000] {logging_mixin.py:190} INFO - Failure caused by Bash command failed. The command returned a non-zero exit code 2.
[2025-09-21T23:21:07.043+0000] {taskinstance.py:1226} INFO - Marking task as FAILED. dag_id=nawy_real_estate_pipeline, task_id=installing_required_dependencies, run_id=scheduled__2025-09-19T00:00:00+00:00, execution_date=20250919T000000, start_date=20250921T231744, end_date=20250921T232107
[2025-09-21T23:21:07.332+0000] {taskinstance.py:341} INFO - ::group::Post task execution logs
[2025-09-21T23:21:07.333+0000] {standard_task_runner.py:124} ERROR - Failed to execute job 346 for task installing_required_dependencies (Bash command failed. The command returned a non-zero exit code 2.; 154)
Traceback (most recent call last):
  File "/home/airflow/.local/lib/python3.12/site-packages/airflow/task/task_runner/standard_task_runner.py", line 117, in _start_by_fork
    ret = args.func(args, dag=self.dag)
          ^^^^^^^^^^^^^^^^^^^^^^^^^^^^^
  File "/home/airflow/.local/lib/python3.12/site-packages/airflow/cli/cli_config.py", line 49, in command
    return func(*args, **kwargs)
           ^^^^^^^^^^^^^^^^^^^^^
  File "/home/airflow/.local/lib/python3.12/site-packages/airflow/utils/cli.py", line 116, in wrapper
    return f(*args, **kwargs)
           ^^^^^^^^^^^^^^^^^^
  File "/home/airflow/.local/lib/python3.12/site-packages/airflow/cli/commands/task_command.py", line 483, in task_run
    task_return_code = _run_task_by_selected_method(args, _dag, ti)
                       ^^^^^^^^^^^^^^^^^^^^^^^^^^^^^^^^^^^^^^^^^^^^
  File "/home/airflow/.local/lib/python3.12/site-packages/airflow/cli/commands/task_command.py", line 256, in _run_task_by_selected_method
    return _run_raw_task(args, ti)
           ^^^^^^^^^^^^^^^^^^^^^^^
  File "/home/airflow/.local/lib/python3.12/site-packages/airflow/cli/commands/task_command.py", line 341, in _run_raw_task
    return ti._run_raw_task(
           ^^^^^^^^^^^^^^^^^
  File "/home/airflow/.local/lib/python3.12/site-packages/airflow/utils/session.py", line 97, in wrapper
    return func(*args, session=session, **kwargs)
           ^^^^^^^^^^^^^^^^^^^^^^^^^^^^^^^^^^^^^^
  File "/home/airflow/.local/lib/python3.12/site-packages/airflow/models/taskinstance.py", line 3006, in _run_raw_task
    return _run_raw_task(
           ^^^^^^^^^^^^^^
  File "/home/airflow/.local/lib/python3.12/site-packages/airflow/models/taskinstance.py", line 274, in _run_raw_task
    TaskInstance._execute_task_with_callbacks(
  File "/home/airflow/.local/lib/python3.12/site-packages/airflow/models/taskinstance.py", line 3161, in _execute_task_with_callbacks
    result = self._execute_task(context, task_orig)
             ^^^^^^^^^^^^^^^^^^^^^^^^^^^^^^^^^^^^^^
  File "/home/airflow/.local/lib/python3.12/site-packages/airflow/models/taskinstance.py", line 3185, in _execute_task
    return _execute_task(self, context, task_orig)
           ^^^^^^^^^^^^^^^^^^^^^^^^^^^^^^^^^^^^^^^
  File "/home/airflow/.local/lib/python3.12/site-packages/airflow/models/taskinstance.py", line 768, in _execute_task
    result = _execute_callable(context=context, **execute_callable_kwargs)
             ^^^^^^^^^^^^^^^^^^^^^^^^^^^^^^^^^^^^^^^^^^^^^^^^^^^^^^^^^^^^^
  File "/home/airflow/.local/lib/python3.12/site-packages/airflow/models/taskinstance.py", line 734, in _execute_callable
    return ExecutionCallableRunner(
           ^^^^^^^^^^^^^^^^^^^^^^^^
  File "/home/airflow/.local/lib/python3.12/site-packages/airflow/utils/operator_helpers.py", line 252, in run
    return self.func(*args, **kwargs)
           ^^^^^^^^^^^^^^^^^^^^^^^^^^
  File "/home/airflow/.local/lib/python3.12/site-packages/airflow/models/baseoperator.py", line 424, in wrapper
    return func(self, *args, **kwargs)
           ^^^^^^^^^^^^^^^^^^^^^^^^^^^
  File "/home/airflow/.local/lib/python3.12/site-packages/airflow/operators/bash.py", line 276, in execute
    raise AirflowException(
airflow.exceptions.AirflowException: Bash command failed. The command returned a non-zero exit code 2.
[2025-09-21T23:21:07.390+0000] {local_task_job_runner.py:266} INFO - Task exited with return code 1
[2025-09-21T23:21:07.440+0000] {taskinstance.py:3901} INFO - 0 downstream tasks scheduled from follow-on schedule check
[2025-09-21T23:21:07.623+0000] {local_task_job_runner.py:245} INFO - ::endgroup::
