[2025-09-21T23:21:27.308+0000] {local_task_job_runner.py:123} INFO - ::group::Pre task execution logs
[2025-09-21T23:21:27.395+0000] {taskinstance.py:2614} INFO - Dependencies all met for dep_context=non-requeueable deps ti=<TaskInstance: nawy_real_estate_pipeline.installing_required_dependencies manual__2025-09-20T05:43:34.046386+00:00 [queued]>
[2025-09-21T23:21:27.427+0000] {taskinstance.py:2614} INFO - Dependencies all met for dep_context=requeueable deps ti=<TaskInstance: nawy_real_estate_pipeline.installing_required_dependencies manual__2025-09-20T05:43:34.046386+00:00 [queued]>
[2025-09-21T23:21:27.431+0000] {taskinstance.py:2867} INFO - Starting attempt 1 of 1
[2025-09-21T23:21:27.598+0000] {taskinstance.py:2890} INFO - Executing <Task(BashOperator): installing_required_dependencies> on 2025-09-20 05:43:34.046386+00:00
[2025-09-21T23:21:30.182+0000] {warnings.py:112} WARNING - /home/***/.local/lib/python3.12/site-packages/***/task/task_runner/standard_task_runner.py:70: DeprecationWarning: This process (pid=289) is multi-threaded, use of fork() may lead to deadlocks in the child.
  pid = os.fork()

[2025-09-21T23:21:30.196+0000] {standard_task_runner.py:72} INFO - Started process 338 to run task
[2025-09-21T23:21:30.201+0000] {standard_task_runner.py:104} INFO - Running: ['***', 'tasks', 'run', 'nawy_real_estate_pipeline', 'installing_required_dependencies', 'manual__2025-09-20T05:43:34.046386+00:00', '--job-id', '368', '--raw', '--subdir', 'DAGS_FOLDER/nawy_dag.py', '--cfg-path', '/tmp/tmp3mgsggqg']
[2025-09-21T23:21:30.209+0000] {standard_task_runner.py:105} INFO - Job 368: Subtask installing_required_dependencies
[2025-09-21T23:21:30.554+0000] {task_command.py:467} INFO - Running <TaskInstance: nawy_real_estate_pipeline.installing_required_dependencies manual__2025-09-20T05:43:34.046386+00:00 [running]> on host b65782a7021d
[2025-09-21T23:21:31.043+0000] {taskinstance.py:3134} INFO - Exporting env vars: AIRFLOW_CTX_DAG_OWNER='***' AIRFLOW_CTX_DAG_ID='nawy_real_estate_pipeline' AIRFLOW_CTX_TASK_ID='installing_required_dependencies' AIRFLOW_CTX_EXECUTION_DATE='2025-09-20T05:43:34.046386+00:00' AIRFLOW_CTX_TRY_NUMBER='1' AIRFLOW_CTX_DAG_RUN_ID='manual__2025-09-20T05:43:34.046386+00:00'
[2025-09-21T23:21:31.046+0000] {logging_mixin.py:190} INFO - Task instance is in running state
[2025-09-21T23:21:31.048+0000] {logging_mixin.py:190} INFO -  Previous state of the Task instance: queued
[2025-09-21T23:21:31.050+0000] {logging_mixin.py:190} INFO - Current task name:installing_required_dependencies state:running start_date:2025-09-21 23:21:27.408612+00:00
[2025-09-21T23:21:31.050+0000] {logging_mixin.py:190} INFO - Dag name:nawy_real_estate_pipeline and current dag run status:running
[2025-09-21T23:21:31.051+0000] {taskinstance.py:732} INFO - ::endgroup::
[2025-09-21T23:21:31.054+0000] {subprocess.py:78} INFO - Tmp dir root location: /tmp
[2025-09-21T23:21:31.107+0000] {subprocess.py:88} INFO - Running command: ['/usr/bin/bash', '-c', ' cd /opt/***/dags/../include/nawy_dbt_project && dbt clean &&  dbt deps --no-version-check ']
[2025-09-21T23:21:31.144+0000] {subprocess.py:99} INFO - Output:
[2025-09-21T23:21:42.099+0000] {subprocess.py:106} INFO - [0m23:21:42  Running with dbt=1.10.11
[2025-09-21T23:21:43.096+0000] {subprocess.py:106} INFO - [0m23:21:43  Checking /opt/***/include/nawy_dbt_project/target/*
[2025-09-21T23:21:43.098+0000] {subprocess.py:106} INFO - [0m23:21:43  Cleaned /opt/***/include/nawy_dbt_project/target/*
[2025-09-21T23:21:43.099+0000] {subprocess.py:106} INFO - [0m23:21:43  Checking /opt/***/include/nawy_dbt_project/dbt_packages/*
[2025-09-21T23:21:43.253+0000] {subprocess.py:106} INFO - [0m23:21:43  Cleaned /opt/***/include/nawy_dbt_project/dbt_packages/*
[2025-09-21T23:21:43.255+0000] {subprocess.py:106} INFO - [0m23:21:43  Finished cleaning all paths.
[2025-09-21T23:21:54.379+0000] {subprocess.py:106} INFO - [0m23:21:54  Running with dbt=1.10.11
[2025-09-21T23:21:55.221+0000] {subprocess.py:106} INFO - [0m23:21:55  Encountered an error:
[2025-09-21T23:21:55.222+0000] {subprocess.py:106} INFO - [Errno 39] Directory not empty: 'dbt_packages/dbt_utils/integration_tests/data/schema_tests'
[2025-09-21T23:21:55.230+0000] {subprocess.py:106} INFO - [0m23:21:55  Traceback (most recent call last):
[2025-09-21T23:21:55.232+0000] {subprocess.py:106} INFO -   File "/home/***/.local/lib/python3.12/site-packages/dbt/cli/requires.py", line 178, in wrapper
[2025-09-21T23:21:55.233+0000] {subprocess.py:106} INFO -     result, success = func(*args, **kwargs)
[2025-09-21T23:21:55.235+0000] {subprocess.py:106} INFO -                       ^^^^^^^^^^^^^^^^^^^^^
[2025-09-21T23:21:55.236+0000] {subprocess.py:106} INFO -   File "/home/***/.local/lib/python3.12/site-packages/dbt/cli/requires.py", line 128, in wrapper
[2025-09-21T23:21:55.237+0000] {subprocess.py:106} INFO -     return func(*args, **kwargs)
[2025-09-21T23:21:55.239+0000] {subprocess.py:106} INFO -            ^^^^^^^^^^^^^^^^^^^^^
[2025-09-21T23:21:55.241+0000] {subprocess.py:106} INFO -   File "/home/***/.local/lib/python3.12/site-packages/dbt/cli/requires.py", line 254, in wrapper
[2025-09-21T23:21:55.243+0000] {subprocess.py:106} INFO -     return func(*args, **kwargs)
[2025-09-21T23:21:55.245+0000] {subprocess.py:106} INFO -            ^^^^^^^^^^^^^^^^^^^^^
[2025-09-21T23:21:55.246+0000] {subprocess.py:106} INFO -   File "/home/***/.local/lib/python3.12/site-packages/dbt/cli/requires.py", line 303, in wrapper
[2025-09-21T23:21:55.247+0000] {subprocess.py:106} INFO -     return func(*args, **kwargs)
[2025-09-21T23:21:55.248+0000] {subprocess.py:106} INFO -            ^^^^^^^^^^^^^^^^^^^^^
[2025-09-21T23:21:55.250+0000] {subprocess.py:106} INFO -   File "/home/***/.local/lib/python3.12/site-packages/dbt/cli/main.py", line 461, in deps
[2025-09-21T23:21:55.251+0000] {subprocess.py:106} INFO -     results = task.run()
[2025-09-21T23:21:55.252+0000] {subprocess.py:106} INFO -               ^^^^^^^^^^
[2025-09-21T23:21:55.253+0000] {subprocess.py:106} INFO -   File "/home/***/.local/lib/python3.12/site-packages/dbt/task/deps.py", line 231, in run
[2025-09-21T23:21:55.257+0000] {subprocess.py:106} INFO -     system.rmtree(self.project.packages_install_path)
[2025-09-21T23:21:55.259+0000] {subprocess.py:106} INFO -   File "/home/***/.local/lib/python3.12/site-packages/dbt_common/clients/system.py", line 718, in rmtree
[2025-09-21T23:21:55.261+0000] {subprocess.py:106} INFO -     return shutil.rmtree(path, onerror=chmod_and_retry)
[2025-09-21T23:21:55.262+0000] {subprocess.py:106} INFO -            ^^^^^^^^^^^^^^^^^^^^^^^^^^^^^^^^^^^^^^^^^^^^
[2025-09-21T23:21:55.266+0000] {subprocess.py:106} INFO -   File "/usr/local/lib/python3.12/shutil.py", line 759, in rmtree
[2025-09-21T23:21:55.287+0000] {subprocess.py:106} INFO -     _rmtree_safe_fd(stack, onexc)
[2025-09-21T23:21:55.304+0000] {subprocess.py:106} INFO -   File "/usr/local/lib/python3.12/shutil.py", line 703, in _rmtree_safe_fd
[2025-09-21T23:21:55.309+0000] {subprocess.py:106} INFO -     onexc(func, path, err)
[2025-09-21T23:21:55.312+0000] {subprocess.py:106} INFO -   File "/usr/local/lib/python3.12/shutil.py", line 750, in onexc
[2025-09-21T23:21:55.315+0000] {subprocess.py:106} INFO -     return onerror(func, path, exc_info)
[2025-09-21T23:21:55.325+0000] {subprocess.py:106} INFO -            ^^^^^^^^^^^^^^^^^^^^^^^^^^^^^
[2025-09-21T23:21:55.326+0000] {subprocess.py:106} INFO -   File "/usr/local/lib/python3.12/shutil.py", line 662, in _rmtree_safe_fd
[2025-09-21T23:21:55.328+0000] {subprocess.py:106} INFO -     os.rmdir(name, dir_fd=dirfd)
[2025-09-21T23:21:55.328+0000] {subprocess.py:106} INFO - OSError: [Errno 39] Directory not empty: 'dbt_packages/dbt_utils/integration_tests/data/schema_tests'
[2025-09-21T23:21:55.329+0000] {subprocess.py:106} INFO - 
[2025-09-21T23:21:56.519+0000] {subprocess.py:110} INFO - Command exited with return code 2
[2025-09-21T23:21:57.081+0000] {taskinstance.py:3313} ERROR - Task failed with exception
Traceback (most recent call last):
  File "/home/airflow/.local/lib/python3.12/site-packages/airflow/models/taskinstance.py", line 768, in _execute_task
    result = _execute_callable(context=context, **execute_callable_kwargs)
             ^^^^^^^^^^^^^^^^^^^^^^^^^^^^^^^^^^^^^^^^^^^^^^^^^^^^^^^^^^^^^
  File "/home/airflow/.local/lib/python3.12/site-packages/airflow/models/taskinstance.py", line 734, in _execute_callable
    return ExecutionCallableRunner(
           ^^^^^^^^^^^^^^^^^^^^^^^^
  File "/home/airflow/.local/lib/python3.12/site-packages/airflow/utils/operator_helpers.py", line 252, in run
    return self.func(*args, **kwargs)
           ^^^^^^^^^^^^^^^^^^^^^^^^^^
  File "/home/airflow/.local/lib/python3.12/site-packages/airflow/models/baseoperator.py", line 424, in wrapper
    return func(self, *args, **kwargs)
           ^^^^^^^^^^^^^^^^^^^^^^^^^^^
  File "/home/airflow/.local/lib/python3.12/site-packages/airflow/operators/bash.py", line 276, in execute
    raise AirflowException(
airflow.exceptions.AirflowException: Bash command failed. The command returned a non-zero exit code 2.
[2025-09-21T23:21:57.091+0000] {logging_mixin.py:190} INFO - Task instance in failure state
[2025-09-21T23:21:57.093+0000] {logging_mixin.py:190} INFO - Task start:2025-09-21 23:21:27.408612+00:00 end:2025-09-21 23:21:57.090838+00:00 duration:29.682226
[2025-09-21T23:21:57.093+0000] {logging_mixin.py:190} INFO - Task:<Task(BashOperator): installing_required_dependencies> dag:<DAG: nawy_real_estate_pipeline> dagrun:<DagRun nawy_real_estate_pipeline @ 2025-09-20 05:43:34.046386+00:00: manual__2025-09-20T05:43:34.046386+00:00, state:running, queued_at: 2025-09-21 23:03:47.690790+00:00. externally triggered: True>
[2025-09-21T23:21:57.097+0000] {logging_mixin.py:190} INFO - Failure caused by Bash command failed. The command returned a non-zero exit code 2.
[2025-09-21T23:21:57.099+0000] {taskinstance.py:1226} INFO - Marking task as FAILED. dag_id=nawy_real_estate_pipeline, task_id=installing_required_dependencies, run_id=manual__2025-09-20T05:43:34.046386+00:00, execution_date=20250920T054334, start_date=20250921T232127, end_date=20250921T232157
[2025-09-21T23:21:57.843+0000] {taskinstance.py:341} INFO - ::group::Post task execution logs
[2025-09-21T23:21:57.847+0000] {standard_task_runner.py:124} ERROR - Failed to execute job 368 for task installing_required_dependencies (Bash command failed. The command returned a non-zero exit code 2.; 338)
Traceback (most recent call last):
  File "/home/airflow/.local/lib/python3.12/site-packages/airflow/task/task_runner/standard_task_runner.py", line 117, in _start_by_fork
    ret = args.func(args, dag=self.dag)
          ^^^^^^^^^^^^^^^^^^^^^^^^^^^^^
  File "/home/airflow/.local/lib/python3.12/site-packages/airflow/cli/cli_config.py", line 49, in command
    return func(*args, **kwargs)
           ^^^^^^^^^^^^^^^^^^^^^
  File "/home/airflow/.local/lib/python3.12/site-packages/airflow/utils/cli.py", line 116, in wrapper
    return f(*args, **kwargs)
           ^^^^^^^^^^^^^^^^^^
  File "/home/airflow/.local/lib/python3.12/site-packages/airflow/cli/commands/task_command.py", line 483, in task_run
    task_return_code = _run_task_by_selected_method(args, _dag, ti)
                       ^^^^^^^^^^^^^^^^^^^^^^^^^^^^^^^^^^^^^^^^^^^^
  File "/home/airflow/.local/lib/python3.12/site-packages/airflow/cli/commands/task_command.py", line 256, in _run_task_by_selected_method
    return _run_raw_task(args, ti)
           ^^^^^^^^^^^^^^^^^^^^^^^
  File "/home/airflow/.local/lib/python3.12/site-packages/airflow/cli/commands/task_command.py", line 341, in _run_raw_task
    return ti._run_raw_task(
           ^^^^^^^^^^^^^^^^^
  File "/home/airflow/.local/lib/python3.12/site-packages/airflow/utils/session.py", line 97, in wrapper
    return func(*args, session=session, **kwargs)
           ^^^^^^^^^^^^^^^^^^^^^^^^^^^^^^^^^^^^^^
  File "/home/airflow/.local/lib/python3.12/site-packages/airflow/models/taskinstance.py", line 3006, in _run_raw_task
    return _run_raw_task(
           ^^^^^^^^^^^^^^
  File "/home/airflow/.local/lib/python3.12/site-packages/airflow/models/taskinstance.py", line 274, in _run_raw_task
    TaskInstance._execute_task_with_callbacks(
  File "/home/airflow/.local/lib/python3.12/site-packages/airflow/models/taskinstance.py", line 3161, in _execute_task_with_callbacks
    result = self._execute_task(context, task_orig)
             ^^^^^^^^^^^^^^^^^^^^^^^^^^^^^^^^^^^^^^
  File "/home/airflow/.local/lib/python3.12/site-packages/airflow/models/taskinstance.py", line 3185, in _execute_task
    return _execute_task(self, context, task_orig)
           ^^^^^^^^^^^^^^^^^^^^^^^^^^^^^^^^^^^^^^^
  File "/home/airflow/.local/lib/python3.12/site-packages/airflow/models/taskinstance.py", line 768, in _execute_task
    result = _execute_callable(context=context, **execute_callable_kwargs)
             ^^^^^^^^^^^^^^^^^^^^^^^^^^^^^^^^^^^^^^^^^^^^^^^^^^^^^^^^^^^^^
  File "/home/airflow/.local/lib/python3.12/site-packages/airflow/models/taskinstance.py", line 734, in _execute_callable
    return ExecutionCallableRunner(
           ^^^^^^^^^^^^^^^^^^^^^^^^
  File "/home/airflow/.local/lib/python3.12/site-packages/airflow/utils/operator_helpers.py", line 252, in run
    return self.func(*args, **kwargs)
           ^^^^^^^^^^^^^^^^^^^^^^^^^^
  File "/home/airflow/.local/lib/python3.12/site-packages/airflow/models/baseoperator.py", line 424, in wrapper
    return func(self, *args, **kwargs)
           ^^^^^^^^^^^^^^^^^^^^^^^^^^^
  File "/home/airflow/.local/lib/python3.12/site-packages/airflow/operators/bash.py", line 276, in execute
    raise AirflowException(
airflow.exceptions.AirflowException: Bash command failed. The command returned a non-zero exit code 2.
[2025-09-21T23:21:57.891+0000] {local_task_job_runner.py:266} INFO - Task exited with return code 1
[2025-09-21T23:21:57.946+0000] {taskinstance.py:3901} INFO - 0 downstream tasks scheduled from follow-on schedule check
[2025-09-21T23:21:58.057+0000] {local_task_job_runner.py:245} INFO - ::endgroup::
