[2025-09-21T23:22:16.923+0000] {local_task_job_runner.py:123} INFO - ::group::Pre task execution logs
[2025-09-21T23:22:16.965+0000] {taskinstance.py:2614} INFO - Dependencies all met for dep_context=non-requeueable deps ti=<TaskInstance: nawy_real_estate_pipeline.installing_required_dependencies manual__2025-09-20T08:12:45.207798+00:00 [queued]>
[2025-09-21T23:22:16.983+0000] {taskinstance.py:2614} INFO - Dependencies all met for dep_context=requeueable deps ti=<TaskInstance: nawy_real_estate_pipeline.installing_required_dependencies manual__2025-09-20T08:12:45.207798+00:00 [queued]>
[2025-09-21T23:22:16.984+0000] {taskinstance.py:2867} INFO - Starting attempt 2 of 2
[2025-09-21T23:22:17.068+0000] {taskinstance.py:2890} INFO - Executing <Task(BashOperator): installing_required_dependencies> on 2025-09-20 08:12:45.207798+00:00
[2025-09-21T23:22:17.077+0000] {warnings.py:112} WARNING - /home/***/.local/lib/python3.12/site-packages/***/task/task_runner/standard_task_runner.py:70: DeprecationWarning: This process (pid=453) is multi-threaded, use of fork() may lead to deadlocks in the child.
  pid = os.fork()

[2025-09-21T23:22:17.080+0000] {standard_task_runner.py:72} INFO - Started process 467 to run task
[2025-09-21T23:22:17.081+0000] {standard_task_runner.py:104} INFO - Running: ['***', 'tasks', 'run', 'nawy_real_estate_pipeline', 'installing_required_dependencies', 'manual__2025-09-20T08:12:45.207798+00:00', '--job-id', '380', '--raw', '--subdir', 'DAGS_FOLDER/nawy_dag.py', '--cfg-path', '/tmp/tmpr6fut_8n']
[2025-09-21T23:22:17.084+0000] {standard_task_runner.py:105} INFO - Job 380: Subtask installing_required_dependencies
[2025-09-21T23:22:17.279+0000] {task_command.py:467} INFO - Running <TaskInstance: nawy_real_estate_pipeline.installing_required_dependencies manual__2025-09-20T08:12:45.207798+00:00 [running]> on host b65782a7021d
[2025-09-21T23:22:17.579+0000] {taskinstance.py:3134} INFO - Exporting env vars: AIRFLOW_CTX_DAG_OWNER='***' AIRFLOW_CTX_DAG_ID='nawy_real_estate_pipeline' AIRFLOW_CTX_TASK_ID='installing_required_dependencies' AIRFLOW_CTX_EXECUTION_DATE='2025-09-20T08:12:45.207798+00:00' AIRFLOW_CTX_TRY_NUMBER='2' AIRFLOW_CTX_DAG_RUN_ID='manual__2025-09-20T08:12:45.207798+00:00'
[2025-09-21T23:22:17.582+0000] {logging_mixin.py:190} INFO - Task instance is in running state
[2025-09-21T23:22:17.583+0000] {logging_mixin.py:190} INFO -  Previous state of the Task instance: queued
[2025-09-21T23:22:17.584+0000] {logging_mixin.py:190} INFO - Current task name:installing_required_dependencies state:running start_date:2025-09-21 23:22:16.966839+00:00
[2025-09-21T23:22:17.584+0000] {logging_mixin.py:190} INFO - Dag name:nawy_real_estate_pipeline and current dag run status:running
[2025-09-21T23:22:17.585+0000] {taskinstance.py:732} INFO - ::endgroup::
[2025-09-21T23:22:17.587+0000] {subprocess.py:78} INFO - Tmp dir root location: /tmp
[2025-09-21T23:22:17.649+0000] {subprocess.py:88} INFO - Running command: ['/usr/bin/bash', '-c', ' cd /opt/***/dags/../include/nawy_dbt_project && dbt clean &&  dbt deps --no-version-check ']
[2025-09-21T23:22:17.669+0000] {subprocess.py:99} INFO - Output:
[2025-09-21T23:22:24.116+0000] {subprocess.py:106} INFO - [0m23:22:24  Running with dbt=1.10.11
[2025-09-21T23:22:24.652+0000] {subprocess.py:106} INFO - [0m23:22:24  Checking /opt/***/include/nawy_dbt_project/target/*
[2025-09-21T23:22:24.654+0000] {subprocess.py:106} INFO - [0m23:22:24  Cleaned /opt/***/include/nawy_dbt_project/target/*
[2025-09-21T23:22:24.656+0000] {subprocess.py:106} INFO - [0m23:22:24  Checking /opt/***/include/nawy_dbt_project/dbt_packages/*
[2025-09-21T23:22:24.755+0000] {subprocess.py:106} INFO - [0m23:22:24  Cleaned /opt/***/include/nawy_dbt_project/dbt_packages/*
[2025-09-21T23:22:24.758+0000] {subprocess.py:106} INFO - [0m23:22:24  Finished cleaning all paths.
[2025-09-21T23:22:32.247+0000] {subprocess.py:106} INFO - [0m23:22:32  Running with dbt=1.10.11
[2025-09-21T23:22:35.750+0000] {subprocess.py:106} INFO - [0m23:22:35  Installing dbt-labs/dbt_utils
[2025-09-21T23:22:40.790+0000] {subprocess.py:106} INFO - [0m23:22:40  Encountered an error:
[2025-09-21T23:22:40.791+0000] {subprocess.py:106} INFO - [Errno 2] No such file or directory: 'dbt_packages/dbt_utils/macros/generic_tests'
[2025-09-21T23:22:40.795+0000] {subprocess.py:106} INFO - [0m23:22:40  Traceback (most recent call last):
[2025-09-21T23:22:40.796+0000] {subprocess.py:106} INFO -   File "/home/***/.local/lib/python3.12/site-packages/dbt/cli/requires.py", line 178, in wrapper
[2025-09-21T23:22:40.796+0000] {subprocess.py:106} INFO -     result, success = func(*args, **kwargs)
[2025-09-21T23:22:40.797+0000] {subprocess.py:106} INFO -                       ^^^^^^^^^^^^^^^^^^^^^
[2025-09-21T23:22:40.797+0000] {subprocess.py:106} INFO -   File "/home/***/.local/lib/python3.12/site-packages/dbt/cli/requires.py", line 128, in wrapper
[2025-09-21T23:22:40.798+0000] {subprocess.py:106} INFO -     return func(*args, **kwargs)
[2025-09-21T23:22:40.799+0000] {subprocess.py:106} INFO -            ^^^^^^^^^^^^^^^^^^^^^
[2025-09-21T23:22:40.799+0000] {subprocess.py:106} INFO -   File "/home/***/.local/lib/python3.12/site-packages/dbt/cli/requires.py", line 254, in wrapper
[2025-09-21T23:22:40.800+0000] {subprocess.py:106} INFO -     return func(*args, **kwargs)
[2025-09-21T23:22:40.801+0000] {subprocess.py:106} INFO -            ^^^^^^^^^^^^^^^^^^^^^
[2025-09-21T23:22:40.802+0000] {subprocess.py:106} INFO -   File "/home/***/.local/lib/python3.12/site-packages/dbt/cli/requires.py", line 303, in wrapper
[2025-09-21T23:22:40.802+0000] {subprocess.py:106} INFO -     return func(*args, **kwargs)
[2025-09-21T23:22:40.804+0000] {subprocess.py:106} INFO -            ^^^^^^^^^^^^^^^^^^^^^
[2025-09-21T23:22:40.806+0000] {subprocess.py:106} INFO -   File "/home/***/.local/lib/python3.12/site-packages/dbt/cli/main.py", line 461, in deps
[2025-09-21T23:22:40.807+0000] {subprocess.py:106} INFO -     results = task.run()
[2025-09-21T23:22:40.808+0000] {subprocess.py:106} INFO -               ^^^^^^^^^^
[2025-09-21T23:22:40.809+0000] {subprocess.py:106} INFO -   File "/home/***/.local/lib/python3.12/site-packages/dbt/task/deps.py", line 258, in run
[2025-09-21T23:22:40.810+0000] {subprocess.py:106} INFO -     package.install(self.project, renderer)
[2025-09-21T23:22:40.810+0000] {subprocess.py:106} INFO -   File "/home/***/.local/lib/python3.12/site-packages/dbt/deps/registry.py", line 63, in install
[2025-09-21T23:22:40.811+0000] {subprocess.py:106} INFO -     self._install(project, renderer)
[2025-09-21T23:22:40.812+0000] {subprocess.py:106} INFO -   File "/home/***/.local/lib/python3.12/site-packages/dbt/deps/base.py", line 121, in _install
[2025-09-21T23:22:40.813+0000] {subprocess.py:106} INFO -     connection_exception_retry(download_untar_fn, 5)
[2025-09-21T23:22:40.813+0000] {subprocess.py:106} INFO -   File "/home/***/.local/lib/python3.12/site-packages/dbt_common/utils/connection.py", line 22, in connection_exception_retry
[2025-09-21T23:22:40.814+0000] {subprocess.py:106} INFO -     return fn()
[2025-09-21T23:22:40.815+0000] {subprocess.py:106} INFO -            ^^^^
[2025-09-21T23:22:40.815+0000] {subprocess.py:106} INFO -   File "/home/***/.local/lib/python3.12/site-packages/dbt/deps/base.py", line 133, in download_and_untar
[2025-09-21T23:22:40.816+0000] {subprocess.py:106} INFO -     system.untar_package(tar_path, deps_path, package_name)
[2025-09-21T23:22:40.816+0000] {subprocess.py:106} INFO -   File "/home/***/.local/lib/python3.12/site-packages/dbt_common/clients/system.py", line 649, in untar_package
[2025-09-21T23:22:40.817+0000] {subprocess.py:106} INFO -     dbt_common.clients.system.rename(downloaded_path, desired_path, force=True)
[2025-09-21T23:22:40.817+0000] {subprocess.py:106} INFO -   File "/home/***/.local/lib/python3.12/site-packages/dbt_common/clients/system.py", line 610, in rename
[2025-09-21T23:22:40.818+0000] {subprocess.py:106} INFO -     rmdir(to_path)
[2025-09-21T23:22:40.819+0000] {subprocess.py:106} INFO -   File "/home/***/.local/lib/python3.12/site-packages/dbt_common/clients/system.py", line 351, in rmdir
[2025-09-21T23:22:40.819+0000] {subprocess.py:106} INFO -     shutil.rmtree(path, onerror=onerror)
[2025-09-21T23:22:40.820+0000] {subprocess.py:106} INFO -   File "/usr/local/lib/python3.12/shutil.py", line 759, in rmtree
[2025-09-21T23:22:40.821+0000] {subprocess.py:106} INFO -     _rmtree_safe_fd(stack, onexc)
[2025-09-21T23:22:40.822+0000] {subprocess.py:106} INFO -   File "/usr/local/lib/python3.12/shutil.py", line 703, in _rmtree_safe_fd
[2025-09-21T23:22:40.823+0000] {subprocess.py:106} INFO -     onexc(func, path, err)
[2025-09-21T23:22:40.824+0000] {subprocess.py:106} INFO -   File "/usr/local/lib/python3.12/shutil.py", line 700, in _rmtree_safe_fd
[2025-09-21T23:22:40.825+0000] {subprocess.py:106} INFO -     onexc(os.unlink, fullname, err)
[2025-09-21T23:22:40.826+0000] {subprocess.py:106} INFO -   File "/usr/local/lib/python3.12/shutil.py", line 698, in _rmtree_safe_fd
[2025-09-21T23:22:40.827+0000] {subprocess.py:106} INFO -     os.unlink(entry.name, dir_fd=topfd)
[2025-09-21T23:22:40.828+0000] {subprocess.py:106} INFO - FileNotFoundError: [Errno 2] No such file or directory: 'dbt_packages/dbt_utils/macros/generic_tests'
[2025-09-21T23:22:40.829+0000] {subprocess.py:106} INFO - 
[2025-09-21T23:22:41.857+0000] {subprocess.py:110} INFO - Command exited with return code 2
[2025-09-21T23:22:42.192+0000] {taskinstance.py:3313} ERROR - Task failed with exception
Traceback (most recent call last):
  File "/home/airflow/.local/lib/python3.12/site-packages/airflow/models/taskinstance.py", line 768, in _execute_task
    result = _execute_callable(context=context, **execute_callable_kwargs)
             ^^^^^^^^^^^^^^^^^^^^^^^^^^^^^^^^^^^^^^^^^^^^^^^^^^^^^^^^^^^^^
  File "/home/airflow/.local/lib/python3.12/site-packages/airflow/models/taskinstance.py", line 734, in _execute_callable
    return ExecutionCallableRunner(
           ^^^^^^^^^^^^^^^^^^^^^^^^
  File "/home/airflow/.local/lib/python3.12/site-packages/airflow/utils/operator_helpers.py", line 252, in run
    return self.func(*args, **kwargs)
           ^^^^^^^^^^^^^^^^^^^^^^^^^^
  File "/home/airflow/.local/lib/python3.12/site-packages/airflow/models/baseoperator.py", line 424, in wrapper
    return func(self, *args, **kwargs)
           ^^^^^^^^^^^^^^^^^^^^^^^^^^^
  File "/home/airflow/.local/lib/python3.12/site-packages/airflow/operators/bash.py", line 276, in execute
    raise AirflowException(
airflow.exceptions.AirflowException: Bash command failed. The command returned a non-zero exit code 2.
[2025-09-21T23:22:42.200+0000] {logging_mixin.py:190} INFO - Task instance in failure state
[2025-09-21T23:22:42.201+0000] {logging_mixin.py:190} INFO - Task start:2025-09-21 23:22:16.966839+00:00 end:2025-09-21 23:22:42.199063+00:00 duration:25.232224
[2025-09-21T23:22:42.202+0000] {logging_mixin.py:190} INFO - Task:<Task(BashOperator): installing_required_dependencies> dag:<DAG: nawy_real_estate_pipeline> dagrun:<DagRun nawy_real_estate_pipeline @ 2025-09-20 08:12:45.207798+00:00: manual__2025-09-20T08:12:45.207798+00:00, state:running, queued_at: 2025-09-21 23:03:47.690490+00:00. externally triggered: True>
[2025-09-21T23:22:42.202+0000] {logging_mixin.py:190} INFO - Failure caused by Bash command failed. The command returned a non-zero exit code 2.
[2025-09-21T23:22:42.203+0000] {taskinstance.py:1226} INFO - Marking task as FAILED. dag_id=nawy_real_estate_pipeline, task_id=installing_required_dependencies, run_id=manual__2025-09-20T08:12:45.207798+00:00, execution_date=20250920T081245, start_date=20250921T232216, end_date=20250921T232242
[2025-09-21T23:22:42.548+0000] {taskinstance.py:341} INFO - ::group::Post task execution logs
[2025-09-21T23:22:42.549+0000] {standard_task_runner.py:124} ERROR - Failed to execute job 380 for task installing_required_dependencies (Bash command failed. The command returned a non-zero exit code 2.; 467)
Traceback (most recent call last):
  File "/home/airflow/.local/lib/python3.12/site-packages/airflow/task/task_runner/standard_task_runner.py", line 117, in _start_by_fork
    ret = args.func(args, dag=self.dag)
          ^^^^^^^^^^^^^^^^^^^^^^^^^^^^^
  File "/home/airflow/.local/lib/python3.12/site-packages/airflow/cli/cli_config.py", line 49, in command
    return func(*args, **kwargs)
           ^^^^^^^^^^^^^^^^^^^^^
  File "/home/airflow/.local/lib/python3.12/site-packages/airflow/utils/cli.py", line 116, in wrapper
    return f(*args, **kwargs)
           ^^^^^^^^^^^^^^^^^^
  File "/home/airflow/.local/lib/python3.12/site-packages/airflow/cli/commands/task_command.py", line 483, in task_run
    task_return_code = _run_task_by_selected_method(args, _dag, ti)
                       ^^^^^^^^^^^^^^^^^^^^^^^^^^^^^^^^^^^^^^^^^^^^
  File "/home/airflow/.local/lib/python3.12/site-packages/airflow/cli/commands/task_command.py", line 256, in _run_task_by_selected_method
    return _run_raw_task(args, ti)
           ^^^^^^^^^^^^^^^^^^^^^^^
  File "/home/airflow/.local/lib/python3.12/site-packages/airflow/cli/commands/task_command.py", line 341, in _run_raw_task
    return ti._run_raw_task(
           ^^^^^^^^^^^^^^^^^
  File "/home/airflow/.local/lib/python3.12/site-packages/airflow/utils/session.py", line 97, in wrapper
    return func(*args, session=session, **kwargs)
           ^^^^^^^^^^^^^^^^^^^^^^^^^^^^^^^^^^^^^^
  File "/home/airflow/.local/lib/python3.12/site-packages/airflow/models/taskinstance.py", line 3006, in _run_raw_task
    return _run_raw_task(
           ^^^^^^^^^^^^^^
  File "/home/airflow/.local/lib/python3.12/site-packages/airflow/models/taskinstance.py", line 274, in _run_raw_task
    TaskInstance._execute_task_with_callbacks(
  File "/home/airflow/.local/lib/python3.12/site-packages/airflow/models/taskinstance.py", line 3161, in _execute_task_with_callbacks
    result = self._execute_task(context, task_orig)
             ^^^^^^^^^^^^^^^^^^^^^^^^^^^^^^^^^^^^^^
  File "/home/airflow/.local/lib/python3.12/site-packages/airflow/models/taskinstance.py", line 3185, in _execute_task
    return _execute_task(self, context, task_orig)
           ^^^^^^^^^^^^^^^^^^^^^^^^^^^^^^^^^^^^^^^
  File "/home/airflow/.local/lib/python3.12/site-packages/airflow/models/taskinstance.py", line 768, in _execute_task
    result = _execute_callable(context=context, **execute_callable_kwargs)
             ^^^^^^^^^^^^^^^^^^^^^^^^^^^^^^^^^^^^^^^^^^^^^^^^^^^^^^^^^^^^^
  File "/home/airflow/.local/lib/python3.12/site-packages/airflow/models/taskinstance.py", line 734, in _execute_callable
    return ExecutionCallableRunner(
           ^^^^^^^^^^^^^^^^^^^^^^^^
  File "/home/airflow/.local/lib/python3.12/site-packages/airflow/utils/operator_helpers.py", line 252, in run
    return self.func(*args, **kwargs)
           ^^^^^^^^^^^^^^^^^^^^^^^^^^
  File "/home/airflow/.local/lib/python3.12/site-packages/airflow/models/baseoperator.py", line 424, in wrapper
    return func(self, *args, **kwargs)
           ^^^^^^^^^^^^^^^^^^^^^^^^^^^
  File "/home/airflow/.local/lib/python3.12/site-packages/airflow/operators/bash.py", line 276, in execute
    raise AirflowException(
airflow.exceptions.AirflowException: Bash command failed. The command returned a non-zero exit code 2.
[2025-09-21T23:22:42.567+0000] {local_task_job_runner.py:266} INFO - Task exited with return code 1
[2025-09-21T23:22:42.600+0000] {taskinstance.py:3901} INFO - 0 downstream tasks scheduled from follow-on schedule check
[2025-09-21T23:22:42.670+0000] {local_task_job_runner.py:245} INFO - ::endgroup::
